Workbook
Name IQ_CH: 110000
Name IQ_CQ: 5000
Name IQ_CY: 10000
Name IQ_DAILY: 500000
Name IQ_FH: 100000
Name IQ_FQ: 500
Name IQ_FY: 1000
Name IQ_LTM: 2000
Name IQ_MONTH: 15000
Name IQ_NTM: 6000
Name IQ_WEEK: 50000
Name IQ_YTD: 3000

Sheet __snloffice
A1: 允䅁䝁䉁䅁潁䅁䅁睉䩂䕁䄴杖䉂䕁䅷兓䕂䍁䅁睑偂䕁䄰䅕䉂䕁䄴兗杁䕁䅫䅒䅁䭁䅕䅁啁䅁䅁村䉂䙁䅑睕㙁䕁䅍村偂䕁䅕䅁䝁允䅁䅅䅁䕁䅍兕硁䑁䅉䅍硁䑁䅫䅁呁䅁䅁䅅䅁䕁䅍兕硁䑁䅉䅍祁䑁䅁䅁䙁䅁䅁䅅䅁䕁䅍兕硁䑁䅉䅍祁䑁䅅䅁摂䅁䅁䅅䅁䕁䅍兕硁䑁䅉䅍祁䑁䅉䅁祁䅁䅁䅅䅁䕁䅍兕硁䑁䅉䅍祁䑁䅍䅁䩂䅁䅁䅅䅁䕁䅍兕硁䑁䅉䅍祁䑁䅑䅁扁䅁䅁䅅䅁䕁䅍兕祁䑁䅉䅍硁䑁䅫䅁婁䅁䅁䅅䅁䕁䅍兕祁䑁䅉䅍祁䑁䅁䅁乁䅁䅁䅅䅁䕁䅍兕祁䑁䅉䅍祁䑁䅅䅁橁䅁䅁䅅䅁䕁䅍兕祁䑁䅉䅍祁䑁䅉䅁㍁䅁䅁䅅䅁䕁䅍兕祁䑁䅉䅍祁䑁䅍䅁偁䅁䅁䅅䅁䕁䅍兕祁䑁䅉䅍祁䑁䅑䅁潁䅁䅁䅅䅁䕁䅍兕穁䑁䅉䅍硁䑁䅫䅁䡁䅁䅁䅅䅁䕁䅍兕穁䑁䅉䅍祁䑁䅁䅁䅂䅁䅁䅅䅁䕁䅍兕穁䑁䅉䅍祁䑁䅅䅁㝁䅁䅁䅅䅁䕁䅍兕穁䑁䅉䅍祁䑁䅉䅁楁䅁䅁䅅䅁䕁䅍兕穁䑁䅉䅍祁䑁䅍䅁剁䅁䅁䅅䅁䕁䅍兕穁䑁䅉䅍祁䑁䅑䅁䭁䅁䅁䅅䅁䕁䅍兕ぁ䑁䅉䅍硁䑁䅫䅁噁䅁䅁䅅䅁䕁䅍兕ぁ䑁䅉䅍祁䑁䅁䅁捁䅁䅁䅅䅁䕁䅍兕ぁ䑁䅉䅍祁䑁䅅䅁瑁䅁䅁䅅䅁䕁䅍兕ぁ䑁䅉䅍祁䑁䅉䅁杁䅁䅁䅅䅁䕁䅍兕ぁ䑁䅉䅍祁䑁䅍䅁湁䅁䅁䅅䅁䕁䅍兕ぁ䑁䅉䅍祁䑁䅑䅁䍁䅁䅁䅈䅁䕁䅫兕啂䑁䅅兏硁䑁䅣䅏穁䑁䅕免ㅁ䑁䅧䅁歃䅁䅁杅䅁䕁䅫兕時䕁䅍兑兂䕁䅕䅗䅁䅁䅫䅁慁䅁䅁兓剂䙁䄸睑䉂䙁䅍䅓時䕁䄸䅕䙂䙁䅉䅁時允䅁杍䅁䕁䅫兕時䕁䅑兓䵂䙁䅕䅖時䕁䅕䅕呂䙁䄸兑䝂䙁䅑兒卂䙁䄸兒奂䙁䅑杕䉂䅁䅁允䅁䅁䅙䅁佂䕁䅅䅁䑁䅁䅁杅䅁䕁䄴兗呂䕁䅕杏䉂䕁䅑兔䅁䙁䅫䅁十䅁䅁杔婂䙁䅍兒㙁䕁䅅兒䙂䅁䅁睌䅁䉁䅉䅁佂䙁䅫睕䙂䑁䅯兑䩂䕁䅣䅁灁䅁䅁杅䅁䕁䄴兗呂䕁䅕杏䉂䕁䅫杗䅁䑁䅁䅁十䅁䅁杔婂䙁䅍兒㙁䕁䅅杓䡂䅁䅁䅅䅁䉁䅑䅁佂䙁䅫睕䙂䑁䅯兑乂䕁䅍杕䅁䝁䄰䅁十䅁䅁杔婂䙁䅍兒㙁䕁䅅兔䙂䅁䅁兏䅁䉁䅉䅁佂䙁䅫睕䙂䑁䅯兑乂䙁䅁䅁灃䅁䅁杅䅁䕁䄴兗呂䕁䅕杏䉂䕁䄰䅖䅁䡁䅍䅁啁䅁䅁杔婂䙁䅍兒㙁䕁䅅杔䙂䙁䅑䅁䵂䅁䅁杅䅁䕁䄴兗呂䕁䅕杏䉂䕁䄸杔䅁䉁䄰䅁十䅁䅁杔婂䙁䅍兒㙁䕁䅅䅕䥂䅁䅁杅䅁䉁䅉䅁佂䙁䅫睕䙂䑁䅯兑兂䕁䄸䅁牁䅁䅁䅆䅁䕁䄴兗呂䕁䅕杏䉂䙁䅁䅖坂䅁䅁具䅁䉁䅉䅁佂䙁䅫睕䙂䑁䅯兑啂䕁䄸䅁䍂䅁䅁杅䅁䕁䄴兗呂䕁䅕杏䉂䙁䅙村䅁乁䄰䅁十䅁䅁杔婂䙁䅍兒㙁䕁䅅杖婂䅁䅁朰䅁䉁䅉䅁佂䙁䅫睕䙂䑁䅯兑塂䕁䅳䅁䍃䅁䅁杅䅁䕁䄴兗呂䕁䅕杏䉂䙁䅧䅕䅁䑁䅯䅁十䅁䅁杔婂䙁䅍兒㙁䕁䅅杗偂䅁䅁睳䅁䉁䅉䅁佂䙁䅫睕䙂䑁䅯村䉂䕁䅍䅁灂䅁䅁䅆䅁䕁䄴兗呂䕁䅕杏䍂䕁䅅䅔䵂䅁䅁䅸䅁䉁䅉䅁佂䙁䅫睕䙂䑁䅯村䉂䙁䅧䅁慃䅁䅁杅䅁䕁䄴兗呂䕁䅕杏䍂䕁䅉兗䅁䉁䅣䅁十䅁䅁杔婂䙁䅍兒㙁䕁䅉䅒奂䅁䅁杋䅁䉁䅉䅁佂䙁䅫睕䙂䑁䅯村䙂䕁䄴䅁䥂允䅁䅆䅁䕁䄴兗呂䕁䅕杏䍂䕁䅙杌䍂䅁䅁杫䅁䉁䅁䅁佂䙁䅫睕䙂䑁䅯村䡂䅁䅁䅤䅁䉁䅑䅁佂䙁䅫睕䙂䑁䅯村䵂䕁䅑杕䅁佁䅉䅁十䅁䅁杔婂䙁䅍兒㙁䕁䅉䅔䱂䅁䅁䄶䅁䉁䅉䅁佂䙁䅫睕䙂䑁䅯村乂䙁䅫䅁捃䅁䅁䅅䅁䕁䄴兗呂䕁䅕杏䍂䙁䅉䅁䙁允䅁杆䅁䕁䄴兗呂䕁䅕杏䍂䙁䅉睓畁䕁䅉䅁䱄䅁䅁杅䅁䕁䄴兗呂䕁䅕杏䍂䙁䅉睔䅁䙁䅣䅁十䅁䅁杔婂䙁䅍兒㙁䕁䅉睕奂䅁䅁眲䅁䉁䅉䅁佂䙁䅫睕䙂䑁䅯村塂䕁䅅䅁桃䅁䅁䅅䅁䕁䄴兗呂䕁䅕杏䍂䙁䅧䅁療䅁䅁杅䅁䕁䄴兗呂䕁䅕杏䍂䙁䅧䅕䅁䱁䄰䅁佁䅁䅁杔婂䙁䅍兒㙁䕁䅍䅁䑃䅁䅁杅䅁䕁䄴兗呂䕁䅕杏䑂䕁䅅睒䅁佁䄸䅁十䅁䅁杔婂䙁䅍兒㙁䕁䅍兑䥂䅁䅁全䅁䉁䅑䅁佂䙁䅫睕䙂䑁䅯睑䉂䙁䅉杕䅁䑁䄴䅁十䅁䅁杔婂䙁䅍兒㙁䕁䅍兑啂䅁䅁杓䅅䉁䅁䅁佂䙁䅫睕䙂䑁䅯睑䍂䅁䅁睫䅁䉁䅑䅁佂䙁䅫睕䙂䑁䅯睑䍂䙁䅉兒䅁䱁䄴䅁十䅁䅁杔婂䙁䅍兒㙁䕁䅍睑䩂䅁䅁杨䅁䉁䅉䅁佂䙁䅫睕䙂䑁䅯睑䑂䕁䅷䅁敄䅁䅁䅅䅁䕁䄴兗呂䕁䅕杏䑂䕁䅕䅁坁允䅁䅅䅁䕁䄴兗呂䕁䅕杏䑂䕁䅙䅁ぁ䅁䅁杅䅁䕁䄴兗呂䕁䅕杏䑂䕁䅙睒䅁偁䅁䅁十䅁䅁杔婂䙁䅍兒㙁䕁䅍䅓䕂䅁䅁杩䅁䉁䅁䅁佂䙁䅫睕䙂䑁䅯睑䵂䅁䅁睆䅅䉁䅉䅁佂䙁䅫睕䙂䑁䅯睑乂䕁䅣䅁楂䅁䅁杅䅁䕁䄴兗呂䕁䅕杏䑂䕁䄰兓䅁䕁䄴䅁十䅁䅁杔婂䙁䅍兒㙁䕁䅍兔呂䅁䅁睄䅅䉁䅉䅁佂䙁䅫睕䙂䑁䅯睑佂䕁䅍䅁ぃ䅁䅁杅䅁䕁䄴兗呂䕁䅕杏䑂䕁䄴䅕䅁䕁䉳䅁十䅁䅁杔婂䙁䅍兒㙁䕁䅍睔䝂䅁䅁䄹䅁䉁䅉䅁佂䙁䅫睕䙂䑁䅯睑偂䙁䅁䅁硂䅁䅁杅䅁䕁䄴兗呂䕁䅕杏䑂䕁䄸杕䅁䝁䄴䅁啁䅁䅁杔婂䙁䅍兒㙁䕁䅍䅕䉂䙁䅫䅁呄䅁䅁杅䅁䕁䄴兗呂䕁䅕杏䑂䙁䅁䅖䅁䭁䅳䅁十䅁䅁杔婂䙁䅍兒㙁䕁䅍杕䵂䅁䅁睓䅁䉁䅑䅁佂䙁䅫睕䙂䑁䅯睑啂䙁䅉兑䅁佁䅅䅁啁䅁䅁杔婂䙁䅍兒㙁䕁䅍䅖坂䕁䅅䅁時䅁䅁杅䅁䕁䄴兗呂䕁䅕杏䑂䙁䅙睕䅁偁䅉䅁十䅁䅁杔婂䙁䅍兒㙁䕁䅍杖奂䅁䅁杘䅁䅁䄴䅁佂䙁䅫睕䙂䑁䅯䅒䅁䕁䅑䅁十䅁䅁杔婂䙁䅍兒㙁䕁䅑兑䵂䅁䅁杄䅁䉁䅉䅁佂䙁䅫睕䙂䑁䅯䅒䉂䙁䅫䅁䉂允䅁䅅䅁䕁䄴兗呂䕁䅕杏䕂䕁䅑䅁橄䅁䅁䅅䅁䕁䄴兗呂䕁䅕杏䕂䕁䅕䅁噃䅁䅁䅆䅁䕁䄴兗呂䕁䅕杏䕂䕁䅕睑䱂䅁䅁䄳䅁䉁䅑䅁佂䙁䅫睕䙂䑁䅯䅒䙂䕁䅷䅔䅁䝁䅳䅁十䅁䅁杔婂䙁䅍兒㙁䕁䅑杒呂䅁䅁䅁䅅䉁䅁䅁佂䙁䅫睕䙂䑁䅯䅒䡂䅁䅁䅬䅁䉁䅉䅁佂䙁䅫睕䙂䑁䅯䅒䥂䕁䅫䅁㡁䅁䅁杅䅁䕁䄴兗呂䕁䅕杏䕂䕁䅧杕䅁䍁䅷䅁十䅁䅁杔婂䙁䅍兒㙁䕁䅑䅔卂䅁䅁䅍䅅䉁䅉䅁佂䙁䅫睕䙂䑁䅯䅒偂䕁䅍䅁湃䅁䅁杅䅁䕁䄴兗呂䕁䅕杏䕂䕁䄸杖䅁䑁䉍䅁十䅁䅁杔婂䙁䅍兒㙁䕁䅑睔塂䅁䅁来䅁䉁䅉䅁佂䙁䅫睕䙂䑁䅯䅒卂䕁䅫䅁獃䅁䅁杅䅁䕁䄴兗呂䕁䅕杏䕂䙁䅑兒䅁䅁䉳䅁十䅁䅁杔婂䙁䅍兒㙁䕁䅑兖䱂䅁䅁䅕䅅䉁䅉䅁佂䙁䅫睕䙂䑁䅯䅒坂䕁䅅䅁奁䅁䅁杅䅁䕁䄴兗呂䕁䅕杏䕂䙁䅙杔䅁䅁䉷䅁十䅁䅁杔婂䙁䅍兒㙁䕁䅕睑䵂䅁䅁杉䅅䉁䅁䅁佂䙁䅫睕䙂䑁䅯兒䕂䅁䅁兖䅅䉁䅉䅁佂䙁䅫睕䙂䑁䅯兒䝂䙁䅧䅁䙂允䅁䅅䅁䕁䄴兗呂䕁䅕杏䙂䕁䅣䅁啂䅁䅁杅䅁䕁䄴兗呂䕁䅕杏䙂䕁䅫䅗䅁䑁䈴䅁十䅁䅁杔婂䙁䅍兒㙁䕁䅕䅔坂䅁䅁䅅䅅䉁䅉䅁佂䙁䅫睕䙂䑁䅯兒乂䕁䄴䅁穁䅁䅁杅䅁䕁䄴兗呂䕁䅕杏䙂䕁䄰杕䅁䅁䅑䅁十䅁䅁杔婂䙁䅍兒㙁䕁䅕睔䡂䅁䅁䄲䅁䉁䅑䅁佂䙁䅫睕䙂䑁䅯兒兂䕁䅅兔䅁䝁䅯䅁十䅁䅁杔婂䙁䅍兒㙁䕁䅕兕卂䅁䅁杗䅁䉁䅉䅁佂䙁䅫睕䙂䑁䅯兒剂䙁䅑䅁求䅁䅁䅅䅁䕁䄴兗呂䕁䅕杏䙂䙁䅍䅁睂䅁䅁杅䅁䕁䄴兗呂䕁䅕杏䙂䙁䅍睕䅁䍁䅕䅁十䅁䅁杔婂䙁䅍兒㙁䕁䅕䅖佂䅁䅁東䅁䉁䅉䅁佂䙁䅫睕䙂䑁䅯兒啂䙁䅉䅁䥂䅁䅁䅅䅁䕁䄴兗呂䕁䅕杏䙂䙁䅣䅁呂允䅁䅆䅁䕁䄴兗呂䕁䅕杏䙂䙁䅧䅕䕂䅁䅁䅘䅁䉁䅉䅁佂䙁䅫睕䙂䑁䅯兒奂䙁䅉䅁楃䅁䅁杄䅁䕁䄴兗呂䕁䅕杏䝂䅁䅁杬䅁䉁䅉䅁佂䙁䅫睕䙂䑁䅯杒䑂䙁䅧䅁杂䅁䅁杅䅁䕁䄴兗呂䕁䅕杏䝂䕁䅑睕䅁䕁䅣䅁十䅁䅁杔婂䙁䅍兒㙁䕁䅙䅒奂䅁䅁䄱䅁䉁䅁䅁佂䙁䅫睕䙂䑁䅯杒䙂䅁䅁兦䅁䉁䅁䅁佂䙁䅫睕䙂䑁䅯杒䩂䅁䅁睂䅅䉁䅑䅁佂䙁䅫睕䙂䑁䅯杒䩂䕁䅍睔䅁偁䄸䅁十䅁䅁杔婂䙁䅍兒㙁䕁䅙兓呂䅁䅁兴䅁䉁䅉䅁佂䙁䅫睕䙂䑁䅯杒乂䕁䅍䅁㥁允䅁杅䅁䕁䄴兗呂䕁䅕杏䝂䙁䅉䅖䅁䩁䅣䅁十䅁䅁杔婂䙁䅍兒㙁䕁䅙䅖坂䅁䅁睐䅁䉁䅁䅁佂䙁䅫睕䙂䑁䅯睒䕂䅁䅁兕䅁䉁䅑䅁佂䙁䅫睕䙂䑁䅯睒䕂䕁䅑兗䅁䕁䅍䅁允䅁䅁杔婂䙁䅍兒㙁䕁䅣兒䅁偁䅧䅁十䅁䅁杔婂䙁䅍兒㙁䕁䅣兒坂䅁䅁杷䅁䉁䅉䅁佂䙁䅫睕䙂䑁䅯睒䩂䙁䅍䅁ㅄ䅁䅁䅅䅁䕁䄴兗呂䕁䅕杏䡂䕁䅷䅁歄䅁䅁杅䅁䕁䄴兗呂䕁䅕杏䡂䕁䅷睖䅁乁䅫䅁允䅁䅁杔婂䙁䅍兒㙁䕁䅣兔䅁䉁䉳䅁啁䅁䅁杔婂䙁䅍兒㙁䕁䅣杔卂䕁䅍䅁睃䅁䅁杅䅁䕁䄴兗呂䕁䅕杏䡂䙁䅁睑䅁䝁䅑䅁十䅁䅁杔婂䙁䅍兒㙁䕁䅣䅕佂䅁䅁眸䅁䉁䅑䅁佂䙁䅫睕䙂䑁䅯睒卂䕁䄰杔䅁䵁䅷䅁十䅁䅁杔婂䙁䅍兒㙁䕁䅧兑䵂䅁䅁权䅅䉁䅉䅁佂䙁䅫睕䙂䑁䅯䅓䑂䕁䅅䅁歁允䅁杅䅁䕁䄴兗呂䕁䅕杏䥂䕁䅕睕䅁䑁䅧䅁十䅁䅁杔婂䙁䅍兒㙁䕁䅧兓䩂䅁䅁充䅅䉁䅉䅁佂䙁䅫睕䙂䑁䅯䅓䵂䙁䅑䅁㡃䅁䅁杅䅁䕁䄴兗呂䕁䅕杏䥂䙁䅁兒䅁䙁䈰䅁十䅁䅁杔婂䙁䅍兒㙁䕁䅧䅕剂䅁䅁䅇䅅䉁䅉䅁佂䙁䅫睕䙂䑁䅯䅓卂䕁䅷䅁噄䅁䅁䅆䅁䕁䄴兗呂䕁䅕杏䥂䙁䅕村䍂䅁䅁兄䅅䉁䅉䅁佂䙁䅫睕䙂䑁䅯䅓噂䕁䄰䅁䱃䅁䅁杅䅁䕁䄴兗呂䕁䅕杏䥂䙁䅣兔䅁乁䄸䅁十䅁䅁杔婂䙁䅍兒㙁䕁䅫村乂䅁䅁睐䅅䉁䅉䅁佂䙁䅫睕䙂䑁䅯兓䑂䕁䅕䅁坄䅁䅁杅䅁䕁䄴兗呂䕁䅕杏䩂䕁䅕䅗䅁䉁䉕䅁十䅁䅁杔婂䙁䅍兒㙁䕁䅫杒䝂䅁䅁睗䅁䉁䅑䅁佂䙁䅫睕䙂䑁䅯兓佂䙁䅙䅓䅁䍁䅙䅁允䅁䅁杔婂䙁䅍兒㙁䕁䅫䅕䅁䅁䉉䅁十䅁䅁杔婂䙁䅍兒㙁䕁䅫兕坂䅁䅁䅏䅅䉁䅁䅁佂䙁䅫睕䙂䑁䅯兓卂䅁䅁杊䅅䉁䅉䅁佂䙁䅫睕䙂䑁䅯兓卂䕁䄰䅁䡂允䅁䅅䅁䕁䄴兗呂䕁䅕杏䩂䙁䅑䅁牁允䅁杅䅁䕁䄴兗呂䕁䅕杏䩂䙁䅑睖䅁䅁䉍䅁十䅁䅁杔婂䙁䅍兒㙁䕁䅫杖慂䅁䅁村䅅䅁䄴䅁佂䙁䅫睕䙂䑁䅯杓䅁偁䄰䅁十䅁䅁杔婂䙁䅍兒㙁䕁䅯村䵂䅁䅁兗䅅䉁䅉䅁佂䙁䅫睕䙂䑁䅯杓䑂䕁䅫䅁慂允䅁杅䅁䕁䄴兗呂䕁䅕杏䭂䕁䄴杓䅁偁䅷䅁啁䅁䅁杔婂䙁䅍兒㙁䕁䅯杔兂䙁䅉䅁䥃䅁䅁杅䅁䕁䄴兗呂䕁䅕杏䭂䙁䅁兔䅁䥁䅣䅁佁䅁䅁杔婂䙁䅍兒㙁䕁䅳䅁灄䅁䅁杅䅁䕁䄴兗呂䕁䅕杏䱂䕁䅕兗䅁䭁䅧䅁啁䅁䅁杔婂䙁䅍兒㙁䕁䅳兒婂䙁䅍䅁ㅁ䅁䅁杅䅁䕁䄴兗呂䕁䅕杏䱂䕁䅫兔䅁䝁䅅䅁十䅁䅁杔婂䙁䅍兒㙁䕁䅳睓卂䅁䅁兔䅁䉁䅉䅁佂䙁䅫睕䙂䑁䅯睓乂䕁䅉䅁晁䅁䅁杅䅁䕁䄴兗呂䕁䅕杏䱂䕁䄰兓䅁䡁䅕䅁十䅁䅁杔婂䙁䅍兒㙁䕁䅳兔奂䅁䅁睑䅅䉁䅑䅁佂䙁䅫睕䙂䑁䅯睓坂䙁䅕兒䅁䕁䉙䅁佁䅁䅁杔婂䙁䅍兒㙁䕁䅷䅁奂允䅁䅆䅁䕁䄴兗呂䕁䅕杏䵂䕁䅑睔呂䅁䅁杘䅅䉁䅉䅁佂䙁䅫睕䙂䑁䅯䅔䙂䕁䄴䅁䙄䅁䅁䅅䅁䕁䄴兗呂䕁䅕杏䵂䕁䅧䅁灁允䅁杅䅁䕁䄴兗呂䕁䅕杏䵂䕁䅧䅗䅁䭁䄸䅁十䅁䅁杔婂䙁䅍兒㙁䕁䅷兓䩂䅁䅁睔䅅䉁䅉䅁佂䙁䅫睕䙂䑁䅯䅔䵂䙁䅫䅁啁䅁䅁杅䅁䕁䄴兗呂䕁䅕杏䵂䕁䄰䅖䅁䙁䉳䅁十䅁䅁杔婂䙁䅍兒㙁䕁䅷睔塂䅁䅁䅖䅅䉁䅉䅁佂䙁䅫睕䙂䑁䅯䅔坂䙁䅍䅁剄䅁䅁䅅䅁䕁䄴兗呂䕁䅕杏䵂䙁䅣䅁湄䅁䅁杅䅁䕁䄴兗呂䕁䅕杏䵂䙁䅫村䅁䅁䉧䅁十䅁䅁杔婂䙁䅍兒㙁䕁䅷兗坂䅁䅁杔䅅䉁䅁䅁佂䙁䅫睕䙂䑁䅯兔䉂䅁䅁杮䅁䉁䅉䅁佂䙁䅫睕䙂䑁䅯兔䉂䕁䅅䅁塂允䅁杅䅁䕁䄴兗呂䕁䅕杏乂䕁䅅睕䅁䵁䅙䅁十䅁䅁杔婂䙁䅍兒㙁䕁䄰睑䕂䅁䅁䅂䅅䉁䅉䅁佂䙁䅫睕䙂䑁䅯兔䑂䕁䅳䅁慄䅁䅁杅䅁䕁䄴兗呂䕁䅕杏乂䕁䅍睔䅁䭁䄰䅁十䅁䅁杔婂䙁䅍兒㙁䕁䄰䅒啂䅁䅁睯䅁䉁䅉䅁佂䙁䅫睕䙂䑁䅯兔䙂䙁䅑䅁ㅁ允䅁杅䅁䕁䄴兗呂䕁䅕杏乂䕁䅣兔䅁䑁䉷䅁十䅁䅁杔婂䙁䅍兒㙁䕁䄰䅓䱂䅁䅁六䅁䉁䅉䅁佂䙁䅫睕䙂䑁䅯兔䱂䕁䅍䅁摁允䅁杅䅁䕁䄴兗呂䕁䅕杏乂䕁䅷兔䅁䍁䉷䅁十䅁䅁杔婂䙁䅍兒㙁䕁䄰兔䑂䅁䅁䅨䅁䉁䅁䅁佂䙁䅫睕䙂䑁䅯兔偂䅁䅁杇䅁䉁䅉䅁佂䙁䅫睕䙂䑁䅯兔偂䕁䅧䅁卂允䅁杅䅁䕁䄴兗呂䕁䅕杏乂䙁䅁睑䅁䉁䉑䅁十䅁䅁杔婂䙁䅍兒㙁䕁䄰杕䱂䅁䅁杺䅁䉁䅁䅁佂䙁䅫睕䙂䑁䅯兔呂䅁䅁眱䅁䉁䅑䅁佂䙁䅫睕䙂䑁䅯兔呂䕁䅍兓䅁䍁䅅䅁十䅁䅁杔婂䙁䅍兒㙁䕁䄰睕䩂䅁䅁䅫䅁䉁䅉䅁佂䙁䅫睕䙂䑁䅯兔啂䕁䅉䅁浂䅁䅁杅䅁䕁䄴兗呂䕁䅕杏乂䙁䅑䅒䅁䕁䉷䅁啁䅁䅁杔婂䙁䅍兒㙁䕁䄴睑䵂䕁䅧䅁敁允䅁杅䅁䕁䄴兗呂䕁䅕杏佂䕁䅕兒䅁偁䅳䅁十䅁䅁杔婂䙁䅍兒㙁䕁䄴兒乂䅁䅁睮䅁䉁䅁䅁佂䙁䅫睕䙂䑁䅯杔䩂䅁䅁䅎䅅䉁䅉䅁佂䙁䅫睕䙂䑁䅯杔䱂䕁䅕䅁㙃䅁䅁杅䅁䕁䄴兗呂䕁䅕杏佂䕁䄸睑䅁䝁䅷䅁十䅁䅁杔婂䙁䅍兒㙁䕁䄴杕䡂䅁䅁杕䅁䉁䅉䅁佂䙁䅫睕䙂䑁䅯杔呂䕁䅍䅁慁允䅁杅䅁䕁䄴兗呂䕁䅕杏佂䙁䅕兒䅁䡁䅙䅁十䅁䅁杔婂䙁䅍兒㙁䕁䄴杖卂䅁䅁兓䅅䉁䅉䅁佂䙁䅫睕䙂䑁䅯睔䱂䕁䅕䅁畁䅁䅁杅䅁䕁䄴兗呂䕁䅕杏偂䕁䄰睑䅁䍁䉧䅁啁䅁䅁杔婂䙁䅍兒㙁䕁䄸杕䑂䕁䅷䅁偄䅁䅁杅䅁䕁䄴兗呂䕁䅕杏偂䙁䅧兗䅁䅁䉫䅁十䅁䅁杔婂䙁䅍兒㙁䙁䅍䅖慂䅁䅁睕䅁䅁䄴䅁佂䙁䅫睕䙂䑁䅯䅖䅁䙁䅕䅁十䅁䅁杔婂䙁䅍兒㙁䙁䅑兑兂䅁䅁睈䅅䉁䅉䅁佂䙁䅫睕䙂䑁䅯䅗偂䕁䄰䅁偂䅁䅁䅈䅁䕁䄴兙穂䝁䅑兙硂䕁䅣兔㙁䕁䅕杔兂䕁䅧䅁汄䅁䅁䅈䅁䕁䄴兙穂䝁䅑兙硂䕁䅣睕㙁䕁䅅兑兂䕁䅷䅁湂䅁䅁䅈䅁䕁䄴兙穂䝁䅑兙硂䕁䅣睕㙁䕁䅅睑䡂䕁䅷䅁硁䅁䅁杇䅁䕁䄴兙穂䝁䅑兙硂䕁䅣睕㙁䕁䅅䅒䩂䅁䅁杴䅁䉁䅯䅁佂䝁䅅督歂䝁䅅兣䡂䙁䅍杏䉂䕁䅑䅕䅁䱁䅣䅁捁䅁䅁杔桂䡁䅍䅚桂䡁䅅睒呂䑁䅯兑䕂䙁䅍睓䅁䅁䅁䅁慁䅁䅁杔桂䡁䅍䅚桂䡁䅅睒呂䑁䅯兑䙂䙁䅁䅁⽂䅁䅁䅈䅁䕁䄴兙穂䝁䅑兙硂䕁䅣睕㙁䕁䅅兔䉂䙁䅑䅁䩃䅁䅁䅈䅁䕁䄴兙穂䝁䅑兙硂䕁䅣睕㙁䕁䅅兔䡂䕁䄴䅁畃䅁䅁䅈䅁䕁䄴兙穂䝁䅑兙硂䕁䅣睕㙁䕁䅅兔慂䕁䄴䅁兂䅁䅁䅈䅁䕁䄴兙穂䝁䅑兙硂䕁䅣睕㙁䕁䅅杔呂䙁䅍䅁䵁䅁䅁杇䅁䕁䄴兙穂䝁䅑兙硂䕁䅣睕㙁䕁䅅䅕䉂䅁䅁兹䅁䉁䅷䅁佂䝁䅅督歂䝁䅅兣䡂䙁䅍杏䉂䙁䅙睒偂䅁䅁兑䅁䉁䅷䅁佂䝁䅅督歂䝁䅅兣䡂䙁䅍杏䉂䙁䅧睔佂䅁䅁䅥䅁䉁䅷䅁佂䝁䅅督歂䝁䅅兣䡂䙁䅍杏䍂䕁䅫兓䍂䅁䅁杪䅁䉁䅷䅁佂䝁䅅督歂䝁䅅兣䡂䙁䅍杏䍂䕁䅳杔䡂䅁䅁杣䅁䉁䅯䅁佂䝁䅅督歂䝁䅅兣䡂䙁䅍杏䍂䕁䅳杕䅁䱁䅅䅁捁䅁䅁杔桂䡁䅍䅚桂䡁䅅睒呂䑁䅯睑䕂䕁䄴睕䅁䩁䄰䅁慁䅁䅁杔桂䡁䅍䅚桂䡁䅅睒呂䑁䅯睑䕂䙁䅣䅁㑃䅁䅁杇䅁䕁䄴兙穂䝁䅑兙硂䕁䅣睕㙁䕁䅍兒䡂䅁䅁䅧䅁䉁䅷䅁佂䝁䅅督歂䝁䅅兣䡂䙁䅍杏䑂䕁䅧杕塂䅁䅁朷䅁䉁䅷䅁佂䝁䅅督歂䝁䅅兣䡂䙁䅍杏䑂䕁䅧䅖卂䅁䅁䅗䅁䉁䅷䅁佂䝁䅅督歂䝁䅅兣䡂䙁䅍杏䑂䕁䅫杔䝂䅁䅁杦䅁䉁䄴䅁佂䝁䅅督歂䝁䅅兣䡂䙁䅍杏䑂䕁䄰睑呂䕁䅅䅁䅄䅁䅁杇䅁䕁䄴兙穂䝁䅑兙硂䕁䅣睕㙁䕁䅍兔䙂䅁䅁䅡䅁䉁䅷䅁佂䝁䅅督歂䝁䅅兣䡂䙁䅍杏䑂䕁䄸睕啂䅁䅁杄䅅䉁䅷䅁佂䝁䅅督歂䝁䅅兣䡂䙁䅍杏䑂䙁䅁杕啂䅁䅁兏䅅䉁䅷䅁佂䝁䅅督歂䝁䅅兣䡂䙁䅍杏䑂䙁䅉睖䕂䅁䅁兌䅅䉁䅷䅁佂䝁䅅督歂䝁䅅兣䡂䙁䅍杏䑂䙁䅍睑偂䅁䅁䅉䅅䉁䅷䅁佂䝁䅅督歂䝁䅅兣䡂䙁䅍杏䑂䙁䅍睒兂䅁䅁兔䅅䉁䅯䅁佂䝁䅅督歂䝁䅅兣䡂䙁䅍杏䑂䙁䅍䅗䅁偁䅫䅁捁䅁䅁杔桂䡁䅍䅚桂䡁䅅睒呂䑁䅯睑啂䕁䅅睕䅁䕁䅕䅁捁䅁䅁杔桂䡁䅍䅚桂䡁䅅睒呂䑁䅯睑啂䙁䅍䅓䅁䍁䈴䅁慁䅁䅁杔桂䡁䅍䅚桂䡁䅅睒呂䑁䅯睑慂䙁䅉䅁㝃䅁䅁䅈䅁䕁䄴兙穂䝁䅑兙硂䕁䅣睕㙁䕁䅑䅔啂䙁䅉䅁捁允䅁杇䅁䕁䄴兙穂䝁䅑兙硂䕁䅣睕㙁䕁䅑䅕慂䅁䅁杹䅁䉁䅷䅁佂䝁䅅督歂䝁䅅兣䡂䙁䅍杏䕂䙁䅧睑乂䅁䅁睷䅁䉁䅧䅁佂䝁䅅督歂䝁䅅兣䡂䙁䅍杏䙂䕁䅅䅁煄䅁䅁䅈䅁䕁䄴兙穂䝁䅑兙硂䕁䅣睕㙁䕁䅕村䉂䙁䅫䅁扃䅁䅁䅈䅁䕁䄴兙穂䝁䅑兙硂䕁䅣睕㙁䕁䅕兕䩂䙁䅧䅁䉁允䅁䅈䅁䕁䄴兙穂䝁䅑兙硂䕁䅣睕㙁䕁䅕杕䩂䕁䅕䅁剃䅁䅁䅈䅁䕁䄴兙穂䝁䅑兙硂䕁䅣睕㙁䕁䅕杖卂䕁䅣䅁㉁允䅁杇䅁䕁䄴兙穂䝁䅑兙硂䕁䅣睕㙁䕁䅕䅗䑂䅁䅁睤䅁䉁䅷䅁佂䝁䅅督歂䝁䅅兣䡂䙁䅍杏䙂䙁䅧䅕䙂䅁䅁杖䅁䉁䅷䅁佂䝁䅅督歂䝁䅅兣䡂䙁䅍杏䝂䕁䅅杔䡂䅁䅁䅯䅁䉁䅷䅁佂䝁䅅督歂䝁䅅兣䡂䙁䅍杏䝂䕁䅅睕啂䅁䅁杂䅁䉁䅷䅁佂䝁䅅督歂䝁䅅兣䡂䙁䅍杏䝂䕁䅙兓坂䅁䅁兺䅁䉁䅷䅁佂䝁䅅督歂䝁䅅兣䡂䙁䅍杏䝂䕁䅫䅖䍂䅁䅁睪䅁䉁䅯䅁佂䝁䅅督歂䝁䅅兣䡂䙁䅍杏䝂䕁䄸䅗䅁䡁䅳䅁捁䅁䅁杔桂䡁䅍䅚桂䡁䅅睒呂䑁䅯杒偂䙁䅧兑䅁䍁䉯䅁捁䅁䅁杔桂䡁䅍䅚桂䡁䅅睒呂䑁䅯杒呂䕁䅷杕䅁䑁䉳䅁捁䅁䅁杔桂䡁䅍䅚桂䡁䅅睒呂䑁䅯杒啂䕁䄴䅖䅁䕁䉑䅁捁䅁䅁杔桂䡁䅍䅚桂䡁䅅睒呂䑁䅯睒䙂䕁䅧睑䅁䙁䉙䅁慁䅁䅁杔桂䡁䅍䅚桂䡁䅅睒呂䑁䅯睒䙂䕁䄴䅁䉃䅁䅁䅈䅁䕁䄴兙穂䝁䅑兙硂䕁䅣睕㙁䕁䅣兓䵂䕁䅑䅁十允䅁䅈䅁䕁䄴兙穂䝁䅑兙硂䕁䅣睕㙁䕁䅣睔偂䕁䅣䅁䥁䅁䅁杈䅁䕁䄴兙穂䝁䅑兙硂䕁䅣睕㙁䕁䅣睔偂䕁䅣䅔䅁䅁䅳䅁慁䅁䅁杔桂䡁䅍䅚桂䡁䅅睒呂䑁䅯䅓䉂䙁䅍䅁牄䅁䅁䅈䅁䕁䄴兙穂䝁䅑兙硂䕁䅣睕㙁䕁䅧村䉂䕁䄴䅁橁允䅁䅈䅁䕁䄴兙穂䝁䅑兙硂䕁䅣睕㙁䕁䅧睔䵂䙁䅧䅁⽃䅁䅁杇䅁䕁䄴兙穂䝁䅑兙硂䕁䅣睕㙁䕁䅧睔佂䅁䅁䅦䅁䉁䅷䅁佂䝁䅅督歂䝁䅅兣䡂䙁䅍杏䥂䙁䅍兓䑂䅁䅁杰䅁䉁䅯䅁佂䝁䅅督歂䝁䅅兣䡂䙁䅍杏䥂䙁䅍䅖䅁偁䅯䅁捁䅁䅁杔桂䡁䅍䅚桂䡁䅅睒呂䑁䅯兓䕂䙁䅧䅗䅁䍁䉅䅁捁䅁䅁杔桂䡁䅍䅚桂䡁䅅睒呂䑁䅯兓佂䕁䅍兗䅁䥁䅷䅁捁䅁䅁杔桂䡁䅍䅚桂䡁䅅睒呂䑁䅯兓佂䙁䅑睑䅁佁䅁䅁捁䅁䅁杔桂䡁䅍䅚桂䡁䅅睒呂䑁䅯兓佂䙁䅑兖䅁偁䅙䅁捁䅁䅁杔桂䡁䅍䅚桂䡁䅅睒呂䑁䅯兓呂䙁䅉睒䅁䑁䉯䅁捁䅁䅁杔桂䡁䅍䅚桂䡁䅅睒呂䑁䅯杓䍂䕁䅧䅖䅁䩁䅧䅁捁䅁䅁杔桂䡁䅍䅚桂䡁䅅睒呂䑁䅯杓䱂䕁䅧兗䅁䉁䉫䅁慁䅁䅁杔桂䡁䅍䅚桂䡁䅅睒呂䑁䅯睓䕂䙁䅁䅁㕃䅁䅁䅈䅁䕁䄴兙穂䝁䅑兙硂䕁䅣睕㙁䕁䅳䅔䉂䕁䅍䅁䥄䅁䅁杇䅁䕁䄴兙穂䝁䅑兙硂䕁䅣睕㙁䕁䅷兓佂䅁䅁朵䅁䉁䅯䅁佂䝁䅅督歂䝁䅅兣䡂䙁䅍杏䵂䕁䅳兕䅁䱁䅉䅁捁䅁䅁杔桂䡁䅍䅚桂䡁䅅睒呂䑁䅯䅔卂䕁䅍䅗䅁乁䅁䅁捁䅁䅁杔桂䡁䅍䅚桂䡁䅅睒呂䑁䅯䅔噂䕁䅷兖䅁偁䅅䅁慁䅁䅁杔桂䡁䅍䅚桂䡁䅅睒呂䑁䅯兔䉂䙁䅉䅁獄䅁䅁䅈䅁䕁䄴兙穂䝁䅑兙硂䕁䅣睕㙁䕁䄰睑䥂䙁䅁䅁㍄䅁䅁䅈䅁䕁䄴兙穂䝁䅑兙硂䕁䅣睕㙁䕁䄰䅒䵂䙁䅯䅁坁䅁䅁䅈䅁䕁䄴兙穂䝁䅑兙硂䕁䅣睕㙁䕁䄰兒啂䕁䅅䅁敁䅁䅁䅈䅁䕁䄴兙穂䝁䅑兙硂䕁䅣睕㙁䕁䄰睓啂䙁䅧䅁㉁䅁䅁䅈䅁䕁䄴兙穂䝁䅑兙硂䕁䅣睕㙁䕁䄰杔呂䙁䅑䅁㥁䅁䅁䅈䅁䕁䄴兙穂䝁䅑兙硂䕁䅣睕㙁䕁䄰䅕塂䙁䅉䅁湁允䅁䅈䅁䕁䄴兙穂䝁䅑兙硂䕁䅣睕㙁䕁䄰杕佂䕁䅅䅁䭂䅁䅁䅈䅁䕁䄴兙穂䝁䅑兙硂䕁䅣睕㙁䕁䄰睕䝂䙁䅑䅁䡄䅁䅁䅈䅁䕁䄴兙穂䝁䅑兙硂䕁䅣睕㙁䕁䄰䅖䑂䕁䅧䅁癁允䅁䅇䅁䕁䄴兙穂䝁䅑兙硂䕁䅣睕㙁䕁䄰兖䅁䑁䉣䅁捁䅁䅁杔桂䡁䅍䅚桂䡁䅅睒呂䑁䅯杔䕂䕁䅅兕䅁䙁䉅䅁捁䅁䅁杔桂䡁䅍䅚桂䡁䅅睒呂䑁䅯杔䕂䙁䅍杔䅁䙁䉷䅁捁䅁䅁杔桂䡁䅍䅚桂䡁䅅睒呂䑁䅯杔䝂䕁䅷䅗䅁䍁䉕䅁捁䅁䅁杔桂䡁䅍䅚桂䡁䅅睒呂䑁䅯杔啂䕁䅅䅕䅁偁䄴䅁捁䅁䅁杔桂䡁䅍䅚桂䡁䅅睒呂䑁䅯杔啂䙁䅉睕䅁䕁䅙䅁捁䅁䅁杔桂䡁䅍䅚桂䡁䅅睒呂䑁䅯杔坂䕁䅑兑䅁䍁䅑䅁慁䅁䅁杔桂䡁䅍䅚桂䡁䅅睒呂䑁䅯杔塂䙁䅍䅁乃䅁䅁䅈䅁䕁䄴兙穂䝁䅑兙硂䕁䅣睕㙁䕁䄴睖呂䕁䅅䅁呁允䅁䅈䅁䕁䄴兙穂䝁䅑兙硂䕁䅣睕㙁䕁䄴䅗兂䕁䅫䅁硁允䅁䅈䅁䕁䄴兙穂䝁䅑兙硂䕁䅣睕㙁䕁䄸䅒䝂䕁䅷䅁瑄䅁䅁䅇䅁䕁䄴兙穂䝁䅑兙硂䕁䅣睕㙁䕁䄸杔䅁䝁䅍䅁捁䅁䅁杔桂䡁䅍䅚桂䡁䅅睒呂䑁䅯睔卂䕁䅷兗䅁䕁䉁䅁捁䅁䅁杔桂䡁䅍䅚桂䡁䅅睒呂䑁䅯䅕偂䕁䅑䅒䅁䑁䉉䅁捁䅁䅁杔桂䡁䅍䅚桂䡁䅅睒呂䑁䅯䅖䙂䕁䅍䅓䅁䡁䅫䅁䅄杈䅁䍄䉁䅁䅁䅂䅁䅁䅍䅄䅁䅁䅯䅁䅁䅁䅯允䅁䅁䅯杁䅁䅁䅅䅁䉁䅁䅁权䑁䅁䅁䍄䉁䅁䅁䅂䅁䅁䅍䅄䅁䅁䅯睖䅁䅁䅯允䅁䅁䅯杍䅁䅁䅅䅁䉁䅁䅁兂歃䑣䬰㘱潐睐杷允䅁䅁䅑䅁䑁䅁䅷䅁䭁乁䅫䅁䭁䅁䅅䅁䭁䑁䅉䅁䉁䅁䅁允䅁䅁䅕⽷潕䥘䌯吵䴸䅉䅅䅁䕁䅁䅁睁䵁䅁䅁权桂䅁䅁权䉁䅁䅁权湁䅁䅁允䅁䅁䅅䅁䙁乁佮ㄹ橐捰⽳䍄䉁䅁䅁䅂䅁䅁䅍䅄䅁䅁䅯䄴䅁䅁䅯允䅁䅁䅯睄䅁䅁䅅䅁䉁䅁䅁兂浂浚浚浚坢睐杷允䅁䅁䅑䅁䑁䅁䅷䅁䭁䕁䉑䅁䭁䅁䅅䅁䭁䉁䅕䅁䉁䅁䅁允䅁䅁䅕䵮村䡳潊呷䴸䅉䅅䅁䕁䅁䅁睁䵁䅁䅁权䙂䅁䅁权䉁䅁䅁权扁䅁䅁允䅁䅁䅅䅁䙁䱁敧敨剴併⼴䍄䉁䅁䅁䅂䅁䅁䅍䅄䅁䅁䅯朸䅁䅁䅯允䅁䅁䅯充䅁䅁䅅䅁䉁䅁䅁兂䅁䅁䅁䅁㡄睐杷允䅁䅁䅑䅁䑁䅁䅷䅁䭁䅁䅳䅁䭁䅁䅫䅁䭁䅁䅯䅁䉁䅁䅁允䅁䉁䅑䱥㑑⼯⼯⼯䴸䅉䅅䅁䕁䅁䅁睁䵁䅁䅁权杄䅁䅁权䉁䅁䅁权祁䅁䅁允䅁䅁䅅䅁䙁䭁䠵場啯癲⼸䍄䉁䅁䅁䅂䅁䅁䅍䅄䅁䅁䅯睃䅁䅁䅯元䅁䅁䅯兌䅁䅁䅅䅁䉁䅁䅁䅆潂灭⼷⼯⼯眯杷允䅁䅁䅑䅁䑁䅁䅷䅁䭁䙁䅷䅁䭁䅁䅅䅁䭁䅁䅉䅁䉁䅁䅁允䅁䅁䅯睁䅁䅁杷允䅁䅁䅑䅁䑁䅁䅷䅁䭁䑁䅕䅁䭁䅁䅅䅁䭁䑁䅉䅁䉁䅁䅁允䅁䅁䅕㡪ㅌ䙋偹樹䴸䅉䅅䅁䕁䅁䅁睁䵁䅁䅁权楂䅁䅁权䉁䅁䅁权㝁䅁䅁允䅁䅁䅅䅁䙁䑁晶㑔堲獢⽉䍄䉁䅁䅁䅂䅁䅁䅍䅄䅁䅁䅯䅂䅁䅁䅯允䅁䅁䅯兂䅁䅁䅅䅁䉁䅁䅁兂桄桥畓⭒煈睐杷允䅁䅁䅑䅁䑁䅁䅷䅁䭁䵁䅅䅁䭁䅁䅅䅁䭁䉁䅕䅁䉁䅁䅁允䅁䅁䅕捺䵺䵺䵺䐷䴸䅉䅅䅁䕁䅁䅁睁䵁䅁䅁权䥁䅁䅁权䩁䅁䅁权䭁䅁䅁允䅁䅁䅅䅁啁䡁ど偏⼯⼯⼯䍄䉁䅁䅁䅂䅁䅁䅍䅄䅁䅁䅯睖䅁䅁䅯允䅁䅁䅯睏䅁䅁䅅䅁䉁䅁䅁兂偄ㄹ橐婰杶睐杷允䅁䅁䅑䅁䑁䅁䅷䅁䭁䡁䅧䅁䭁䅁䅅䅁䭁䉁䅅䅁䉁䅁䅁允䅁䅁䅕䘷㑇潈牘吶䴸䅉䅅䅁䕁䅁䅁睁䵁䅁䅁权㍁允䅁权䉁䅁䅁权噁䅁䅁允䅁䅁䅅䅁䙁䍁搯䅊䉡摬⽳䍄䉁䅁䅁䅂䅁䅁䅍䅄䅁䅁䅯睗䅁䅁䅯允䅁䅁䅯杉䅁䅁䅅䅁䉁䅁䅁兂呄坔光䑗桫䅷杷允䅁䅁䅑䅁䑁䅁䅷䅁䭁䝁䄸䅁䭁䅁䅅䅁䭁䉁䅅䅁䉁䅁䅁允䅁䅁䅕灳瘳㡰䱚稵䴸䅉䅅䅁䕁䅁䅁睁䵁䅁䅁权䝁䅁䅁权䉁䅁䅁权䡁䅁䅁允䅁䅁䅅䅁䙁䭁䠵場啯瑲⽣䍄䉁䅁䅁䅂䅁䅁䅍䅄䅁䅁䅯杲䅁䅁䅯允䅁䅁䅯兇䅁䅁䅅䅁䉁䅁䅁兂偃癷潕䥘䴸䅑杷允䅁䅁䅑䅁䑁䅁䅷䅁䭁䅁䅷䅁䭁䅁䅅䅁䭁䅁䄰䅁䉁䅁䅁允䅁䅁䅕⽷潕䥘䌯吸䴸䅉䅅䅁䕁䅁䅁睁䵁䅁䅁权杂䅁䅁权䉁䅁䅁权㍁䅁䅁允䅁䅁䅅䅁䙁䩁瑈䑦ㄸ畘⽉䍄䉁䅁䅁䅂䅁䅁䅍䅄䅁䅁䅯兖䅅䅁䅯允䅁䅁䅯睎䅁䅁䅅䅁䉁䅁䅁兂䭁㘱睎児湲睐杷允䅁䅁䅑䅁䑁䅁䅷䅁䭁䡁䄸䅁䭁䅁䅅䅁䭁䅁䄰䅁䉁䅁䅁允䅁䅁䅕捺䵺䵺䵺䐸䴸䅉䅅䅁䕁䅁䅁睁䵁䅁䅁权呃䅁䅁权䉁䅁䅁权䭁䅁䅁允䅁䅁䅅䅁䙁䵁䴳䵺䵺䉺䅚䍄䉁䅁䅁䅂䅁䅁䅍䅄䅁䅁䅯䅣䅁䅁䅯允䅁䅁䅯睄䅁䅁䅅䅁䉁䅁䅁兂㝂䭆䠵場歱睐杷允䅁䅁䅑䅁䑁䅁䅷䅁䭁佁䅧䅁䭁䅁䅅䅁䭁䍁䅍䅁䉁䅁䅁允䅁䅁䅕㘱睎児塲啉䵁䅉䅅䅁䕁䅁䅁睁䵁䅁䅁权䥁䅁䅁权䩁䅁䅁权瑁䅁䅁允䅁䅁䅅䅁啁䝁慩癮⼯⼯⼯䍄䉁䅁䅁䅂䅁䅁䅍䅄䅁䅁䅯杒䅁䅁䅯允䅁䅁䅯兓䅁䅁䅅䅁䉁䅁䅁兂灁䥘䌯匹㑪睐杷允䅁䅁䅑䅁䑁䅁䅷䅁䭁䅁䉧䅁䭁䅁䅅䅁䭁䅁䄸䅁䉁䅁䅁允䅁䅁䅕潂噇㑑獴啁䵁䅉䅅䅁䕁䅁䅁睁䵁䅁䅁权潁允䅁权䉁䅁䅁权噁䅁䅁允䅁䅁䅅䅁䙁䉁䑋䵷桱晒⼴䍄䉁䅁䅁䅂䅁䅁䅍䅄䅁䅁䅯杅䅁䅁䅯允䅁䅁䅯睉䅁䅁䅅䅁䉁䅁䅁兂ㅁ牘䩰䅄呌睐杷允䅁䅁䅑䅁䑁䅁䅷䅁䭁䑁䅷䅁䭁䅁䅅䅁䭁䅁䅯䅁䉁䅁䅁允䅁䅁䅕䡶呓䅇坒い䵁䅉䅅䅁䕁䅁䅁睁䵁䅁䅁权䑂䅁䅁权䉁䅁䅁权䩂䅁䅁允䅁䅁䅅䅁䙁䑁積積積㥍⽍䍄䉁䅁䅁䅂䅁䅁䅍䅄䅁䅁䅯䅓䅁䅁䅯允䅁䅁䅯兌䅁䅁䅅䅁䉁䅁䅁兂汄䌰扌堫〷睐杷允䅁䅁䅑䅁䑁䅁䅷䅁䭁䥁䅯䅁䭁䅁䅅䅁䭁䉁䅫䅁䉁䅁䅁允䅁䅁䅕灭婭婭婭吴䴸䅉䅅䅁䕁䅁䅁睁䵁䅁䅁权兂䅁䅁权䩁䅁䅁权䩂䅁䅁允䅁䅁䅅䅁啁佁㍧⽊⼯⼯⼯䍄䉁䅁䅁䅂䅁䅁䅍䅄䅁䅁䅯杄䅁䅁䅯允䅁䅁䅯睄䅁䅁䅅䅁䉁䅁䅁兂㑃潈牘払䝧䅑杷允䅁䅁䅑䅁䑁䅁䅷䅁䭁䑁䄸䅁䭁䅁䅅䅁䭁䍁䄰䅁䉁䅁䅁允䅁䅁䅕へ㍳啩杆吳䴸䅉䅅䅁䕁䅁䅁睁䵁䅁䅁权坄䅁䅁权䉁䅁䅁权䙁䅁䅁允䅁䅁䅅䅁䙁䱁敧敨剴偵⽉䍄䉁䅁䅁䅂䅁䅁䅍䅄䅁䅁䅯眳䅁䅁䅯允䅁䅁䅯睉䅁䅁䅅䅁䉁䅁䅁兂䑄匹捨㡪䙌睐杷允䅁䅁䅑䅁䑁䅁䅷䅁䭁䍁䉯䅁䭁䅁䅅䅁䭁䑁䅣䅁䉁䅁䅁允䅁䅁䅕噈歰㥏倹吴䴸䅉䅅䅁䕁䅁䅁睁䵁䅁䅁权䑂䅁䅁权䉁䅁䅁权偁䅁䅁允䅁䅁䅅䅁䙁䕁桪桥畓⭒⽅䍄䉁䅁䅁䅂䅁䅁䅍䅄䅁䅁䅯共䅁䅁䅯允䅁䅁䅯兘䅁䅁䅅䅁䉁䅁䅁兂歃䑣䬰㘱䵍䅑杷允䅁䅁䅑䅁䑁䅁䅷䅁䭁䕁䅑䅁䭁䅁䅅䅁䭁䍁䅣䅁䉁䅁䅁允䅁䅁䅕癱午坔光䐰䴸䅉䅅䅁䕁䅁䅁睁䵁䅁䅁权䥃䅁䅁权䉁䅁䅁权乁䅁䅁允䅁䅁䅅䅁䙁䅁塲㍯㥁獃⽣䍄䉁䅁䅁䅂䅁䅁䅍䅄䅁䅁䅯眸䅁䅁䅯允䅁䅁䅯睏䅁䅁䅅䅁䉁䅁䅁兂灁䥘䌯匹睪睐杷允䅁䅁䅑䅁䑁䅁䅷䅁䭁偁䅙䅁䭁䅁䅅䅁䭁䍁䅧䅁䉁䅁䅁允䅁䅁䅕㥉㕶浦㡱䱴䴸䅉䅅䅁䕁䅁䅁睁䵁䅁䅁权䥁䅁䅁权䩁䅁䅁权䍁䅁䅁允䅁䅁䅅䅁啁䝁煁癊⼯⼯⼯䍄䉁䅁䅁䅂䅁䅁䅍䅄䅁䅁䅯睄䅅䅁䅯允䅁䅁䅯兓䅁䅁䅅䅁䉁䅁䅁兂啁歲桦桥浔睐杷允䅁䅁䅑䅁䑁䅁䅷䅁䭁偁䅍䅁䭁䅁䅅䅁䭁䙁䄰䅁䉁䅁䅁允䅁䅁䅕㑈牘払敧吵䴸䅉䅅䅁䕁䅁䅁睁䵁䅁䅁权坁允䅁权䉁䅁䅁权㝁䅁䅁允䅁䅁䅅䅁䙁䥁䅐煹䙆桎䅊䍄䉁䅁䅁䅂䅁䅁䅍䅄䅁䅁䅯睃䅁䅁䅯元䅁䅁䅯兄䅁䅁䅅䅁䉁䅁䅁䅆潂慶⼳⼯⼯眯杷允䅁䅁䅑䅁䑁䅁䅷䅁䭁䍁䈴䅁䭁䅁䅅䅁䭁䉁䅕䅁䉁䅁䅁允䅁䅁䅕〳丫㉬匴稵䴸䅉䅅䅁䕁䅁䅁睁䵁䅁䅁权睃䅁䅁权䉁䅁䅁权䅂䅁䅁允䅁䅁䅅䅁䙁䉁䘫ㄶ㑇癈⼰䍄䉁䅁䅁䅂䅁䅁䅍䅄䅁䅁䅯睃䅁䅁䅯元䅁䅁䅯杁䅁䅁䅅䅁䉁䅁䅁䅆杂楋⽢⼯⼯眯杷允䅁䅁䅑䅁䑁䅁䅷䅁䭁佁䅉䅁䭁䅁䅅䅁䭁䕁䅁䅁䉁䅁䅁允䅁䅁䅕䥘䌯匹捨稵䴸䅉䅅䅁䕁䅁䅁睁䵁䅁䅁权ㅄ䅁䅁权䉁䅁䅁权䙁䅁䅁允䅁䅁䅅䅁䙁䭁䠵場啯畲⽣䍄䉁䅁䅁䅂䅁䅁䅍䅄䅁䅁䅯䅅䅁䅁䅯允䅁䅁䅯充䅁䅁䅅䅁䉁䅁䅁兂㝂䭆䠵場ひ睐杷允䅁䅁䅑䅁䑁䅁䅷䅁䭁䝁䅁䅁䭁䅁䅅䅁䭁䍁䅍䅁䉁䅁䅁允䅁䅁䅕硨婢発呤稵䴸䅉䅅䅁䕁䅁䅁睁䵁䅁䅁权坁䅁䅁权䉁䅁䅁权捁䅁䅁允䅁䅁䅅䅁䙁䉁婦発呤⬴⽫䍄䉁䅁䅁䅂䅁䅁䅍䅄䅁䅁䅯兏䅁䅁䅯允䅁䅁䅯兘䅁䅁䅅䅁䉁䅁䅁兂啁歲桦桥畔睐杷允䅁䅁䅑䅁䑁䅁䅷䅁䭁䵁䅑䅁䭁䅁䅅䅁䭁䑁䅳䅁䉁䅁䅁允䅁䅁䅕体㙆䭆䠵吴䴸䅉䅅䅁䕁䅁䅁睁䵁䅁䅁权獄䅁䅁权䉁䅁䅁权㝁䅁䅁允䅁䅁䅅䅁䙁䡁㥅瑃橥佣⽕䍄䉁䅁䅁䅂䅁䅁䅍䅄䅁䅁䅯兏䅁䅁䅯允䅁䅁䅯睊䅁䅁䅅䅁䉁䅁䅁兂畃⭒㙆䭆㌷睐杷允䅁䅁䅑䅁䑁䅁䅷䅁䭁䝁䄰䅁䭁䅁䅅䅁䭁䍁䅍䅁䉁䅁䅁允䅁䅁䅕㙹䙆癴㥐䑸䴸䅉䅅䅁䕁䅁䅁睁䵁䅁䅁权奃䅁䅁权䉁䅁䅁权呁䅁䅁允䅁䅁䅅䅁䙁䡁㥅瑃橥偣⽅䍄䉁䅁䅁䅂䅁䅁䅍䅄䅁䅁䅯朱䅁䅁䅯允䅁䅁䅯兇䅁䅁䅅䅁䉁䅁䅁兂㍁啩杆搵煄睐杷允䅁䅁䅑䅁䑁䅁䅷䅁䭁䥁䅉䅁䭁䅁䅅䅁䭁䉁䅷䅁䉁䅁䅁允䅁䅁䅕硢䑋䵷桱吶䴸䅉䅅䅁䕁䅁䅁睁䵁䅁䅁权晁䅁䅁权䉁䅁䅁权杁䅁䅁允䅁䅁䅅䅁䙁䩁䑚㉩湺⼫⽣䍄䉁䅁䅁䅂䅁䅁䅍䅄䅁䅁䅯睫䅁䅁䅯允䅁䅁䅯兇䅁䅁䅅䅁䉁䅁䅁兂䅁䅁䅁䅁䕁䅑杷允䅁䅁䅑䅁䑁䅁䅷䅁䭁䕁䅉䅁䭁䅁䅅䅁䭁䕁䅁䅁䉁䅁䅁允䅁䅁䅕歯㉗⼸唳䐴䴸䅉䅅䅁䕁䅁䅁睁䵁䅁䅁权牁䅁䅁权䉁䅁䅁权䭁䅁䅁允䅁䅁䅅䅁䙁䭁睒児塲⽯⽑䍄䉁䅁䅁䅂䅁䅁䅍䅄䅁䅁䅯䅁䅅䅁䅯允䅁䅁䅯䅉䅁䅁䅅䅁䉁䅁䅁兂牁硨婢発乣䅑杷允䅁䅁䅑䅁䑁䅁䅷䅁䭁䡁䅧䅁䭁䅁䅅䅁䭁䍁䅧䅁䉁䅁䅁允䅁䅁䅕倹唳佥浫吴䴸䅉䅅䅁䕁䅁䅁睁䵁䅁䅁权佂允䅁权䉁䅁䅁权捁䅁䅁允䅁䅁䅅䅁䙁䥁坣挲㌷睕䅄䍄䉁䅁䅁䅂䅁䅁䅍䅄䅁䅁䅯兪䅁䅁䅯允䅁䅁䅯睅䅁䅁䅅䅁䉁䅁䅁兂捃䍸睃浣剩睐杷允䅁䅁䅑䅁䑁䅁䅷䅁䭁䉁䅉䅁䭁䅁䅅䅁䭁䉁䅍䅁䉁䅁䅁允䅁䅁䅕婧䑖㉩湺穹䴸䅉䅅䅁䕁䅁䅁睁䵁䅁䅁权敁䅁䅁权時允䅁权㍁䅁䅁允䅁䅁䅅䅁啁䭁奁杵䅁䅁䅁䍄䉁䅁䅁䅂䅁䅁䅍䅄䅁䅁䅯䅐䅁䅁䅯允䅁䅁䅯睊䅁䅁䅅䅁䉁䅁䅁兂偃癷潕䥘䜸䅑杷允䅁䅁䅑䅁䑁䅁䅷䅁䭁䵁䅕䅁䭁䅁䅅䅁䭁䑁䅣䅁䉁䅁䅁允䅁䅁䅕㑋坣挲㌷啅䵁䅉䅅䅁䕁䅁䅁睁䵁䅁䅁权歁䅁䅁权䉁䅁䅁权乁䅁䅁允䅁䅁䅅䅁䙁䩁婱婭婭婭⽫䍄䉁䅁䅁䅂䅁䅁䅍䅄䅁䅁䅯兵䅁䅁䅯允䅁䅁䅯兂䅁䅁䅅䅁䉁䅁䅁兂灁䥘䌯匹㡩睐杷允䅁䅁䅑䅁䑁䅁䅷䅁䭁䙁䄴䅁䭁䅁䅅䅁䭁䍁䅣䅁䉁䅁䅁允䅁䅁䅕匳䝑婧䑖稸䴸䅉䅅䅁䕁䅁䅁睁䵁䅁䅁权硄䅁䅁权䉁䅁䅁权潁䅁䅁允䅁䅁䅅䅁䙁䑁積積積睍䅬䍄䉁䅁䅁䅂䅁䅁䅍䅄䅁䅁䅯杌䅁䅁䅯允䅁䅁䅯䅉䅁䅁䅅䅁䉁䅁䅁兂摄䅊䉡啬硐睐杷允䅁䅁䅑䅁䑁䅁䅷䅁䭁䑁䄴䅁䭁䅁䅅䅁䭁䅁䅣䅁䉁䅁䅁允䅁䅁䅕硫䕧杖琴樴䴸䅉䅅䅁䕁䅁䅁睁䵁䅁䅁权ㅂ䅁䅁权䉁䅁䅁权偁䅁䅁允䅁䅁䅅䅁䙁䭁睒児塲㥯⽁䍄䉁䅁䅁䅂䅁䅁䅍䅄䅁䅁䅯朶䅁䅁䅯允䅁䅁䅯䅉䅁䅁䅅䅁䉁䅁䅁兂捂㡪ㅌ䙋湺睐杷允䅁䅁䅑䅁䑁䅁䅷䅁䭁䉁䅑䅁䭁䅁䅅䅁䭁䉁䅕䅁䉁䅁䅁允䅁䅁䅕噋偹癷潕樫䴸䅉䅅䅁䕁䅁䅁睁䵁䅁䅁权灁䅁䅁权䉁䅁䅁权䍁䅁䅁允䅁䅁䅅䅁䭁䅁䅍䅁䵁䅉䅅䅁䕁䅁䅁睁䵁䅁䅁权䭃䅁䅁权䉁䅁䅁权潁䅁䅁允䅁䅁䅅䅁䙁䭁䠵場啯畲⼸䍄䉁䅁䅁䅂䅁䅁䅍䅄䅁䅁䅯杖䅅䅁䅯允䅁䅁䅯杉䅁䅁䅅䅁䉁䅁䅁兂晁敨剴䉵砷睐杷允䅁䅁䅑䅁䑁䅁䅷䅁䭁䕁䅉䅁䭁䅁䅅䅁䭁䑁䅳䅁䉁䅁䅁允䅁䅁䅕䡳潊敫㠱稱䴸䅉䅅䅁䕁䅁䅁睁䵁䅁䅁权畃䅁䅁权䉁䅁䅁权祁䅁䅁允䅁䅁䅅䅁䙁䡁㥅瑃橥䅣䅖䍄䉁䅁䅁䅂䅁䅁䅍䅄䅁䅁䅯児䅅䅁䅯允䅁䅁䅯睂䅁䅁䅅䅁䉁䅁䅁兂煂䡶呓䅇浔睐杷允䅁䅁䅑䅁䑁䅁䅷䅁䭁䑁䅙䅁䭁䅁䅅䅁䭁䑁䅣䅁䉁䅁䅁允䅁䅁䅕硥畓⭒㙆䐯䴸䅉䅅䅁䕁䅁䅁睁䵁䅁䅁权㑄䅁䅁权䉁䅁䅁权䭁䅁䅁允䅁䅁䅅䅁䙁䱁䥔牤昶癇⽳䍄䉁䅁䅁䅂䅁䅁䅍䅄䅁䅁䅯睭䅁䅁䅯允䅁䅁䅯睂䅁䅁䅅䅁䉁䅁䅁兂䕁杖琴灳堳睐杷允䅁䅁䅑䅁䑁䅁䅷䅁䭁乁䄰䅁䭁䅁䅅䅁䭁䍁䅧䅁䉁䅁䅁允䅁䅁䅕歵䵫楁䡵䐯䴸䅉䅅䅁䕁䅁䅁睁䵁䅁䅁权ㅄ䅁䅁权䉁䅁䅁权扁䅁䅁允䅁䅁䅅䅁䙁䱁敧敨剴偵⽉䍄䉁䅁䅁䅂䅁䅁䅍䅄䅁䅁䅯䅄䅁䅁䅯允䅁䅁䅯兇䅁䅁䅅䅁䉁䅁䅁兂㝂䭆䠵場ひ睐杷允䅁䅁䅑䅁䑁䅁䅷䅁䭁䝁䅷䅁䭁䅁䅅䅁䭁䉁䅅䅁䉁䅁䅁允䅁䅁䅕䉵䘶ㄶ㑇䕇䵁䅉䅅䅁䕁䅁䅁睁䵁䅁䅁权⽃䅁䅁权䉁䅁䅁权婁䅁䅁允䅁䅁䅅䅁䙁䱁へ硫䕧瑖⽙䍄䉁䅁䅁䅂䅁䅁䅍䅄䅁䅁䅯杅䅁䅁䅯允䅁䅁䅯睇䅁䅁䅅䅁䉁䅁䅁兂塄㍯㥁瑃扦睐杷允䅁䅁䅑䅁䑁䅁䅷䅁䭁䍁䉷䅁䭁䅁䅅䅁䭁䉁䅕䅁䉁䅁䅁允䅁䅁䅕渷⽷噎㘶䕁䵁䅉䅅䅁䕁䅁䅁睁䵁䅁䅁权䝁允䅁权䉁䅁䅁权婁䅁䅁允䅁䅁䅅䅁䙁偁潙䥘䌯改⽧䍄䉁䅁䅁䅂䅁䅁䅍䅄䅁䅁䅯杆䅁䅁䅯允䅁䅁䅯充䅁䅁䅅䅁䉁䅁䅁兂䭁㘱睎児湲睐杷允䅁䅁䅑䅁䑁䅁䅷䅁䭁䑁䉅䅁䭁䅁䅅䅁䭁䙁䄰䅁䉁䅁䅁允䅁䅁䅕䅁䅁䅁䅁䐹䴸䅉䅅䅁䕁䅁䅁睁䵁䅁䅁权穂䅁䅁权䉁䅁䅁权䭁䅁䅁允䅁䅁䅅䅁䙁䡁呗䅇坒癄⽵䍄䉁䅁䅁䅂䅁䅁䅍䅄䅁䅁䅯杵䅁䅁䅯允䅁䅁䅯睉䅁䅁䅅䅁䉁䅁䅁兂啁歲桦桥畔睐杷允䅁䅁䅑䅁䑁䅁䅷䅁䭁䉁䅣䅁䭁䅁䅅䅁䭁䉁䅍䅁䉁䅁䅁允䅁䅁䅕䥘䌯匹捨稷䴸䅉䅅䅁䕁䅁䅁睁䵁䅁䅁权坂允䅁权䉁䅁䅁权捁䅁䅁允䅁䅁䅅䅁䭁䅁䅍䅁䵁䅉䅅䅁䕁䅁䅁睁䵁䅁䅁权兂䅁䅁权䩁䅁䅁权湁䅁䅁允䅁䅁䅅䅁啁䭁湂晉⼯⼯⼯䍄䉁䅁䅁䅂䅁䅁䅍䅄䅁䅁䅯䅖䅁䅁䅯允䅁䅁䅯睂䅁䅁䅅䅁䉁䅁䅁兂㝂䭆䠵場䕯䅑杷允䅁䅁䅑䅁䑁䅁䅷䅁䭁䱁䅑䅁䭁䅁䅅䅁䭁䍁䅁䅁䉁䅁䅁允䅁䅁䅕牕敧敨剴䰲䴸䅉䅅䅁䕁䅁䅁睁䵁䅁䅁权允䅁䅁权䉁䅁䅁权扁䅁䅁允䅁䅁䅅䅁䙁佁剸䉵䘶眶䅖䍄䉁䅁䅁䅂䅁䅁䅍䅄䅁䅁䅯䅶䅁䅁䅯允䅁䅁䅯杍䅁䅁䅅䅁䉁䅁䅁兂䅁䅁䅁䅁潄睐杷允䅁䅁䅑䅁䑁䅁䅷䅁䭁䉁䅧䅁䭁䅁䅅䅁䭁䉁䅫䅁䉁䅁䅁允䅁䅁䅕硫䕧杖琴樫䴸䅉䅅䅁䕁䅁䅁睁䵁䅁䅁权摄䅁䅁权䉁䅁䅁权䡁䅁䅁允䅁䅁䅅䅁啁䅁䅉䅁䅁䅁䅁䍄䉁䅁䅁䅂䅁䅁䅍䅄䅁䅁䅯䅖䅅䅁䅯允䅁䅁䅯兇䅁䅁䅅䅁䉁䅁䅁兂ぃ䡹⭡确䉯䅑杷允䅁䅁䅑䅁䑁䅁䅷䅁䭁䙁䅁䅁䭁䅁䅫䅁䭁䍁䅍䅁䉁䅁䅁允䅁䉁䅑偧汳⼯⼯⼯䴸䅉䅅䅁䕁䅁䅁睁䵁䅁䅁权瑂䅁䅁权䉁䅁䅁权扁䅁䅁允䅁䅁䅅䅁䙁䙁乃㉬匴㡧⽁䍄䉁䅁䅁䅂䅁䅁䅍䅄䅁䅁䅯䅡䅁䅁䅯允䅁䅁䅯睉䅁䅁䅅䅁䉁䅁䅁兂㑃潈牘払㉪睐杷允䅁䅁䅑䅁䑁䅁䅷䅁䭁䭁䅉䅁䭁䅁䅅䅁䭁䅁䅉䅁䉁䅁䅁允䅁䅁䅯睁䅁䅁杷允䅁䅁䅑䅁䑁䅁䅷䅁䭁䝁䄰䅁䭁䅁䅅䅁䭁䍁䅣䅁䉁䅁䅁允䅁䅁䅕浗㝑〳丫穴䴸䅉䅅䅁䕁䅁䅁睁䵁䅁䅁权㉃䅁䅁权䉁䅁䅁权祁䅁䅁允䅁䅁䅅䅁䙁乁橥䑣䬰⼱⽣䍄䉁䅁䅁䅂䅁䅁䅍䅄䅁䅁䅯䅌䅅䅁䅯允䅁䅁䅯杉䅁䅁䅅䅁䉁䅁䅁兂䱃佢㝦晱卅䅑杷允䅁䅁䅑䅁䑁䅁䅷䅁䭁䉁䅯䅁䭁䅁䅅䅁䭁䅁䅉䅁䉁䅁䅁允䅁䅁䅕䡰㥁瑃橥䐯䴸䅉䅅䅁䕁䅁䅁睁䵁䅁䅁权䑁允䅁权䉁䅁䅁权䙁䅁䅁允䅁䅁䅅䅁䙁䙁㑋潈牘晕⽷䍄䉁䅁䅁䅂䅁䅁䅍䅄䅁䅁䅯兤䅁䅁䅯允䅁䅁䅯䅉䅁䅁䅅䅁䉁䅁䅁兂㍁啩杆搵卄睐杷允䅁䅁䅑䅁䑁䅁䅷䅁䭁䱁䄰䅁䭁䅁䅅䅁䭁䍁䄰䅁䉁䅁䅁允䅁䅁䅕䅄牉硨婢樸䴸䅉䅅䅁䕁䅁䅁睁䵁䅁䅁权流䅁䅁权䉁䅁䅁权湁䅁䅁允䅁䅁䅅䅁䙁佁㙆䭆䠵挴⽯䍄䉁䅁䅁䅂䅁䅁䅍䅄䅁䅁䅯睌䅁䅁䅯允䅁䅁䅯睂䅁䅁䅅䅁䉁䅁䅁兂䙃ㄶ㑇潈㍘睐杷允䅁䅁䅑䅁䑁䅁䅷䅁䭁䉁䅙䅁䭁䅁䅅䅁䭁䍁䅁䅁䉁䅁䅁允䅁䅁䅕㑎䉬余兘樲䴸䅉䅅䅁䕁䅁䅁睁䵁䅁䅁权牄䅁䅁权䉁䅁䅁权㝁䅁䅁允䅁䅁䅅䅁䙁䕁桪桥畓⽒⼰䍄䉁䅁䅁䅂䅁䅁䅍䅄䅁䅁䅯䅖䅅䅁䅯允䅁䅁䅯睄䅁䅁䅅䅁䉁䅁䅁兂㥁瑃橥䑣匰䅑杷允䅁䅁䅑䅁䑁䅁䅷䅁䭁䅁䉕䅁䭁䅁䅅䅁䭁䅁䄰䅁䉁䅁䅁允䅁䅁䅕免獩䙈歰稯䴸䅉䅅䅁䕁䅁䅁睁䵁䅁䅁权慁䅁䅁权䉁䅁䅁权扁䅁䅁允䅁䅁䅅䅁䙁䥁坣挲㌷⽕⽍䍄䉁䅁䅁䅂䅁䅁䅍䅄䅁䅁䅯朷䅁䅁䅯允䅁䅁䅯兆䅁䅁䅅䅁䉁䅁䅁兂䡃瑆佮ㄹ湐睐杷允䅁䅁䅑䅁䑁䅁䅷䅁䭁䥁䄰䅁䭁䅁䅅䅁䭁䅁䅣䅁䉁䅁䅁允䅁䅁䅕椹捨㡪ㅌ䰲䴸䅉䅅䅁䕁䅁䅁睁䵁䅁䅁权䍁允䅁权䉁䅁䅁权橁䅁䅁允䅁䅁䅅䅁䙁䱁祂䩡瑈偦⽅䍄䉁䅁䅁䅂䅁䅁䅍䅄䅁䅁䅯杌䅅䅁䅯允䅁䅁䅯睇䅁䅁䅅䅁䉁䅁䅁兂癁匳䝑婧硘睐杷允䅁䅁䅑䅁䑁䅁䅷䅁䭁䅁䅳䅁䭁䅁䅫䅁䭁䉁䅅䅁䉁䅁䅁允䅁䉁䅑䉋䙥⼯⼯⼯䴸䅉䅅䅁䕁䅁䅁睁䵁䅁䅁权癃䅁䅁权䉁䅁䅁权祁䅁䅁允䅁䅁䅅䅁䙁䥁牘払敧全䅎䍄䉁䅁䅁䅂䅁䅁䅍䅄䅁䅁䅯兑䅅䅁䅯允䅁䅁䅯充䅁䅁䅅䅁䉁䅁䅁兂㙄浦㡱䩤奏睶杷允䅁䅁䅑䅁䑁䅁䅷䅁䭁䕁䉫䅁䭁䅁䅅䅁䭁䉁䅍䅁䉁䅁䅁允䅁䅁䅕牕敧敨剶げ䵁䅉䅅䅁䕁䅁䅁睁䵁䅁䅁权䕁䅁䅁权䉁䅁䅁权捁䅁䅁允䅁䅁䅅䅁䙁䭁䠵場啯畲⽣䍄䉁䅁䅁䅂䅁䅁䅍䅄䅁䅁䅯先䅁䅁䅯允䅁䅁䅯睅䅁䅁䅅䅁䉁䅁䅁兂慃婭婭婭䙫䅑杷允䅁䅁䅑䅁䑁䅁䅷䅁䭁䕁䅧䅁䭁䅁䅅䅁䭁䍁䅁䅁䉁䅁䅁允䅁䅁䅕呦ㄸ牘䩰䐴䴸䅉䅅䅁䕁䅁䅁睁䵁䅁䅁权䥁䅁䅁权時允䅁权偁䅁䅁允䅁䅁䅅䅁啁䩁潂兴䅅䅁䅁䍄䉁䅁䅁䅂䅁䅁䅍䅄䅁䅁䅯杙䅁䅁䅯允䅁䅁䅯兂䅁䅁䅅䅁䉁䅁䅁兂婄発呤㘴牗睐杷允䅁䅁䅑䅁䑁䅁䅷䅁䭁䍁䅕䅁䭁䅁䅅䅁䭁䅁䅉䅁䉁䅁䅁允䅁䅁䅯睁䅁䅁杷允䅁䅁䅑䅁䑁䅁䅷䅁䭁䭁䄸䅁䭁䅁䅅䅁䭁䅁䄸䅁䉁䅁䅁允䅁䅁䅕体㙆䭆䠵启䴸䅉䅅䅁䕁䅁䅁睁䵁䅁䅁权楄䅁䅁权䉁䅁䅁权捁䅁䅁允䅁䅁䅅䅁䙁䑁䩥坑汄倰⽉䍄䉁䅁䅁䅂䅁䅁䅍䅄䅁䅁䅯杕䅅䅁䅯允䅁䅁䅯䅑䅁䅁䅅䅁䉁䅁䅁兂乄䵺䵺䵺䥷䅑杷允䅁䅁䅑䅁䑁䅁䅷䅁䭁䍁䅫䅁䭁䅁䅅䅁䭁䍁䅣䅁䉁䅁䅁允䅁䅁䅕塹⭡确癯呶䴸䅉䅅䅁䕁䅁䅁睁䵁䅁䅁权畃䅁䅁权䉁䅁䅁权㍁䅁䅁允䅁䅁䅅䅁䙁䩁婱婭婭六䅎䍄䉁䅁䅁䅂䅁䅁䅍䅄䅁䅁䅯睍䅁䅁䅯允䅁䅁䅯杁䅁䅁䅅䅁䉁䅁䅁兂偃癷潕䥘䜸䅑杷允䅁䅁䅑䅁䑁䅁䅷䅁䭁䙁䅁䅁䭁䅁䅫䅁䭁䉁䅳䅁䉁䅁䅁允䅁䉁䅑䕏捍⼯⼯⼯䴸䅉䅅䅁䕁䅁䅁睁䵁䅁䅁权畄䅁䅁权䉁䅁䅁权偁䅁䅁允䅁䅁䅅䅁䙁佁剸䉵䘶⬶⽫䍄䉁䅁䅁䅂䅁䅁䅍䅄䅁䅁䅯杇䅅䅁䅯允䅁䅁䅯兄䅁䅁䅅䅁䉁䅁䅁兂㝂䭆䠵場㑲睐杷允䅁䅁䅑䅁䑁䅁䅷䅁䭁䉁䄴䅁䭁䅁䅫䅁䭁䅁䅉䅁䉁䅁䅁允䅁䉁䅑佗橑⼯⼯⼯䴸䅉䅅䅁䕁䅁䅁睁䵁䅁䅁权⭃䅁䅁权䉁䅁䅁权橁䅁䅁允䅁䅁䅅䅁䙁䵁䴳䵺䵺偺⽑䍄䉁䅁䅁䅂䅁䅁䅍䅄䅁䅁䅯朰䅁䅁䅯允䅁䅁䅯兓䅁䅁䅅䅁䉁䅁䅁兂塄㍯㥁瑃㍦睐杷允䅁䅁䅑䅁䑁䅁䅷䅁䭁佁䅳䅁䭁䅁䅅䅁䭁䅁䅉䅁䉁䅁䅁允䅁䅁䅯睁䅁䅁杷允䅁䅁䅑䅁䑁䅁䅷䅁䭁䍁䉣䅁䭁䅁䅅䅁䭁䍁䅧䅁䉁䅁䅁允䅁䅁䅕浚浚浚浚䕁䵁䅉䅅䅁䕁䅁䅁睁䵁䅁䅁权䅂允䅁权䉁䅁䅁权䍁䅁䅁允䅁䅁䅅䅁䭁䅁䅍䅁䵁䅉䅅䅁䕁䅁䅁睁䵁䅁䅁权桁䅁䅁权䉁䅁䅁权楁䅁䅁允䅁䅁䅅䅁䙁䡁㥅瑃橥䅣䅖䍄䉁䅁䅁䅂䅁䅁䅍䅄䅁䅁䅯杗䅁䅁䅯允䅁䅁䅯充䅁䅁䅅䅁䉁䅁䅁兂䱄啯㉗⼸挳睐杷允䅁䅁䅑䅁䑁䅁䅷䅁䭁䥁䅫䅁䭁䅁䅅䅁䭁䉁䅷䅁䉁䅁䅁允䅁䅁䅕敨剴䉵䘶稸䴸䅉䅅䅁䕁䅁䅁睁䵁䅁䅁权䙄䅁䅁权䉁䅁䅁权潁䅁䅁允䅁䅁䅅䅁䙁䍁搯䅊䉡公䅴䍄䉁䅁䅁䅂䅁䅁䅍䅄䅁䅁䅯眫䅁䅁䅯允䅁䅁䅯睅䅁䅁䅅䅁䉁䅁䅁兂歂㥏倹婪坦睐杷允䅁䅁䅑䅁䑁䅁䅷䅁䭁䅁䅧䅁䭁䅁䅫䅁䭁䍁䅍䅁䉁䅁䅁允䅁䉁䅑䍑獏⼯⼯⼯䴸䅉䅅䅁䕁䅁䅁睁䵁䅁䅁权橃䅁䅁权䉁䅁䅁权瑁䅁䅁允䅁䅁䅅䅁䙁䩁婱婭婭晭⽅䍄䉁䅁䅁䅂䅁䅁䅍䅄䅁䅁䅯䅁䅁䅁䅯允䅁䅁䅯充䅁䅁䅅䅁䉁䅁䅁兂獄払敧敨硶睐杷允䅁䅁䅑䅁䑁䅁䅷䅁䭁䉁䅁䅁䭁䅁䅅䅁䭁䙁䄰䅁䉁䅁䅁允䅁䅁䅕䉵䘶ㄶ㑇樯䴸䅉䅅䅁䕁䅁䅁睁䵁䅁䅁权㕂䅁䅁权䉁䅁䅁权婁䅁䅁允䅁䅁䅅䅁䙁佁㙆䭆䠵戴⽯䍄䉁䅁䅁䅂䅁䅁䅍䅄䅁䅁䅯杈䅁䅁䅯元䅁䅁䅯睏䅁䅁䅅䅁䉁䅁䅁䅆睂㝲⼳⼯⼯眯杷允䅁䅁䅑䅁䑁䅁䅷䅁䭁䭁䅯䅁䭁䅁䅅䅁䭁䅁䅯䅁䉁䅁䅁允䅁䅁䅕児塲㍯㥁䕂䵁䅉䅅䅁䕁䅁䅁睁䵁䅁䅁权㕁䅁䅁权䉁䅁䅁权乁䅁䅁允䅁䅁䅅䅁䙁䅁塲㍯㥁畃⽣䍄䉁䅁䅁䅂䅁䅁䅍䅄䅁䅁䅯兏䅅䅁䅯允䅁䅁䅯兂䅁䅁䅅䅁䉁䅁䅁兂塄㍯㥁瑃䑦睐杷允䅁䅁䅑䅁䑁䅁䅷䅁䭁䕁䉍䅁䭁䅁䅅䅁䭁䙁䄰䅁䉁䅁䅁允䅁䅁䅕⼵灵搸乊䐹䴸䅉䅅䅁䕁䅁䅁睁䵁䅁䅁权䡂䅁䅁权䉁䅁䅁权祁䅁䅁允䅁䅁䅅䅁䙁䱁敧敨剴䅵䅚䍄䉁䅁䅁䅂䅁䅁䅍䅄䅁䅁䅯眲䅁䅁䅯允䅁䅁䅯睄䅁䅁䅅䅁䉁䅁䅁兂䭁㘱睎児䡲睐杷允䅁䅁䅑䅁䑁䅁䅷䅁䭁䍁䅕䅁䭁䅁䅅䅁䭁䍁䅁䅁䉁䅁䅁允䅁䅁䅕䉲慸䑚晶歂䵁䅉䅅䅁䕁䅁䅁睁䵁䅁䅁权䅃䅁䅁权䉁䅁䅁权䅂䅁䅁允䅁䅁䅅䅁䭁䅁䅍䅁䵁䅉䅅䅁䕁䅁䅁睁䵁䅁䅁权㥃䅁䅁权䉁䅁䅁权䅂䅁䅁允䅁䅁䅅䅁䙁䉁奂扏䥔畤⽉䍄䉁䅁䅁䅂䅁䅁䅍䅄䅁䅁䅯䅑䅅䅁䅯允䅁䅁䅯睎䅁䅁䅅䅁䉁䅁䅁兂偃癷潕䥘核䅑杷允䅁䅁䅑䅁䑁䅁䅷䅁䭁䅁䅳䅁䭁䅁䅫䅁䭁䍁䅍䅁䉁䅁䅁允䅁䉁䅑䍑獏⼯⼯⼯䴸䅉䅅䅁䕁䅁䅁睁䵁䅁䅁权䱁䅁䅁权䩁䅁䅁权潁䅁䅁允䅁䅁䅅䅁啁䑁䵄癎⼯⼯⼯䍄䉁䅁䅁䅂䅁䅁䅍䅄䅁䅁䅯睖䅁䅁䅯允䅁䅁䅯睄䅁䅁䅅䅁䉁䅁䅁兂硂児塲㍯汄睐杷允䅁䅁䅑䅁䑁䅁䅷䅁䭁䙁䅣䅁䭁䅁䅅䅁䭁䙁䄰䅁䉁䅁䅁允䅁䅁䅕浚浚浚浚樵䴸䅉䅅䅁䕁䅁䅁睁䵁䅁䅁权扂䅁䅁权䉁䅁䅁权杁䅁䅁允䅁䅁䅅䅁䙁䩁婱婭婭扭⽭䍄䉁䅁䅁䅂䅁䅁䅍䅄䅁䅁䅯兦䅁䅁䅯允䅁䅁䅯杍䅁䅁䅅䅁䉁䅁䅁兂䅁䅁䅁䅁杄睐杷允䅁䅁䅑䅁䑁䅁䅷䅁䭁䩁䅅䅁䭁䅁䅅䅁䭁䍁䄰䅁䉁䅁䅁允䅁䅁䅕㝤昶楇搯䐸䴸䅉䅅䅁䕁䅁䅁睁䵁䅁䅁权䵁䅁䅁权䉁䅁䅁权杁䅁䅁允䅁䅁䅅䅁䙁䩁婱婭婭六䅤䍄䉁䅁䅁䅂䅁䅁䅍䅄䅁䅁䅯䅌䅅䅁䅯允䅁䅁䅯睅䅁䅁䅅䅁䉁䅁䅁兂䑄匹捨㡪汌睐杷允䅁䅁䅑䅁䑁䅁䅷䅁䭁䍁䅯䅁䭁䅁䅅䅁䭁䍁䄰䅁䉁䅁䅁允䅁䅁䅕児塲㍯㥁歁䵁䅉䅅䅁䕁䅁䅁睁䵁䅁䅁权潃䅁䅁权䉁䅁䅁权偁䅁䅁允䅁䅁䅅䅁䙁偁卌坔光乗⽅䍄䉁䅁䅁䅂䅁䅁䅍䅄䅁䅁䅯䅴䅁䅁䅯允䅁䅁䅯䅈䅁䅁䅅䅁䉁䅁䅁兂扁㥌欰潂噇睶杷允䅁䅁䅑䅁䑁䅁䅷䅁䭁䙁䅁䅁䭁䅁䅫䅁䭁䅁䅯䅁䉁䅁䅁允䅁䉁䅑乯浩瘯⼯⼯䴸䅉䅅䅁䕁䅁䅁睁䵁䅁䅁权楁允䅁权䉁䅁䅁权橁䅁䅁允䅁䅁䅅䅁䙁䕁桪桥畓⽒⽅䍄䉁䅁䅁䅂䅁䅁䅍䅄䅁䅁䅯眹䅁䅁䅯允䅁䅁䅯睊䅁䅁䅅䅁䉁䅁䅁兂歃䑣䬰㘱潐睐杷允䅁䅁䅑䅁䑁䅁䅷䅁䭁䍁䅕䅁䭁䅁䅅䅁䭁䉁䅅䅁䉁䅁䅁允䅁䅁䅕⽷潕䥘䌯吹䴸䅉䅅䅁䕁䅁䅁睁䵁䅁䅁权卂允䅁权䉁䅁䅁权扁䅁䅁允䅁䅁䅅䅁䙁䭁䠵場啯桲䅒䍄䉁䅁䅁䅂䅁䅁䅍䅄䅁䅁䅯睯䅁䅁䅯允䅁䅁䅯睅䅁䅁䅅䅁䉁䅁䅁兂灄橊䥅䉲畺睐杷允䅁䅁䅑䅁䑁䅁䅷䅁䭁䕁䄴䅁䭁䅁䅅䅁䭁䅁䅉䅁䉁䅁䅁允䅁䅁䅕積積積積䕃䵁䅉䅅䅁䕁䅁䅁睁䵁䅁䅁权兂䅁䅁权䩁䅁䅁权䍁䅁䅁允䅁䅁䅅䅁䭁䅁䅍䅁䵁䅉䅅䅁䕁䅁䅁睁䵁䅁䅁权䉄䅁䅁权䉁䅁䅁权捁䅁䅁允䅁䅁䅅䅁䙁偁周㘴扗偸⽁䍄䉁䅁䅁䅂䅁䅁䅍䅄䅁䅁䅯䅃䅁䅁䅯元䅁䅁䅯䅋䅁䅁䅅䅁䉁䅁䅁䅆睁䑺⽢⼯⼯眯杷允䅁䅁䅑䅁䑁䅁䅷䅁䭁䥁䅍䅁䭁䅁䅅䅁䭁䍁䅧䅁䉁䅁䅁允䅁䅁䅕穊䥅䉲慸䐫䴸䅉䅅䅁䕁䅁䅁睁䵁䅁䅁权睄䅁䅁权䉁䅁䅁权摂䅁䅁允䅁䅁䅅䅁䙁佁剸䉵䘶⼶⽕䍄䉁䅁䅁䅂䅁䅁䅍䅄䅁䅁䅯杤䅁䅁䅯允䅁䅁䅯兘䅁䅁䅅䅁䉁䅁䅁兂楂䙅㕧䵴䥧䅑杷允䅁䅁䅑䅁䑁䅁䅷䅁䭁䱁䅫䅁䭁䅁䅅䅁䭁䑁䅣䅁䉁䅁䅁允䅁䅁䅕積積積積穷䴸䅉䅅䅁䕁䅁䅁睁䵁䅁䅁权癁䅁䅁权䉁䅁䅁权偁䅁䅁允䅁䅁䅅䅁䙁䵁䴳䵺䵺佺⽷䍄䉁䅁䅁䅂䅁䅁䅍䅄䅁䅁䅯杇䅁䅁䅯允䅁䅁䅯兌䅁䅁䅅䅁䉁䅁䅁兂卂䉵䘶ㄶ獈睐杷允䅁䅁䅑䅁䑁䅁䅷䅁䭁佁䅧䅁䭁䅁䅅䅁䭁䅁䅉䅁䉁䅁䅁允䅁䅁䅕⽷潕䥘䌹啊䵁䅉䅅䅁䕁䅁䅁睁䵁䅁䅁权煁䅁䅁权䉁䅁䅁权噁䅁䅁允䅁䅁䅅䅁䙁乁橥䑣䬰⬱⽳䍄䉁䅁䅁䅂䅁䅁䅍䅄䅁䅁䅯睯䅁䅁䅯允䅁䅁䅯杍䅁䅁䅅䅁䉁䅁䅁兂慃婭婭婭确睐杷允䅁䅁䅑䅁䑁䅁䅷䅁䭁䵁䅫䅁䭁䅁䅅䅁䭁䅁䅯䅁䉁䅁䅁允䅁䅁䅕灳瘳㡰䱚㜴䴸䅉䅅䅁䕁䅁䅁睁䵁䅁䅁权㑄䅁䅁权䉁䅁䅁权㝁䅁䅁允䅁䅁䅅䅁䙁䙁偹癷潕偘⽅䍄䉁䅁䅁䅂䅁䅁䅍䅄䅁䅁䅯杈䅁䅁䅯睘䅅䅁䅯兘䅁䅁䅅䅁䉁䅁䅁䅆兂䱺䅯䅁䅁䅁杷允䅁䅁䅑䅁䑁䅁䅷䅁䭁䑁䅁䅁䭁䅁䅅䅁䭁䍁䅉䅁䉁䅁䅁允䅁䅁䅕䵮村䡳潊呷䴸䅉䅅䅁䕁䅁䅁睁䵁䅁䅁权流允䅁权䉁䅁䅁权杁䅁䅁允䅁䅁䅅䅁䙁䵁㉬灶愸⭌⽅䍄䉁䅁䅁䅂䅁䅁䅍䅄䅁䅁䅯䅌䅅䅁䅯允䅁䅁䅯睎䅁䅁䅅䅁䉁䅁䅁兂䉄煹䙆湴塍䅑杷允䅁䅁䅑䅁䑁䅁䅷䅁䭁䉁䅣䅁䭁䅁䅅䅁䭁䍁䄰䅁䉁䅁䅁允䅁䅁䅕癴㥐䠱灪䕂䵁䅉䅅䅁䕁䅁䅁睁䵁䅁䅁权㥃䅁䅁权䉁䅁䅁权婁䅁䅁允䅁䅁䅅䅁䙁偁潙䥘䌯昹⽁䍄䉁䅁䅁䅂䅁䅁䅍䅄䅁䅁䅯杕䅅䅁䅯允䅁䅁䅯兄䅁䅁䅅䅁䉁䅁䅁兂慃婭婭婭卫䅑杷允䅁䅁䅑䅁䑁䅁䅷䅁䭁佁䄴䅁䭁䅁䅅䅁䭁䅁䅯䅁䉁䅁䅁允䅁䅁䅕灭婭婭婭吶䴸䅉䅅䅁䕁䅁䅁睁䵁䅁䅁权䵁䅁䅁权䉁䅁䅁权呁䅁䅁允䅁䅁䅅䅁䙁䍁捬㡪ㅌ偋⽁䍄䉁䅁䅁䅂䅁䅁䅍䅄䅁䅁䅯睡䅁䅁䅯允䅁䅁䅯睎䅁䅁䅅䅁䉁䅁䅁兂䑄匹捨㡪汌睐杷允䅁䅁䅑䅁䑁䅁䅷䅁䭁䡁䅅䅁䭁䅁䅅䅁䭁䉁䅅䅁䉁䅁䅁允䅁䅁䅕㡪ㅌ䙋偹歁䵁䅉䅅䅁䕁䅁䅁睁䵁䅁䅁权㙃䅁䅁权䉁䅁䅁权䩂䅁䅁允䅁䅁䅅䅁䙁䕁桪桥畓⭒⽫䍄䉁䅁䅁䅂䅁䅁䅍䅄䅁䅁䅯村䅁䅁䅯允䅁䅁䅯睂䅁䅁䅅䅁䉁䅁䅁兂ぃ䡹⭡确晲睐杷允䅁䅁䅑䅁䑁䅁䅷䅁䭁䅁䉷䅁䭁䅁䅅䅁䭁䉁䅕䅁䉁䅁䅁允䅁䅁䅕㝤昶楇搯爫䴸䅉䅅䅁䕁䅁䅁睁䵁䅁䅁权煁䅁䅁权䉁䅁䅁权䍁䅁䅁允䅁䅁䅅䅁䭁䅁䅍䅁䵁䅉䅅䅁䕁䅁䅁睁䵁䅁䅁权硂䅁䅁权䉁䅁䅁权㍁䅁䅁允䅁䅁䅅䅁䙁䝁渳㘫确朰䄹䍄䉁䅁䅁䅂䅁䅁䅍䅄䅁䅁䅯朷䅁䅁䅯允䅁䅁䅯䅑䅁䅁䅅䅁䉁䅁䅁䅆䉁䅁䅁䅁䅁䅁杷允䅁䅁䅑䅁䑁䅁䅷䅁䭁䍁䅷䅁䭁䅁䅅䅁䭁䍁䅉䅁䉁䅁䅁允䅁䅁䅕捺䵺䵺䵺䕁䵁䅉䅅䅁䕁䅁䅁睁䵁䅁䅁权歃䅁䅁权䉁䅁䅁权湁䅁䅁允䅁䅁䅅䅁䭁䭁䅕䅁䵁䅉䅅䅁䕁䅁䅁睁䵁䅁䅁权䝂允䅁权䉁䅁䅁权噁䅁䅁允䅁䅁䅅䅁䭁䅁䅍䅁䵁䅉䅅䅁䕁䅁䅁睁䵁䅁䅁权䥁䅁䅁权䩁䅁䅁权扁䅁䅁允䅁䅁䅅䅁啁䍁㉃偓⼯⼯⼯䍄䉁䅁䅁䅂䅁䅁䅍䅄䅁䅁䅯杗䅁䅁䅯允䅁䅁䅯兇䅁䅁䅅䅁䉁䅁䅁兂汄䌰扌堫焷睐杷允䅁䅁䅑䅁䑁䅁䅷䅁䭁䙁䅁䅁䭁䅁䅫䅁䭁䉁䅅䅁䉁䅁䅁允䅁䉁䅑䨶䉖⼯⼯⼯䴸䅉䅅䅁䕁䅁䅁睁䵁䅁䅁权偂允䅁权䉁䅁䅁权䭁䅁䅁允䅁䅁䅅䅁䙁䱁敧敨剴䉵䅰䍄䉁䅁䅁䅂䅁䅁䅍䅄䅁䅁䅯睃䅁䅁䅯元䅁䅁䅯睇䅁䅁䅅䅁䉁䅁䅁䅆杁歴⽪⼯⼯眯杷允䅁䅁䅑䅁䑁䅁䅷䅁䭁䕁䅣䅁䭁䅁䅅䅁䭁䙁䄰䅁䉁䅁䅁允䅁䅁䅕䅁䅁䅁䅁䕂䵁䅉䅅䅁䕁䅁䅁睁䵁䅁䅁权硁䅁䅁权䉁䅁䅁权捁䅁䅁允䅁䅁䅅䅁䙁䵁䴳䵺䵺偺⽑䍄䉁䅁䅁䅂䅁䅁䅍䅄䅁䅁䅯䅎䅁䅁䅯允䅁䅁䅯兂䅁䅁䅅䅁䉁䅁䅁兂塄㍯㥁瑃呦睐杷允䅁䅁䅑䅁䑁䅁䅷䅁䭁乁䄰䅁䭁䅁䅅䅁䭁䅁䄸䅁䉁䅁䅁允䅁䅁䅕㡧䭄啯㉗䕂䵁䅉䅅䅁䕁䅁䅁睁䵁䅁䅁权㡁䅁䅁权䉁䅁䅁权呁䅁䅁允䅁䅁䅅䅁䙁䵁ㅐ䙋偹畷⼰䍄䉁䅁䅁䅂䅁䅁䅍䅄䅁䅁䅯兪䅁䅁䅯允䅁䅁䅯兌䅁䅁䅅䅁䉁䅁䅁兂捃䍸睃浣婪睐杷允䅁䅁䅑䅁䑁䅁䅷䅁䭁䵁䅑䅁䭁䅁䅅䅁䭁䍁䅁䅁䉁䅁䅁允䅁䅁䅕潅䅐煹䙆橸䴸䅉䅅䅁䕁䅁䅁睁䵁䅁䅁权十䅁䅁权䉁䅁䅁权偁䅁䅁允䅁䅁䅅䅁䙁䭁䠵場啯瑲⽣䍄䉁䅁䅁䅂䅁䅁䅍䅄䅁䅁䅯杈䅁䅁䅯睘䅅䅁䅯杉䅁䅁䅅䅁䉁䅁䅁䅆杂㔴䅍䅁䅁䅁杷允䅁䅁䅑䅁䑁䅁䅷䅁䭁䅁䉙䅁䭁䅁䅅䅁䭁䅁䄰䅁䉁䅁䅁允䅁䅁䅕硥畓⭒㙆䐸䴸䅉䅅䅁䕁䅁䅁睁䵁䅁䅁权十允䅁权䉁䅁䅁权湁䅁䅁允䅁䅁䅅䅁䙁䭁硲欰椱偅⽉䍄䉁䅁䅁䅂䅁䅁䅍䅄䅁䅁䅯兕䅁䅁䅯允䅁䅁䅯权䅁䅁䅅䅁䉁䅁䅁兂乄䵺䵺䵺䭷䅑杷允䅁䅁䅑䅁䑁䅁䅷䅁䭁䍁䈰䅁䭁䅁䅅䅁䭁䍁䅧䅁䉁䅁䅁允䅁䅁䅕牕敧敨剴䑹䴸䅉䅅䅁䕁䅁䅁睁䵁䅁䅁权䥁䅁䅁权䩁䅁䅁权剁䅁䅁允䅁䅁䅅䅁啁䍁塧晨⼯⼯⼯䍄䉁䅁䅁䅂䅁䅁䅍䅄䅁䅁䅯䅔䅁䅁䅯允䅁䅁䅯睇䅁䅁䅅䅁䉁䅁䅁兂塄㍯㥁瑃⽦睐杷允䅁䅁䅑䅁䑁䅁䅷䅁䭁偁䅫䅁䭁䅁䅅䅁䭁䅁䅣䅁䉁䅁䅁允䅁䅁䅕瑃橥䑣䬰稱䴸䅉䅅䅁䕁䅁䅁睁䵁䅁䅁权䵂䅁䅁权䉁䅁䅁权橁䅁䅁允䅁䅁䅅䅁䙁乁橥䑣䬰⬱⽍䍄䉁䅁䅁䅂䅁䅁䅍䅄䅁䅁䅯杘䅅䅁䅯允䅁䅁䅯睄䅁䅁䅅䅁䉁䅁䅁兂䅁䅁䅁䅁㑄睐杷允䅁䅁䅑䅁䑁䅁䅷䅁䭁䍁䄸䅁䭁䅁䅅䅁䭁䉁䅷䅁䉁䅁䅁允䅁䅁䅕卸睃浣剩吳䴸䅉䅅䅁䕁䅁䅁睁䵁䅁䅁权剄䅁䅁权䉁䅁䅁权䡁䅁䅁允䅁䅁䅅䅁䙁䉁畓⭒㙆但⽙䍄䉁䅁䅁䅂䅁䅁䅍䅄䅁䅁䅯免䅁䅁䅯允䅁䅁䅯杍䅁䅁䅅䅁䉁䅁䅁兂㑃潈牘払敪睐杷允䅁䅁䅑䅁䑁䅁䅷䅁䭁䑁䅫䅁䭁䅁䅅䅁䭁䉁䅕䅁䉁䅁䅁允䅁䅁䅕䉵䘶ㄶ㑇樷䴸䅉䅅䅁䕁䅁䅁睁䵁䅁䅁权捂允䅁权䉁䅁䅁权摂䅁䅁允䅁䅁䅅䅁䙁偁潙䥘䌯儹䅂䍄䉁䅁䅁䅂䅁䅁䅍䅄䅁䅁䅯杹䅁䅁䅯允䅁䅁䅯睄䅁䅁䅅䅁䉁䅁䅁兂歃䑣䬰㘱䥍䅑杷允䅁䅁䅑䅁䑁䅁䅷䅁䭁䑁䅯䅁䭁䅁䅅䅁䭁䅁䅉䅁䉁䅁䅁允䅁䅁䅕牕敧敨剴䕃䵁䅉䅅䅁䕁䅁䅁睁䵁䅁䅁权晄䅁䅁权䉁䅁䅁权潁䅁䅁允䅁䅁䅅䅁䙁䵁䴳䵺䵺佺⽑䍄䉁䅁䅁䅂䅁䅁䅍䅄䅁䅁䅯杌䅅䅁䅯允䅁䅁䅯睏䅁䅁䅅䅁䉁䅁䅁兂㝂䭆䠵場睲睐杷允䅁䅁䅑䅁䑁䅁䅷䅁䭁䙁䉧䅁䭁䅁䅅䅁䭁䉁䅷䅁䉁䅁䅁允䅁䅁䅕畮渫歸㍳稹䴸䅉䅅䅁䕁䅁䅁睁䵁䅁䅁权灂䅁䅁权䉁䅁䅁权䭁䅁䅁允䅁䅁䅅䅁䙁佁剸䉵䘶⬶⽫䍄䉁䅁䅁䅂䅁䅁䅍䅄䅁䅁䅯免䅁䅁䅯允䅁䅁䅯兄䅁䅁䅅䅁䉁䅁䅁兂㑃潈牘払浪睐杷允䅁䅁䅑䅁䑁䅁䅷䅁䭁䵁䅙䅁䭁䅁䅅䅁䭁䍁䅧䅁䉁䅁䅁允䅁䅁䅕䉵䘶ㄶ㑇樸䴸䅉䅅䅁䕁䅁䅁睁䵁䅁䅁权䅄䅁䅁权䉁䅁䅁权潁䅁䅁允䅁䅁䅅䅁啁䅁䅅䅁䅁䅁䅁䍄䉁䅁䅁䅂䅁䅁䅍䅄䅁䅁䅯眰䅁䅁䅯允䅁䅁䅯兆䅁䅁䅅䅁䉁䅁䅁兂䍂余兘瑉䕳䅑杷允䅁䅁䅑䅁䑁䅁䅷䅁䭁䅁䉙䅁䭁䅁䅅䅁䭁䍁䅣䅁䉁䅁䅁允䅁䅁䅕歲桦桥畓稯䴸䅉䅅䅁䕁䅁䅁睁䵁䅁䅁权䱁䅁䅁权䩁䅁䅁权杁䅁䅁允䅁䅁䅅䅁啁䅁捧偪⼯⼯⼯䍄䉁䅁䅁䅂䅁䅁䅍䅄䅁䅁䅯睮䅁䅁䅯允䅁䅁䅯睏䅁䅁䅅䅁䉁䅁䅁兂㡄晱午坔睊睐杷允䅁䅁䅑䅁䑁䅁䅷䅁䭁䉁䉣䅁䭁䅁䅅䅁䭁䅁䄰䅁䉁䅁䅁允䅁䅁䅕歲桦桥畓稵䴸䅉䅅䅁䕁䅁䅁睁䵁䅁䅁权卂䅁䅁权䉁䅁䅁权䅂䅁䅁允䅁䅁䅅䅁䙁䙁㑋潈牘晕⽁䍄䉁䅁䅁䅂䅁䅁䅍䅄䅁䅁䅯眵䅁䅁䅯允䅁䅁䅯兓䅁䅁䅅䅁䉁䅁䅁兂捂㡪ㅌ䙋空睐杷允䅁䅁䅑䅁䑁䅁䅷䅁䭁䉁䅯䅁䭁䅁䅅䅁䭁䉁䅅䅁䉁䅁䅁允䅁䅁䅕祇搯䅊䉡稸䴸䅉䅅䅁䕁䅁䅁睁䵁䅁䅁权癁䅁䅁权䉁䅁䅁权潁䅁䅁允䅁䅁䅅䅁䙁䥁獴⼵灵攸⼴䍄䉁䅁䅁䅂䅁䅁䅍䅄䅁䅁䅯眶䅁䅁䅯允䅁䅁䅯杉䅁䅁䅅䅁䉁䅁䅁兂䑄匹捨㡪瑌睐杷允䅁䅁䅑䅁䑁䅁䅷䅁䭁䑁䅧䅁䭁䅁䅅䅁䭁䅁䅣䅁䉁䅁䅁允䅁䅁䅕㥏倹婪畤爵䴸䅉䅅䅁䕁䅁䅁睁䵁䅁䅁权晃䅁䅁权䉁䅁䅁权㍁䅁䅁允䅁䅁䅅䅁䙁䙁㘶兓䍷㥋⼸䍄䉁䅁䅁䅂䅁䅁䅍䅄䅁䅁䅯朱䅁䅁䅯允䅁䅁䅯睉䅁䅁䅅䅁䉁䅁䅁兂䑄匹捨㡪䉉䅑杷允䅁䅁䅑䅁䑁䅁䅷䅁䭁䙁䅕䅁䭁䅁䅅䅁䭁䑁䅉䅁䉁䅁䅁允䅁䅁䅕㝤昶楇搯䐵䴸䅉䅅䅁䕁䅁䅁睁䵁䅁䅁权慁䅁䅁权䉁䅁䅁权婁䅁䅁允䅁䅁䅅䅁䙁䡁呗䅇坒癄⽅䍄䉁䅁䅁䅂䅁䅁䅍䅄䅁䅁䅯䅌䅁䅁䅯允䅁䅁䅯权䅁䅁䅅䅁䉁䅁䅁兂獄払敧敨硶睐杷允䅁䅁䅑䅁䑁䅁䅷䅁䭁䝁䅅䅁䭁䅁䅅䅁䭁䕁䅁䅁䉁䅁䅁允䅁䅁䅕場啯歲桦牵䴸䅉䅅䅁䕁䅁䅁睁䵁䅁䅁权牁䅁䅁权䉁䅁䅁权捁䅁䅁允䅁䅁䅅䅁䙁偁湃歸㍳晩⼰䍄䉁䅁䅁䅂䅁䅁䅍䅄䅁䅁䅯睪䅁䅁䅯允䅁䅁䅯睊䅁䅁䅅䅁䉁䅁䅁兂䭁㘱睎児湲睐杷允䅁䅁䅑䅁䑁䅁䅷䅁䭁䑁䅯䅁䭁䅁䅅䅁䭁䉁䅍䅁䉁䅁䅁允䅁䅁䅕捺䵺䵺䵺䐯䴸䅉䅅䅁䕁䅁䅁睁䵁䅁䅁权䙂䅁䅁权䉁䅁䅁权䡁䅁䅁允䅁䅁䅅䅁䙁䥁䌯匹捨⭪⽉䍄䉁䅁䅁䅂䅁䅁䅍䅄䅁䅁䅯䅅䅁䅁䅯允䅁䅁䅯杁䅁䅁䅅䅁䉁䅁䅁兂獄払敧敨硶睐杷允䅁䅁䅑䅁䑁䅁䅷䅁䭁䑁䅑䅁䭁䅁䅅䅁䭁䍁䅧䅁䉁䅁䅁允䅁䅁䅕免獩䙈歰歁䵁䅉䅅䅁䕁䅁䅁睁䵁䅁䅁权㕁䅁䅁权䉁䅁䅁权捁䅁䅁允䅁䅁䅅䅁䙁䝁浚浚浚畚⼴䍄䉁䅁䅁䅂䅁䅁䅍䅄䅁䅁䅯睘䅁䅁䅯允䅁䅁䅯䅑䅁䅁䅅䅁䉁䅁䅁兂橁⼲⭬牡杺睶杷允䅁䅁䅑䅁䑁䅁䅷䅁䭁䉁䉙䅁䭁䅁䅅䅁䭁䉁䅫䅁䉁䅁䅁允䅁䅁䅕䑚晶㑔堲樫䴸䅉䅅䅁䕁䅁䅁睁䵁䅁䅁权瑂䅁䅁权䉁䅁䅁权祁䅁䅁允䅁䅁䅅䅁䙁䝁光䑗ね䵹⽙䍄䉁䅁䅁䅂䅁䅁䅍䅄䅁䅁䅯李䅅䅁䅯允䅁䅁䅯䅉䅁䅁䅅䅁䉁䅁䅁兂䵂㑎䉬余杗睐杷允䅁䅁䅑䅁䑁䅁䅷䅁䭁䑁䅯䅁䭁䅁䅅䅁䭁䑁䅳䅁䉁䅁䅁允䅁䅁䅕灶愸㥌欰歁䵁䅉䅅䅁䕁䅁䅁睁䵁䅁䅁权㍁允䅁权䉁䅁䅁权㝁䅁䅁允䅁䅁䅅䅁䙁䙁㘶兓䍷睋䅎䍄䉁䅁䅁䅂䅁䅁䅍䅄䅁䅁䅯睈䅁䅁䅯允䅁䅁䅯兌䅁䅁䅅䅁䉁䅁䅁兂乃㉬匴㡧睄睐杷允䅁䅁䅑䅁䑁䅁䅷䅁䭁䙁䅧䅁䭁䅁䅅䅁䭁䉁䅅䅁䉁䅁䅁允䅁䅁䅕䅁䅁䅁䅃䕉䵁䅉䅅䅁䕁䅁䅁睁䵁䅁䅁权䍄䅁䅁权䉁䅁䅁权祁䅁䅁允䅁䅁䅅䅁䭁䅁䅍䅁䵁䅉䅅䅁䕁䅁䅁睁䵁䅁䅁权畄䅁䅁权䉁䅁䅁权乁䅁䅁允䅁䅁䅅䅁䙁偁潙䥘䌯昹⽁䍄䉁䅁䅁䅂䅁䅁䅍䅄䅁䅁䅯材䅁䅁䅯允䅁䅁䅯兆䅁䅁䅅䅁䉁䅁䅁兂⽂牡へ硫杪睐杷允䅁䅁䅑䅁䑁䅁䅷䅁䭁䝁䅣䅁䭁䅁䅅䅁䭁䍁䅁䅁䉁䅁䅁允䅁䅁䅕䭆䠵場啯樯䴸䅉䅅䅁䕁䅁䅁睁䵁䅁䅁权䉃䅁䅁权䉁䅁䅁权祁䅁䅁允䅁䅁䅅䅁䙁䕁㉡⼸唳䵥⽫䍄䉁䅁䅁䅂䅁䅁䅍䅄䅁䅁䅯朸䅁䅁䅯允䅁䅁䅯兄䅁䅁䅅䅁䉁䅁䅁兂啁歲桦桥䍑䅑杷允䅁䅁䅑䅁䑁䅁䅷䅁䭁䩁䅉䅁䭁䅁䅅䅁䭁䉁䅕䅁䉁䅁䅁允䅁䅁䅕䉵䘶ㄶ㑇樳䴸䅉䅅䅁䕁䅁䅁睁䵁䅁䅁权煁䅁䅁权䉁䅁䅁权偁䅁䅁允䅁䅁䅅䅁䙁䵁ㅐ䙋偹癷⽕䍄䉁䅁䅁䅂䅁䅁䅍䅄䅁䅁䅯䅡䅁䅁䅯允䅁䅁䅯睄䅁䅁䅅䅁䉁䅁䅁兂灄橊䥅䉲䉷䅑杷允䅁䅁䅑䅁䑁䅁䅷䅁䭁䡁䅉䅁䭁䅁䅅䅁䭁䍁䅣䅁䉁䅁䅁允䅁䅁䅕⽺呤㘴払啇䵁䅉䅅䅁䕁䅁䅁睁䵁䅁䅁权穁允䅁权䉁䅁䅁权㝁䅁䅁允䅁䅁䅅䅁䙁偁潙䥘䌯昹⽷䍄䉁䅁䅁䅂䅁䅁䅍䅄䅁䅁䅯䅐䅁䅁䅯允䅁䅁䅯睄䅁䅁䅅䅁䉁䅁䅁兂穁積積積偍䅑杷允䅁䅁䅑䅁䑁䅁䅷䅁䭁偁䅁䅁䭁䅁䅅䅁䭁䑁䅉䅁䉁䅁䅁允䅁䅁䅕渷⽷噎㘶吷䴸䅉䅅䅁䕁䅁䅁睁䵁䅁䅁权十允䅁权䉁䅁䅁权潁䅁䅁允䅁䅁䅅䅁䙁䭁睒児塲⽯⽑䍄䉁䅁䅁䅂䅁䅁䅍䅄䅁䅁䅯睉䅅䅁䅯允䅁䅁䅯睏䅁䅁䅅䅁䉁䅁䅁兂灁䥘䌯匹䵪睐杷允䅁䅁䅑䅁䑁䅁䅷䅁䭁䑁䄰䅁䭁䅁䅅䅁䭁䍁䅍䅁䉁䅁䅁允䅁䅁䅕䅁䅁䅁䅁䐲䴸䅉䅅䅁䕁䅁䅁睁䵁䅁䅁权い䅁䅁权䉁䅁䅁权摂䅁䅁允䅁䅁䅅䅁䙁䱁䥔牤昶桇䅸䍄䉁䅁䅁䅂䅁䅁䅍䅄䅁䅁䅯杙䅁䅁䅯允䅁䅁䅯睉䅁䅁䅅䅁䉁䅁䅁兂䵂㑎䉬余䅘睐杷允䅁䅁䅑䅁䑁䅁䅷䅁䭁䥁䅍䅁䭁䅁䅅䅁䭁䙁䄰䅁䉁䅁䅁允䅁䅁䅕㑋坣挲㌷䕄䵁䅉䅅䅁䕁䅁䅁睁䵁䅁䅁权⽄䅁䅁权䉁䅁䅁权䩂䅁䅁允䅁䅁䅅䅁啁䅁䅑䅁䅁䅁䅁䍄䉁䅁䅁䅂䅁䅁䅍䅄䅁䅁䅯李䅅䅁䅯允䅁䅁䅯睏䅁䅁䅅䅁䉁䅁䅁兂穁積積積⽐睐杷允䅁䅁䅑䅁䑁䅁䅷䅁䭁䑁䄸䅁䭁䅁䅅䅁䭁䕁䅁䅁䉁䅁䅁允䅁䅁䅕敨剴䉵䘶稴䴸䅉䅅䅁䕁䅁䅁睁䵁䅁䅁权䑁允䅁权䉁䅁䅁权䭁䅁䅁允䅁䅁䅅䅁䙁䕁桪桥畓睒䄹䍄䉁䅁䅁䅂䅁䅁䅍䅄䅁䅁䅯杕䅁䅁䅯允䅁䅁䅯睎䅁䅁䅅䅁䉁䅁䅁兂䥂場啯歲䉣䅑杷允䅁䅁䅑䅁䑁䅁䅷䅁䭁䙁䄸䅁䭁䅁䅅䅁䭁䅁䄸䅁䉁䅁䅁允䅁䅁䅕報灪橊䥅䐸䴸䅉䅅䅁䕁䅁䅁睁䵁䅁䅁权䝂䅁䅁权䉁䅁䅁权扁䅁䅁允䅁䅁䅅䅁䙁䅁琴灳瘳⭰⼴䍄䉁䅁䅁䅂䅁䅁䅍䅄䅁䅁䅯兓䅅䅁䅯允䅁䅁䅯睏䅁䅁䅅䅁䉁䅁䅁兂捂㡪ㅌ䩋噸䅑杷允䅁䅁䅑䅁䑁䅁䅷䅁䭁䕁䅅䅁䭁䅁䅅䅁䭁䑁䅉䅁䉁䅁䅁允䅁䅁䅕余兘瑉㕶樴䴸䅉䅅䅁䕁䅁䅁睁䵁䅁䅁权㡂䅁䅁权䉁䅁䅁权呁䅁䅁允䅁䅁䅅䅁䙁䱁敧敨剴偵⼴䍄䉁䅁䅁䅂䅁䅁䅍䅄䅁䅁䅯䅗䅁䅁䅯允䅁䅁䅯䅉䅁䅁䅅䅁䉁䅁䅁兂奂扏䥔牤攴䅑杷允䅁䅁䅑䅁䑁䅁䅷䅁䭁䩁䄰䅁䭁䅁䅅䅁䭁䑁䅉䅁䉁䅁䅁允䅁䅁䅕積積積積稶䴸䅉䅅䅁䕁䅁䅁睁䵁䅁䅁权硃䅁䅁权䉁䅁䅁权呁䅁䅁允䅁䅁䅅䅁䙁䱁敧敨剴䭵⼴䍄䉁䅁䅁䅂䅁䅁䅍䅄䅁䅁䅯儯䅁䅁䅯允䅁䅁䅯睉䅁䅁䅅䅁䉁䅁䅁兂㡃䩤奍䙂煢睐杷允䅁䅁䅑䅁䑁䅁䅷䅁䭁䑁䉫䅁䭁䅁䅅䅁䭁䍁䅣䅁䉁䅁䅁允䅁䅁䅕㑈牘払敧吱䴸䅉䅅䅁䕁䅁䅁睁䵁䅁䅁权婂䅁䅁权䉁䅁䅁权䭁䅁䅁允䅁䅁䅅䅁䙁䥁獴⼵灵愸⽉䍄䉁䅁䅁䅂䅁䅁䅍䅄䅁䅁䅯睈䅅䅁䅯允䅁䅁䅯杁䅁䅁䅅䅁䉁䅁䅁权䑁䅁䅁䍄䉁䅁䅁䅂䅁䅁䅍䅄䅁䅁䅯內䅁䅁䅯允䅁䅁䅯权䅁䅁䅅䅁䉁䅁䅁兂歃䑣䬰㘱児睐杷允䅁䅁䅑䅁䑁䅁䅷䅁䭁䵁䄰䅁䭁䅁䅅䅁䭁䙁䄰䅁䉁䅁䅁允䅁䅁䅕浚浚浚浚樵䴸䅉䅅䅁䕁䅁䅁睁䵁䅁䅁权牁䅁䅁权䉁䅁䅁权䙁䅁䅁允䅁䅁䅅䅁䙁䅁坒楄礲剮䅈䍄䉁䅁䅁䅂䅁䅁䅍䅄䅁䅁䅯村䅁䅁䅯允䅁䅁䅯睄䅁䅁䅅䅁䉁䅁䅁兂啁歲桦桥畔睐杷允䅁䅁䅑䅁䑁䅁䅷䅁䭁䝁䅳䅁䭁䅁䅅䅁䭁䉁䅅䅁䉁䅁䅁允䅁䅁䅕⽷潕䥘䌯吹䴸䅉䅅䅁䕁䅁䅁睁䵁䅁䅁权乃䅁䅁权䉁䅁䅁权䍁䅁䅁允䅁䅁䅅䅁䭁䅁䅍䅁䵁䅉䅅䅁䕁䅁䅁睁䵁䅁䅁权塃䅁䅁权䉁䅁䅁权瑁䅁䅁允䅁䅁䅅䅁䙁佁㙆䭆䠵昴⽙䍄䉁䅁䅁䅂䅁䅁䅍䅄䅁䅁䅯䅃䅁䅁䅯元䅁䅁䅯睊䅁䅁䅅䅁䉁䅁䅁䅆䥁嘳⽦⼯⼯眯杷允䅁䅁䅑䅁䑁䅁䅷䅁䭁䵁䄴䅁䭁䅁䅅䅁䭁䑁䅣䅁䉁䅁䅁允䅁䅁䅕捺䵺䵺䵺䐫䴸䅉䅅䅁䕁䅁䅁睁䵁䅁䅁权卂䅁䅁权䉁䅁䅁权偁䅁䅁允䅁䅁䅅䅁䙁䅁䅁䅁䅁偁⽑䍄䉁䅁䅁䅂䅁䅁䅍䅄䅁䅁䅯杁䅅䅁䅯允䅁䅁䅯睇䅁䅁䅅䅁䉁䅁䅁兂㝂䭆䠵場䕲睐杷允䅁䅁䅑䅁䑁䅁䅷䅁䭁䑁䅑䅁䭁䅁䅅䅁䭁䍁䅁䅁䉁䅁䅁允䅁䅁䅕䑔䩥坑求啅䵁䅉䅅䅁䕁䅁䅁睁䵁䅁䅁权⽂䅁䅁权䉁䅁䅁权偁䅁䅁允䅁䅁䅅䅁䙁䍁捬㡪ㅌ偋⽁䍄䉁䅁䅁䅂䅁䅁䅍䅄䅁䅁䅯光䅁䅁䅯允䅁䅁䅯兂䅁䅁䅅䅁䉁䅁䅁兂畃⭒㙆䭆㜷睐杷允䅁䅁䅑䅁䑁䅁䅷䅁䭁䙁䅫䅁䭁䅁䅅䅁䭁䅁䄰䅁䉁䅁䅁允䅁䅁䅕婪畤潅䅐樶䴸䅉䅅䅁䕁䅁䅁睁䵁䅁䅁权呃䅁䅁权䉁䅁䅁权偁䅁䅁允䅁䅁䅅䅁䙁䕁桪桥畓硒䅆䍄䉁䅁䅁䅂䅁䅁䅍䅄䅁䅁䅯睃䅁䅁䅯元䅁䅁䅯睊䅁䅁䅅䅁䉁䅁䅁䅆䥁嘳⽦⼯⼯眯杷允䅁䅁䅑䅁䑁䅁䅷䅁䭁䥁䅫䅁䭁䅁䅅䅁䭁䍁䅁䅁䉁䅁䅁允䅁䅁䅕噋偹癷潕䕁䵁䅉䅅䅁䕁䅁䅁睁䵁䅁䅁权偃䅁䅁权䉁䅁䅁权捁䅁䅁允䅁䅁䅅䅁䙁䡁潎敫㠱⭐⽫䍄䉁䅁䅁䅂䅁䅁䅍䅄䅁䅁䅯杩䅁䅁䅯允䅁䅁䅯杁䅁䅁䅅䅁䉁䅁䅁兂卂䉵䘶ㄶ潈睐杷允䅁䅁䅑䅁䑁䅁䅷䅁䭁䙁䅁䅁䭁䅁䅫䅁䭁䅁䅣䅁䉁䅁䅁允䅁䉁䅑䙗㑓⼯⼯⼯䴸䅉䅅䅁䕁䅁䅁睁䵁䅁䅁权剁允䅁权䉁䅁䅁权䩂䅁䅁允䅁䅁䅅䅁䙁乁橥䑣䬰眱䅬䍄䉁䅁䅁䅂䅁䅁䅍䅄䅁䅁䅯先䅅䅁䅯允䅁䅁䅯杉䅁䅁䅅䅁䉁䅁䅁兂㥁瑃橥䑣焳睐杷允䅁䅁䅑䅁䑁䅁䅷䅁䭁䍁䉫䅁䭁䅁䅅䅁䭁䍁䅍䅁䉁䅁䅁允䅁䅁䅕瑃橥䑣䬰ぅ䵁䅉䅅䅁䕁䅁䅁睁䵁䅁䅁权ぁ允䅁权䉁䅁䅁权湁䅁䅁允䅁䅁䅅䅁䙁䭁硲欰椱佅⽁䍄䉁䅁䅁䅂䅁䅁䅍䅄䅁䅁䅯睫䅁䅁䅯允䅁䅁䅯兄䅁䅁䅅䅁䉁䅁䅁兂扄堫焵䡶湔睶杷允䅁䅁䅑䅁䑁䅁䅷䅁䭁䭁䅍䅁䭁䅁䅅䅁䭁䉁䅅䅁䉁䅁䅁允䅁䅁䅕⽷潕䥘䌯吵䴸䅉䅅䅁䕁䅁䅁睁䵁䅁䅁权⽄䅁䅁权䉁䅁䅁权剁䅁䅁允䅁䅁䅅䅁䙁偁⭰牡へ硅䅂䍄䉁䅁䅁䅂䅁䅁䅍䅄䅁䅁䅯䅪䅁䅁䅯允䅁䅁䅯兘䅁䅁䅅䅁䉁䅁䅁兂㑃潈牘払佪睐杷允䅁䅁䅑䅁䑁䅁䅷䅁䭁偁䅳䅁䭁䅁䅅䅁䭁䑁䅳䅁䉁䅁䅁允䅁䅁䅕塹⭡确癯呺䴸䅉䅅䅁䕁䅁䅁睁䵁䅁䅁权䵁允䅁权䉁䅁䅁权乁䅁䅁允䅁䅁䅅䅁䙁䩁䑚㉩湺⼫⽵䍄䉁䅁䅁䅂䅁䅁䅍䅄䅁䅁䅯䅃䅁䅁䅯元䅁䅁䅯兓䅁䅁䅅䅁䉁䅁䅁䅆奃慃⽄⼯⼯眯杷允䅁䅁䅑䅁䑁䅁䅷䅁䭁䝁䄸䅁䭁䅁䅅䅁䭁䕁䅫䅁䉁䅁䅁允䅁䅁䅕噋偹癷潕䑶䴸䅉䅅䅁䕁䅁䅁睁䵁䅁䅁权⽂䅁䅁权䉁䅁䅁权摂䅁䅁允䅁䅁䅅䅁䙁䝁浚浚浚癚⽉䍄䉁䅁䅁䅂䅁䅁䅍䅄䅁䅁䅯朶䅁䅁䅯允䅁䅁䅯䅑䅁䅁䅅䅁䉁䅁䅁兂灁䥘䌯匹歪睐杷允䅁䅁䅑䅁䑁䅁䅷䅁䭁䩁䅙䅁䭁䅁䅅䅁䭁䍁䅍䅁䉁䅁䅁允䅁䅁䅕䘷㑇潈牘呷䴸䅉䅅䅁䕁䅁䅁睁䵁䅁䅁权偂允䅁权䉁䅁䅁权杁䅁䅁允䅁䅁䅅䅁䙁䱁昶楇搯䅊䅖䍄䉁䅁䅁䅂䅁䅁䅍䅄䅁䅁䅯杨䅁䅁䅯允䅁䅁䅯充䅁䅁䅅䅁䉁䅁䅁兂䙃ㄶ㑇潈橘睐杷允䅁䅁䅑䅁䑁䅁䅷䅁䭁䭁䅷䅁䭁䅁䅅䅁䭁䅁䄸䅁䉁䅁䅁允䅁䅁䅕硢䑋䵷桱䕂䵁䅉䅅䅁䕁䅁䅁睁䵁䅁䅁权䱁䅁䅁权䩁䅁䅁权䩂䅁䅁允䅁䅁䅅䅁啁䩁䩧偯⼯⼯⼯䍄䉁䅁䅁䅂䅁䅁䅍䅄䅁䅁䅯杴䅁䅁䅯允䅁䅁䅯䅉䅁䅁䅅䅁䉁䅁䅁兂啁歲桦桥⭔睐杷允䅁䅁䅑䅁䑁䅁䅷䅁䭁䕁䅯䅁䭁䅁䅅䅁䭁䉁䅕䅁䉁䅁䅁允䅁䅁䅕䙂余扌摋㜱䴸䅉䅅䅁䕁䅁䅁睁䵁䅁䅁权汁允䅁权䉁䅁䅁权橁䅁䅁允䅁䅁䅅䅁䙁䵁ㅐ䙋偹杷䅤䍄䉁䅁䅁䅂䅁䅁䅍䅄䅁䅁䅯杲䅁䅁䅯允䅁䅁䅯睄䅁䅁䅅䅁䉁䅁䅁兂偃癷潕䥘䔸䅑杷允䅁䅁䅑䅁䑁䅁䅷䅁䭁䙁䅳䅁䭁䅁䅅䅁䭁䍁䅣䅁䉁䅁䅁允䅁䅁䅕灰䕶䱉祂䵊䵁䅉䅅䅁䕁䅁䅁睁䵁䅁䅁权㝂䅁䅁权䉁䅁䅁权䭁䅁䅁允䅁䅁䅅䅁䙁䡁啳歲桦癥⽷䍄䉁䅁䅁䅂䅁䅁䅍䅄䅁䅁䅯睓䅅䅁䅯允䅁䅁䅯兆䅁䅁䅅䅁䉁䅁䅁兂䅁䅁䅁䅁兄睐杷允䅁䅁䅑䅁䑁䅁䅷䅁䭁䕁䅳䅁䭁䅁䅅䅁䭁䉁䅅䅁䉁䅁䅁允䅁䅁䅕瑃橥䑣䬰稫䴸䅉䅅䅁䕁䅁䅁睁䵁䅁䅁权䵄䅁䅁权䉁䅁䅁权䍁䅁䅁允䅁䅁䅅䅁䭁䅁䅍䅁䵁䅉䅅䅁䕁䅁䅁睁䵁䅁䅁权奁允䅁权䉁䅁䅁权䭁䅁䅁允䅁䅁䅅䅁䙁䝁㡱䩤奍佂⼴䍄䉁䅁䅁䅂䅁䅁䅍䅄䅁䅁䅯睫䅁䅁䅯允䅁䅁䅯兆䅁䅁䅅䅁䉁䅁䅁兂婄発呤㘴䕕䅑杷允䅁䅁䅑䅁䑁䅁䅷䅁䭁䅁䅧䅁䭁䅁䅫䅁䭁䅁䄸䅁䉁䅁䅁允䅁䉁䅑佷块⼯⼯⼯䴸䅉䅅䅁䕁䅁䅁睁䵁䅁䅁权䍂䅁䅁权䉁䅁䅁权䭁䅁䅁允䅁䅁䅅䅁䙁䑁䥅䉲慸佚⽳䍄䉁䅁䅁䅂䅁䅁䅍䅄䅁䅁䅯杦䅁䅁䅯允䅁䅁䅯睄䅁䅁䅅䅁䉁䅁䅁兂䭁㘱睎児䱯䅑杷允䅁䅁䅑䅁䑁䅁䅷䅁䭁䥁䅫䅁䭁䅁䅅䅁䭁䙁䄰䅁䉁䅁䅁允䅁䅁䅕場啯歲桦樹䴸䅉䅅䅁䕁䅁䅁睁䵁䅁䅁权祃䅁䅁权䉁䅁䅁权乁䅁䅁允䅁䅁䅅䅁䙁䭁慁㥌欰瑂⽫䍄䉁䅁䅁䅂䅁䅁䅍䅄䅁䅁䅯䅋䅅䅁䅯允䅁䅁䅯睂䅁䅁䅅䅁䉁䅁䅁兂晁敨剴䉵ㄷ睐杷允䅁䅁䅑䅁䑁䅁䅷䅁䭁䅁䅷䅁䭁䅁䅅䅁䭁䍁䅍䅁䉁䅁䅁允䅁䅁䅕椹捨㡪ㅌ䐸䴸䅉䅅䅁䕁䅁䅁睁䵁䅁䅁权奃䅁䅁权䉁䅁䅁权䩂䅁䅁允䅁䅁䅅䅁䙁䑁䬰㘱睎晐⼴䍄䉁䅁䅁䅂䅁䅁䅍䅄䅁䅁䅯兌䅅䅁䅯允䅁䅁䅯䅈䅁䅁䅅䅁䉁䅁䅁兂煂䡶呓䅇㉓睶杷允䅁䅁䅑䅁䑁䅁䅷䅁䭁䅁䅳䅁䭁䅁䅫䅁䭁䅁䄸䅁䉁䅁䅁允䅁䉁䅑佷块⼯⼯⼯䴸䅉䅅䅁䕁䅁䅁睁䵁䅁䅁权䡄䅁䅁权䩁䅁䅁权剁䅁䅁允䅁䅁䅅䅁啁䱁瑩偡⼯⼯⼯䍄䉁䅁䅁䅂䅁䅁䅍䅄䅁䅁䅯䅄䅁䅁䅯允䅁䅁䅯兂䅁䅁䅅䅁䉁䅁䅁兂㉄䙋偹癷杘睐杷允䅁䅁䅑䅁䑁䅁䅷䅁䭁䙁䅁䅁䭁䙁䈸䅁䭁䉁䅷䅁䉁䅁䅁允䅁䉁䅑䙇兦允䅁䅁䵁䅉䅅䅁䕁䅁䅁睁䵁䅁䅁权睄䅁䅁权䉁䅁䅁权杁䅁䅁允䅁䅁䅅䅁䙁䩁䑚㉩湺⼫⽍䍄䉁䅁䅁䅂䅁䅁䅍䅄䅁䅁䅯睋䅁䅁䅯允䅁䅁䅯睅䅁䅁䅅䅁䉁䅁䅁兂摁浗㝑〳氯睐杷允䅁䅁䅑䅁䑁䅁䅷䅁䭁䥁䅧䅁䭁䅁䅅䅁䭁䑁䅉䅁䉁䅁䅁允䅁䅁䅕⽷潕䥘䌯呸䴸䅉䅅䅁䕁䅁䅁睁䵁䅁䅁权桁允䅁权䉁䅁䅁权橁䅁䅁允䅁䅁䅅䅁䙁䱁敧敨剴䅵䅊䍄䉁䅁䅁䅂䅁䅁䅍䅄䅁䅁䅯先䅁䅁䅯允䅁䅁䅯䅈䅁䅁䅅䅁䉁䅁䅁兂灁䥘䌯匹䍧䅑杷允䅁䅁䅑䅁䑁䅁䅷䅁䭁䍁䅳䅁䭁䅁䅅䅁䭁䕁䅁䅁䉁䅁䅁允䅁䅁䅕⽷潕䥘䌯吸䴸䅉䅅䅁䕁䅁䅁睁䵁䅁䅁权慄䅁䅁权䉁䅁䅁权婁䅁䅁允䅁䅁䅅䅁䙁䥁噇㑑獴眵䅆䍄䉁䅁䅁䅂䅁䅁䅍䅄䅁䅁䅯朳䅁䅁䅯允䅁䅁䅯兌䅁䅁䅅䅁䉁䅁䅁兂汄䌰扌堫䌴䅷杷允䅁䅁䅑䅁䑁䅁䅷䅁䭁䑁䅯䅁䭁䅁䅅䅁䭁䍁䄰䅁䉁䅁䅁允䅁䅁䅕䡳潊敫㠱啁䵁䅉䅅䅁䕁䅁䅁睁䵁䅁䅁权㡃䅁䅁权䉁䅁䅁权䅂䅁䅁允䅁䅁䅅䅁䙁䥁䌯匹捨㥪⽋䍄䉁䅁䅁䅂䅁䅁䅍䅄䅁䅁䅯䅔䅁䅁䅯允䅁䅁䅯杁䅁䅁䅅䅁䉁䅁䅁权䑁䅁䅁䍄䉁䅁䅁䅂䅁䅁䅍䅄䅁䅁䅯眴䅁䅁䅯允䅁䅁䅯充䅁䅁䅅䅁䉁䅁䅁兂允䑗ね䡹浢睐杷允䅁䅁䅑䅁䑁䅁䅷䅁䭁䙁䅍䅁䭁䅁䅅䅁䭁䅁䅣䅁䉁䅁䅁允䅁䅁䅕扉祂䩡瑈捂䵁䅉䅅䅁䕁䅁䅁睁䵁䅁䅁权⽁允䅁权䉁䅁䅁权摂䅁䅁允䅁䅁䅅䅁䙁䭁䙊癴㥐倱⽁䍄䉁䅁䅁䅂䅁䅁䅍䅄䅁䅁䅯先䅁䅁䅯允䅁䅁䅯充䅁䅁䅅䅁䉁䅁䅁兂塄㍯㥁瑃䉣䅑杷允䅁䅁䅑䅁䑁䅁䅷䅁䭁䥁䅕䅁䭁䅁䅅䅁䭁䉁䅫䅁䉁䅁䅁允䅁䅁䅕灰䕶䱉祂䐵䴸䅉䅅䅁䕁䅁䅁睁䵁䅁䅁权啂䅁䅁权䉁䅁䅁权䭁䅁䅁允䅁䅁䅅䅁䙁䩁婱婭婭卭䅤䍄䉁䅁䅁䅂䅁䅁䅍䅄䅁䅁䅯兔䅁䅁䅯允䅁䅁䅯杁䅁䅁䅅䅁䉁䅁䅁权䑁䅁䅁䍄䉁䅁䅁䅂䅁䅁䅍䅄䅁䅁䅯睵䅁䅁䅯允䅁䅁䅯兆䅁䅁䅅䅁䉁䅁䅁兂⭃确癯匳䝔睶杷允䅁䅁䅑䅁䑁䅁䅷䅁䭁偁䅫䅁䭁䅁䅅䅁䭁䉁䅅䅁䉁䅁䅁允䅁䅁䅕児塲㍯㥁樲䴸䅉䅅䅁䕁䅁䅁睁䵁䅁䅁权㕁䅁䅁权䉁䅁䅁权楁䅁䅁允䅁䅁䅅䅁䙁䭁睒児塲⽯⽑䍄䉁䅁䅁䅂䅁䅁䅍䅄䅁䅁䅯杏䅁䅁䅯允䅁䅁䅯兄䅁䅁䅅䅁䉁䅁䅁兂偃癷潕䥘匯睐杷允䅁䅁䅑䅁䑁䅁䅷䅁䭁䩁䅙䅁䭁䅁䅅䅁䭁䉁䅫䅁䉁䅁䅁允䅁䅁䅕㉩湺㘫确橯䴸䅉䅅䅁䕁䅁䅁睁䵁䅁䅁权䵁允䅁权䉁䅁䅁权婁䅁䅁允䅁䅁䅅䅁䙁䕁桪桥畓⽒⽍䍄䉁䅁䅁䅂䅁䅁䅍䅄䅁䅁䅯兄䅅䅁䅯允䅁䅁䅯杉䅁䅁䅅䅁䉁䅁䅁兂癁匳䝑婧䕕䅑杷允䅁䅁䅑䅁䑁䅁䅷䅁䭁䱁䅕䅁䭁䅁䅅䅁䭁䅁䅉䅁䉁䅁䅁允䅁䅁䅯睁䅁䅁杷允䅁䅁䅑䅁䑁䅁䅷䅁䭁䕁䄴䅁䭁䅁䅅䅁䭁䍁䅣䅁䉁䅁䅁允䅁䅁䅕敥浫免獧䵊䵁䅉䅅䅁䕁䅁䅁睁䵁䅁䅁权允䅁䅁权䉁䅁䅁权䙁䅁䅁允䅁䅁䅅䅁䙁䭁睒児塲⽯⽷䍄䉁䅁䅁䅂䅁䅁䅍䅄䅁䅁䅯杲䅁䅁䅯允䅁䅁䅯䅈䅁䅁䅅䅁䉁䅁䅁兂䭂䅄牉硨䝙䅑杷允䅁䅁䅑䅁䑁䅁䅷䅁䭁佁䅣䅁䭁䅁䅅䅁䭁䍁䅧䅁䉁䅁䅁允䅁䅁䅕匰扌堫焵䐷䴸䅉䅅䅁䕁䅁䅁睁䵁䅁䅁权獁䅁䅁权䉁䅁䅁权㝁䅁䅁允䅁䅁䅅䅁䙁䭁睒児塲⽯⽧䍄䉁䅁䅁䅂䅁䅁䅍䅄䅁䅁䅯睒䅁䅁䅯允䅁䅁䅯充䅁䅁䅅䅁䉁䅁䅁兂㉄䙋偹癷㙘睐杷允䅁䅁䅑䅁䑁䅁䅷䅁䭁䑁䉕䅁䭁䅁䅅䅁䭁䅁䅕䅁䉁䅁䅁允䅁䅁䅕䅁䅁䅁䅁ぅ䵁䅉䅅䅁䕁䅁䅁睁䵁䅁䅁权㉃䅁䅁权䉁䅁䅁权橁䅁䅁允䅁䅁䅅䅁䙁䩁婱婭婭晭⽕䍄䉁䅁䅁䅂䅁䅁䅍䅄䅁䅁䅯朵䅁䅁䅯允䅁䅁䅯䅈䅁䅁䅅䅁䉁䅁䅁兂摄䅊䉡啬㍐睐杷允䅁䅁䅑䅁䑁䅁䅷䅁䭁䡁䄸䅁䭁䅁䅅䅁䭁䍁䄰䅁䉁䅁䅁允䅁䅁䅕㑈牘払敧吸䴸䅉䅅䅁䕁䅁䅁睁䵁䅁䅁权㡁䅁䅁权䉁䅁䅁权乁䅁䅁允䅁䅁䅅䅁䙁䥁牘払敧晨⽳䍄䉁䅁䅁䅂䅁䅁䅍䅄䅁䅁䅯睥䅁䅁䅯允䅁䅁䅯䅋䅁䅁䅅䅁䉁䅁䅁兂瑂⼵灵搸汌睐杷允䅁䅁䅑䅁䑁䅁䅷䅁䭁䥁䅁䅁䭁䅁䅅䅁䭁䅁䄸䅁䉁䅁䅁允䅁䅁䅕硥畓⭒㙆䕂䵁䅉䅅䅁䕁䅁䅁睁䵁䅁䅁权⭁允䅁权䉁䅁䅁权潁䅁䅁允䅁䅁䅅䅁䙁䱁昶楇搯偊⽉䍄䉁䅁䅁䅂䅁䅁䅍䅄䅁䅁䅯睔䅁䅁䅯允䅁䅁䅯杁䅁䅁䅅䅁䉁䅁䅁兂䙃ㄶ㑇潈㝘睐杷允䅁䅁䅑䅁䑁䅁䅷䅁䭁䙁䅁䅁䭁䅁䅫䅁䭁䉁䅍䅁䉁䅁䅁允䅁䉁䅑䵣乺⼯⼯⼯䴸䅉䅅䅁䕁䅁䅁睁䵁䅁䅁权晁允䅁权䉁䅁䅁权偁䅁䅁允䅁䅁䅅䅁䙁䉁䘫ㄶ㑇癈⽫䍄䉁䅁䅁䅂䅁䅁䅍䅄䅁䅁䅯兡䅁䅁䅯允䅁䅁䅯䅑䅁䅁䅅䅁䉁䅁䅁兂潃歸㍳啩杈睐杷允䅁䅁䅑䅁䑁䅁䅷䅁䭁䝁䄰䅁䭁䅁䅅䅁䭁䑁䅳䅁䉁䅁䅁允䅁䅁䅕䘫橐婰䕶䑷䴸䅉䅅䅁䕁䅁䅁睁䵁䅁䅁权䭄䅁䅁权䉁䅁䅁权摂䅁䅁允䅁䅁䅅䅁啁䅁䅍䅁䅁䅁䅁䍄䉁䅁䅁䅂䅁䅁䅍䅄䅁䅁䅯杰䅁䅁䅯允䅁䅁䅯兓䅁䅁䅅䅁䉁䅁䅁兂晁敨剴䉵琷睐杷允䅁䅁䅑䅁䑁䅁䅷䅁䭁䅁䅧䅁䭁䅁䅫䅁䭁䍁䅁䅁䉁䅁䅁允䅁䉁䅑䉃䵹⼯⼯⼯䴸䅉䅅䅁䕁䅁䅁睁䵁䅁䅁权摁䅁䅁权䉁䅁䅁权摂䅁䅁允䅁䅁䅅䅁啁䅁䅑䅁䅁䅁䅁䍄䉁䅁䅁䅂䅁䅁䅍䅄䅁䅁䅯儯䅁䅁䅯允䅁䅁䅯兇䅁䅁䅅䅁䉁䅁䅁兂㕂匶硙䭃佷䅑杷允䅁䅁䅑䅁䑁䅁䅷䅁䭁䍁䅯䅁䭁䅁䅅䅁䭁䑁䅣䅁䉁䅁䅁允䅁䅁䅕㑎䉬余兘樸䴸䅉䅅䅁䕁䅁䅁睁䵁䅁䅁权䕂䅁䅁权䉁䅁䅁权㍁䅁䅁允䅁䅁䅅䅁䙁䅁塲㍯㥁畃⽏䍄䉁䅁䅁䅂䅁䅁䅍䅄䅁䅁䅯眫䅁䅁䅯允䅁䅁䅯兇䅁䅁䅅䅁䉁䅁䅁兂㝂䭆䠵場歲睐杷允䅁䅁䅑䅁䑁䅁䅷䅁䭁䍁䄴䅁䭁䅁䅅䅁䭁䕁䅁䅁䉁䅁䅁允䅁䅁䅕浚浚浚浚樵䴸䅉䅅䅁䕁䅁䅁睁䵁䅁䅁权慂允䅁权䉁䅁䅁权摂䅁䅁允䅁䅁䅅䅁䙁䝁㝑〳丫㥬⼴䍄䉁䅁䅁䅂䅁䅁䅍䅄䅁䅁䅯䅍䅁䅁䅯允䅁䅁䅯睉䅁䅁䅅䅁䉁䅁䅁兂㍂灶愸㥌䬰䅑杷允䅁䅁䅑䅁䑁䅁䅷䅁䭁䵁䅣䅁䭁䅁䅫䅁䭁䅁䄰䅁䉁䅁䅁允䅁䉁䅑䩷㍹⼯⼯⼯䴸䅉䅅䅁䕁䅁䅁睁䵁䅁䅁权兂䅁䅁权䩁䅁䅁权潁䅁䅁允䅁䅁䅅䅁啁佁橁⼸⼷⼯⼯䍄䉁䅁䅁䅂䅁䅁䅍䅄䅁䅁䅯兕䅁䅁䅯允䅁䅁䅯兄䅁䅁䅅䅁䉁䅁䅁兂硂児塲㍯䉁䅑杷允䅁䅁䅑䅁䑁䅁䅷䅁䭁䍁䅙䅁䭁䅁䅅䅁䭁䉁䅅䅁䉁䅁䅁允䅁䅁䅕場啯歲桦橹䴸䅉䅅䅁䕁䅁䅁睁䵁䅁䅁权ぃ䅁䅁权䉁䅁䅁权剁䅁䅁允䅁䅁䅅䅁䙁䅁牉硨婢畺⽳䍄䉁䅁䅁䅂䅁䅁䅍䅄䅁䅁䅯杕䅁䅁䅯允䅁䅁䅯兄䅁䅁䅅䅁䉁䅁䅁兂卂䉵䘶ㄶえ睐杷允䅁䅁䅑䅁䑁䅁䅷䅁䭁䱁䅁䅁䭁䅁䅅䅁䭁䍁䅉䅁䉁䅁䅁允䅁䅁䅕㡪ㅌ䙋偹樶䴸䅉䅅䅁䕁䅁䅁睁䵁䅁䅁权灂䅁䅁权䉁䅁䅁权䙁䅁䅁允䅁䅁䅅䅁䙁䩁婱婭婭摭⽫䍄䉁䅁䅁䅂䅁䅁䅍䅄䅁䅁䅯䅃䅁䅁䅯元䅁䅁䅯杉䅁䅁䅅䅁䉁䅁䅁䅆杁瀫⽄⼯⼯眯杷允䅁䅁䅑䅁䑁䅁䅷䅁䭁䍁䄸䅁䭁䅁䅅䅁䭁䉁䅫䅁䉁䅁䅁允䅁䅁䅕瑃橥䑣䬰稵䴸䅉䅅䅁䕁䅁䅁睁䵁䅁䅁权䱁䅁䅁权䩁䅁䅁权楁䅁䅁允䅁䅁䅅䅁啁䍁㙄偫⼯⼯⼯䍄䉁䅁䅁䅂䅁䅁䅍䅄䅁䅁䅯杰䅁䅁䅯允䅁䅁䅯兄䅁䅁䅅䅁䉁䅁䅁兂扄堫焵䡶穓睶杷允䅁䅁䅑䅁䑁䅁䅷䅁䭁䍁䉣䅁䭁䅁䅅䅁䭁䉁䅍䅁䉁䅁䅁允䅁䅁䅕㡪ㅌ䙋偹樴䴸䅉䅅䅁䕁䅁䅁睁䵁䅁䅁权䵁䅁䅁权䉁䅁䅁权楁䅁䅁允䅁䅁䅅䅁䙁䩁婱婭婭晭⽅䍄䉁䅁䅁䅂䅁䅁䅍䅄䅁䅁䅯杚䅁䅁䅯允䅁䅁䅯兌䅁䅁䅅䅁䉁䅁䅁兂㉄䙋偹癷䭕䅑杷允䅁䅁䅑䅁䑁䅁䅷䅁䭁䩁䅯䅁䭁䅁䅅䅁䭁䉁䅷䅁䉁䅁䅁允䅁䅁䅕兊䉡啬䱏䐱䴸䅉䅅䅁䕁䅁䅁睁䵁䅁䅁权塁䅁䅁权䉁䅁䅁权㝁䅁䅁允䅁䅁䅅䅁啁䅁䅉䅁䅁䅁䅁䍄䉁䅁䅁䅂䅁䅁䅍䅄䅁䅁䅯村䅁䅁䅯允䅁䅁䅯睉䅁䅁䅅䅁䉁䅁䅁兂桁䡳潊敫漳睐杷允䅁䅁䅑䅁䑁䅁䅷䅁䭁䍁䄴䅁䭁䅁䅅䅁䭁䅁䅉䅁䉁䅁䅁允䅁䅁䅯睁䅁䅁杷允䅁䅁䅑䅁䑁䅁䅷䅁䭁䅁䉁䅁䭁䅁䅅䅁䭁䉁䅳䅁䉁䅁䅁允䅁䅁䅕䅁䅁䅁䅁歃䵁䅉䅅䅁䕁䅁䅁睁䵁䅁䅁权慁䅁䅁权䉁䅁䅁权潁䅁䅁允䅁䅁䅅䅁䙁䕁䱓佢㝦共䅆䍄䉁䅁䅁䅂䅁䅁䅍䅄䅁䅁䅯睕䅁䅁䅯允䅁䅁䅯权䅁䅁䅅䅁䉁䅁䅁兂捂㡪ㅌ䙋慷䅷杷允䅁䅁䅑䅁䑁䅁䅷䅁䭁䙁䅧䅁䭁䅁䅅䅁䭁䕁䅁䅁䉁䅁䅁允䅁䅁䅕積積積積い䵁䅉䅅䅁䕁䅁䅁睁䵁䅁䅁权䍄䅁䅁权䉁䅁䅁权噁䅁䅁允䅁䅁䅅䅁䭁䅁䅍䅁䵁䅉䅅䅁䕁䅁䅁睁䵁䅁䅁权楄䅁䅁权䉁䅁䅁权噁䅁䅁允䅁䅁䅅䅁䙁䅁䍷㑋坣搲⽙䍄䉁䅁䅁䅂䅁䅁䅍䅄䅁䅁䅯兇䅅䅁䅯允䅁䅁䅯权䅁䅁䅅䅁䉁䅁䅁兂啁歲桦桥㙔睐杷允䅁䅁䅑䅁䑁䅁䅷䅁䭁䥁䅳䅁䭁䅁䅅䅁䭁䑁䅣䅁䉁䅁䅁允䅁䅁䅕䘷㑇潈牘商䵁䅉䅅䅁䕁䅁䅁睁䵁䅁䅁权慁䅁䅁权䉁䅁䅁权䩂䅁䅁允䅁䅁䅅䅁䙁䍁䡵瑆佮⬹⼸䍄䉁䅁䅁䅂䅁䅁䅍䅄䅁䅁䅯免䅁䅁䅯允䅁䅁䅯杁䅁䅁䅅䅁䉁䅁䅁权䑁䅁䅁䍄䉁䅁䅁䅂䅁䅁䅍䅄䅁䅁䅯杨䅁䅁䅯允䅁䅁䅯睏䅁䅁䅅䅁䉁䅁䅁兂獄払敧敨灶睐杷允䅁䅁䅑䅁䑁䅁䅷䅁䭁䉁䅣䅁䭁䅁䅅䅁䭁䉁䅅䅁䉁䅁䅁允䅁䅁䅕硨婢発呤稸䴸䅉䅅䅁䕁䅁䅁睁䵁䅁䅁权祂䅁䅁权䉁䅁䅁权扁䅁䅁允䅁䅁䅅䅁䙁䉁䘫ㄶ㑇橘䅚䍄䉁䅁䅁䅂䅁䅁䅍䅄䅁䅁䅯杶䅁䅁䅯允䅁䅁䅯睅䅁䅁䅅䅁䉁䅁䅁兂㑃潈牘払敪睐杷允䅁䅁䅑䅁䑁䅁䅷䅁䭁䉁䉫䅁䭁䅁䅅䅁䭁䑁䅳䅁䉁䅁䅁允䅁䅁䅕䭆䠵場啯樹䴸䅉䅅䅁䕁䅁䅁睁䵁䅁䅁权呂䅁䅁权䉁䅁䅁权剁䅁䅁允䅁䅁䅅䅁䙁佁剸䉵䘶眶䄱䍄䉁䅁䅁䅂䅁䅁䅍䅄䅁䅁䅯兖䅁䅁䅯允䅁䅁䅯兄䅁䅁䅅䅁䉁䅁䅁兂煂䡶呓䅇䝔睐杷允䅁䅁䅑䅁䑁䅁䅷䅁䭁䩁䅅䅁䭁䅁䅅䅁䭁䍁䅉䅁䉁䅁䅁允䅁䅁䅕⽷潕䥘䌯含䴸䅉䅅䅁䕁䅁䅁睁䵁䅁䅁权剁允䅁权䉁䅁䅁权㍁䅁䅁允䅁䅁䅅䅁䙁䭁䝪穓䩥剷䅆䍄䉁䅁䅁䅂䅁䅁䅍䅄䅁䅁䅯䅕䅁䅁䅯元䅁䅁䅯䅑䅁䅁䅅䅁䉁䅁䅁䅆潁噍⽦⼯⼯眯杷允䅁䅁䅑䅁䑁䅁䅷䅁䭁䵁䅣䅁䭁䅁䅫䅁䭁䍁䅣䅁䉁䅁䅁允䅁䉁䅑䡱牒⼯⼯⼯䴸䅉䅅䅁䕁䅁䅁睁䵁䅁䅁权⽂䅁䅁权䉁䅁䅁权䙁䅁䅁允䅁䅁䅅䅁啁䅁䅅䅁䅁䅁䅁䍄䉁䅁䅁䅂䅁䅁䅍䅄䅁䅁䅯杖䅅䅁䅯允䅁䅁䅯杁䅁䅁䅅䅁䉁䅁䅁权䑁䅁䅁䍄䉁䅁䅁䅂䅁䅁䅍䅄䅁䅁䅯䅎䅁䅁䅯允䅁䅁䅯杉䅁䅁䅅䅁䉁䅁䅁兂硂児塲㍯䉁䅑杷允䅁䅁䅑䅁䑁䅁䅷䅁䭁䩁䅉䅁䭁䅁䅅䅁䭁䑁䅳䅁䉁䅁䅁允䅁䅁䅕䥘䌯匹捨稳䴸䅉䅅䅁䕁䅁䅁睁䵁䅁䅁权捂允䅁权䉁䅁䅁权杁䅁䅁允䅁䅁䅅䅁䙁偁潙䥘䌯昹⽷䍄䉁䅁䅁䅂䅁䅁䅍䅄䅁䅁䅯兢䅁䅁䅯允䅁䅁䅯睎䅁䅁䅅䅁䉁䅁䅁兂㝁〳丫㉬礶睐杷允䅁䅁䅑䅁䑁䅁䅷䅁䭁䉁䉫䅁䭁䅁䅅䅁䭁䉁䅅䅁䉁䅁䅁允䅁䅁䅕児塲㍯㥁樹䴸䅉䅅䅁䕁䅁䅁睁䵁䅁䅁权ㅃ䅁䅁权䉁䅁䅁权䅂䅁䅁允䅁䅁䅅䅁䙁䱁敧敨剴䩵⼴䍄䉁䅁䅁䅂䅁䅁䅍䅄䅁䅁䅯䅃䅁䅁䅯睘䅅䅁䅯兇䅁䅁䅅䅁䉁䅁䅁䅆㑁䵲䅁䅁䅁䅁杷允䅁䅁䅑䅁䑁䅁䅷䅁䭁䙁䅙䅁䭁䅁䅅䅁䭁䅁䅉䅁䉁䅁䅁允䅁䅁䅯睁䅁䅁杷允䅁䅁䅑䅁䑁䅁䅷䅁䭁䙁䅣䅁䭁䅁䅅䅁䭁䅁䅯䅁䉁䅁䅁允䅁䅁䅕䘷㑇潈牘吶䴸䅉䅅䅁䕁䅁䅁睁䵁䅁䅁权䑁允䅁权䉁䅁䅁权潁䅁䅁允䅁䅁䅅䅁䙁䙁㑋潈牘兕䅒䍄䉁䅁䅁䅂䅁䅁䅍䅄䅁䅁䅯䅲䅁䅁䅯允䅁䅁䅯兓䅁䅁䅅䅁䉁䅁䅁兂佂桙奂扏䍑䅑杷允䅁䅁䅑䅁䑁䅁䅷䅁䭁䍁䈸䅁䭁䅁䅅䅁䭁䉁䅅䅁䉁䅁䅁允䅁䅁䅕䩡瑈䑦ㄸ樴䴸䅉䅅䅁䕁䅁䅁睁䵁䅁䅁权杁允䅁权䉁䅁䅁权潁䅁䅁允䅁䅁䅅䅁䙁䩁瘷㡰䱚⭎⽅䍄䉁䅁䅁䅂䅁䅁䅍䅄䅁䅁䅯睓䅁䅁䅯允䅁䅁䅯兘䅁䅁䅅䅁䉁䅁䅁兂穁積積積穐睐杷允䅁䅁䅑䅁䑁䅁䅷䅁䭁䱁䅣䅁䭁䅁䅅䅁䭁䉁䅅䅁䉁䅁䅁允䅁䅁䅕䡰㥁瑃橥䕁䵁䅉䅅䅁䕁䅁䅁睁䵁䅁䅁权浂䅁䅁权䉁䅁䅁权㍁䅁䅁允䅁䅁䅅䅁䙁䕁桪桥畓⽒⽅䍄䉁䅁䅁䅂䅁䅁䅍䅄䅁䅁䅯䅢䅁䅁䅯允䅁䅁䅯䅈䅁䅁䅅䅁䉁䅁䅁兂睄㡰䱚㑎⽮睐杷允䅁䅁䅑䅁䑁䅁䅷䅁䭁䅁䉁䅁䭁䅁䅅䅁䭁䉁䅕䅁䉁䅁䅁允䅁䅁䅕椹捨㡪ㅌ啁䵁䅉䅅䅁䕁䅁䅁睁䵁䅁䅁权潂䅁䅁权䉁䅁䅁权䙁䅁䅁允䅁䅁䅅䅁䙁䉁䘫ㄶ㑇杈䅆䍄䉁䅁䅁䅂䅁䅁䅍䅄䅁䅁䅯児䅅䅁䅯允䅁䅁䅯兆䅁䅁䅅䅁䉁䅁䅁兂慃婭婭婭婭睶杷允䅁䅁䅑䅁䑁䅁䅷䅁䭁䝁䅍䅁䭁䅁䅅䅁䭁䉁䅅䅁䉁䅁䅁允䅁䅁䅕浔光䑗ね䐹䴸䅉䅅䅁䕁䅁䅁睁䵁䅁䅁权㉂䅁䅁权䉁䅁䅁权潁䅁䅁允䅁䅁䅅䅁䙁䩁䕺䱉祂䅡䅖䍄䉁䅁䅁䅂䅁䅁䅍䅄䅁䅁䅯关䅁䅁䅯允䅁䅁䅯兂䅁䅁䅅䅁䉁䅁䅁兂瑂⼵灵嘸癉䅷杷允䅁䅁䅑䅁䑁䅁䅷䅁䭁䱁䅫䅁䭁䅁䅅䅁䭁䉁䅷䅁䉁䅁䅁允䅁䅁䅕積積積積稰䴸䅉䅅䅁䕁䅁䅁睁䵁䅁䅁权㙁䅁䅁权䉁䅁䅁权䩂䅁䅁允䅁䅁䅅䅁䙁䝁剩堷⽷兎䅎䍄䉁䅁䅁䅂䅁䅁䅍䅄䅁䅁䅯児䅁䅁䅯允䅁䅁䅯睅䅁䅁䅅䅁䉁䅁䅁兂㑃潈牘払佪睐杷允䅁䅁䅑䅁䑁䅁䅷䅁䭁䉁䉫䅁䭁䅁䅅䅁䭁䅁䄰䅁䉁䅁䅁允䅁䅁䅕䬸䝦穓䩥吶䴸䅉䅅䅁䕁䅁䅁睁䵁䅁䅁权㝃䅁䅁权䉁䅁䅁权䍁䅁䅁允䅁䅁䅅䅁䭁䅁䅍䅁䵁䅉䅅䅁䕁䅁䅁睁䵁䅁䅁权啁䅁䅁权䉁䅁䅁权㝁䅁䅁允䅁䅁䅅䅁䙁䥁牘払敧晨⽍䍄䉁䅁䅁䅂䅁䅁䅍䅄䅁䅁䅯睕䅁䅁䅯允䅁䅁䅯杉䅁䅁䅅䅁䉁䅁䅁兂浂浚浚畚奙䅷杷允䅁䅁䅑䅁䑁䅁䅷䅁䭁䉁䉑䅁䭁䅁䅅䅁䭁䅁䅯䅁䉁䅁䅁允䅁䅁䅕䘷㑇潈牘启䴸䅉䅅䅁䕁䅁䅁睁䵁䅁䅁权睁䅁䅁权䉁䅁䅁权㝁䅁䅁允䅁䅁䅅䅁䙁䱁へ硫䕧楬䄱䍄䉁䅁䅁䅂䅁䅁䅍䅄䅁䅁䅯䅥䅁䅁䅯允䅁䅁䅯睇䅁䅁䅅䅁䉁䅁䅁兂畃⭒㙆䭆㜷睐杷允䅁䅁䅑䅁䑁䅁䅷䅁䭁䑁䅫䅁䭁䅁䅅䅁䭁䍁䄰䅁䉁䅁䅁允䅁䅁䅕䥘䌯匹捨稸䴸䅉䅅䅁䕁䅁䅁睁䵁䅁䅁权慂䅁䅁权䉁䅁䅁权䙁䅁䅁允䅁䅁䅅䅁䙁䝁浚浚浚畚⽯䍄䉁䅁䅁䅂䅁䅁䅍䅄䅁䅁䅯眶䅁䅁䅯允䅁䅁䅯兌䅁䅁䅅䅁䉁䅁䅁兂㉃⼸唳佥楮睐杷允䅁䅁䅑䅁䑁䅁䅷䅁䭁䅁䅷䅁䭁䅁䅅䅁䭁䉁䅕䅁䉁䅁䅁允䅁䅁䅕浚浚浚浚樯䴸䅉䅅䅁䕁䅁䅁睁䵁䅁䅁权乁允䅁权䉁䅁䅁权偁䅁䅁允䅁䅁䅅䅁䙁䥁䌯匹捨睪䄵䍄䉁䅁䅁䅂䅁䅁䅍䅄䅁䅁䅯兖䅅䅁䅯允䅁䅁䅯兂䅁䅁䅅䅁䉁䅁䅁兂獄払敧敨硶睐杷允䅁䅁䅑䅁䑁䅁䅷䅁䭁䑁䄴䅁䭁䅁䅅䅁䭁䑁䅉䅁䉁䅁䅁允䅁䅁䅕体㙆䭆䠵含䴸䅉䅅䅁䕁䅁䅁睁䵁䅁䅁权扂䅁䅁权䉁䅁䅁权䩂䅁䅁允䅁䅁䅅䅁䙁䡁啳歲桦煥⽓䍄䉁䅁䅁䅂䅁䅁䅍䅄䅁䅁䅯兮䅁䅁䅯允䅁䅁䅯睎䅁䅁䅅䅁䉁䅁䅁兂䑄匹捨㡪汌睐杷允䅁䅁䅑䅁䑁䅁䅷䅁䭁䙁䉍䅁䭁䅁䅅䅁䭁䉁䅫䅁䉁䅁䅁允䅁䅁䅕牕敧敨剴䐲䴸䅉䅅䅁䕁䅁䅁睁䵁䅁䅁权䥁䅁䅁权䩁䅁䅁权䙁䅁䅁允䅁䅁䅅䅁啁偁敨偰⼯⼯⼯䍄䉁䅁䅁䅂䅁䅁䅍䅄䅁䅁䅯睁䅅䅁䅯允䅁䅁䅯兌䅁䅁䅅䅁䉁䅁䅁兂䵁楁䡵瑆⭮睐杷允䅁䅁䅑䅁䑁䅁䅷䅁䭁䅁䅧䅁䭁䅁䅫䅁䭁䑁䅣䅁䉁䅁䅁允䅁䉁䅑义塃⼯⼯⼯䴸䅉䅅䅁䕁䅁䅁睁䵁䅁䅁权癃䅁䅁权䉁䅁䅁权䩂䅁䅁允䅁䅁䅅䅁䙁䍁捬㡪ㅌ偋⽷䍄䉁䅁䅁䅂䅁䅁䅍䅄䅁䅁䅯睃䅁䅁䅯元䅁䅁䅯睎䅁䅁䅅䅁䉁䅁䅁䅆杁䨰⽦⼯⼯眯杷允䅁䅁䅑䅁䑁䅁䅷䅁䭁䱁䄴䅁䭁䅁䅅䅁䭁䑁䅣䅁䉁䅁䅁允䅁䅁䅕歲桦桥畓稹䴸䅉䅅䅁䕁䅁䅁睁䵁䅁䅁权䕂䅁䅁权䉁䅁䅁权橁䅁䅁允䅁䅁䅅䅁䙁䡁潎敫㠱㥐⽕䍄䉁䅁䅁䅂䅁䅁䅍䅄䅁䅁䅯杖䅁䅁䅯允䅁䅁䅯权䅁䅁䅅䅁䉁䅁䅁兂灁䥘䌯匹啧䅑杷允䅁䅁䅑䅁䑁䅁䅷䅁䭁䡁䅉䅁䭁䅁䅅䅁䭁䍁䄰䅁䉁䅁䅁允䅁䅁䅕䑔䩥坑汄啌䵁䅉䅅䅁䕁䅁䅁睁䵁䅁䅁权䡃䅁䅁权䉁䅁䅁权㝁䅁䅁允䅁䅁䅅䅁䙁佁剸䉵䘶眶䄱䍄䉁䅁䅁䅂䅁䅁䅍䅄䅁䅁䅯䅅䅁䅁䅯允䅁䅁䅯睅䅁䅁䅅䅁䉁䅁䅁兂卂䉵䘶ㄶ㡈睐杷允䅁䅁䅑䅁䑁䅁䅷䅁䭁䡁䅁䅁䭁䅁䅅䅁䭁䍁䅣䅁䉁䅁䅁允䅁䅁䅕⼲⭬牡へ捄䵁䅉䅅䅁䕁䅁䅁睁䵁䅁䅁权呂䅁䅁权䉁䅁䅁权扁䅁䅁允䅁䅁䅅䅁䙁佁浫免獩䅈䅆䍄䉁䅁䅁䅂䅁䅁䅍䅄䅁䅁䅯䅃䅁䅁䅯睘䅅䅁䅯䅋䅁䅁䅅䅁䉁䅁䅁䅆䅃灦䉙䅁䅁䅁杷允䅁䅁䅑䅁䑁䅁䅷䅁䭁䡁䅑䅁䭁䅁䅅䅁䭁䅁䄰䅁䉁䅁䅁允䅁䅁䅕婪畤潅䅐ぃ䵁䅉䅅䅁䕁䅁䅁睁䵁䅁䅁权十允䅁权䉁䅁䅁权䍁䅁䅁允䅁䅁䅅䅁䭁䅁䅍䅁䵁䅉䅅䅁䕁䅁䅁睁䵁䅁䅁权䕄䅁䅁权䉁䅁䅁权摂䅁䅁允䅁䅁䅅䅁䙁䑁積積積⭍⽍䍄䉁䅁䅁䅂䅁䅁䅍䅄䅁䅁䅯儸䅁䅁䅯允䅁䅁䅯睅䅁䅁䅅䅁䉁䅁䅁兂婄発呤㘴湘睐杷允䅁䅁䅑䅁䑁䅁䅷䅁䭁䑁䉫䅁䭁䅁䅅䅁䭁䅁䅉䅁䉁䅁䅁允䅁䅁䅯睁䅁䅁杷允䅁䅁䅑䅁䑁䅁䅷䅁䭁佁䅫䅁䭁䅁䅅䅁䭁䍁䅁䅁䉁䅁䅁允䅁䅁䅯睁䅁䅁杷允䅁䅁䅑䅁䑁䅁䅷䅁䭁偁䄸䅁䭁䅁䅅䅁䭁䍁䅁䅁䉁䅁䅁允䅁䅁䅕䉵䘶ㄶ㑇歄䵁䅉䅅䅁䕁䅁䅁睁䵁䅁䅁权硁䅁䅁权䉁䅁䅁权杁䅁䅁允䅁䅁䅅䅁䙁䡁呗䅇坒杄䅊䍄䉁䅁䅁䅂䅁䅁䅍䅄䅁䅁䅯睖䅅䅁䅯允䅁䅁䅯睎䅁䅁䅅䅁䉁䅁䅁兂䭁㘱睎児㥲睐杷允䅁䅁䅑䅁䑁䅁䅷䅁䭁䙁䅷䅁䭁䅁䅅䅁䭁䙁䄰䅁䉁䅁䅁允䅁䅁䅕䉵䘶ㄶ㑇樫䴸䅉䅅䅁䕁䅁䅁睁䵁䅁䅁权㝃䅁䅁权䉁䅁䅁权剁䅁䅁允䅁䅁䅅䅁䙁䵁ㅐ䙋偹瑷⽕䍄䉁䅁䅁䅂䅁䅁䅍䅄䅁䅁䅯杆䅅䅁䅯允䅁䅁䅯充䅁䅁䅅䅁䉁䅁䅁兂療潅䅐浹桅䅑杷允䅁䅁䅑䅁䑁䅁䅷䅁䭁䝁䅫䅁䭁䅁䅅䅁䭁䅁䄰䅁䉁䅁䅁允䅁䅁䅕歲桦桥畓稱䴸䅉䅅䅁䕁䅁䅁睁䵁䅁䅁权祄䅁䅁权䉁䅁䅁权摂䅁䅁允䅁䅁䅅䅁䙁佁㙆䭆䠵昴⽯䍄䉁䅁䅁䅂䅁䅁䅍䅄䅁䅁䅯杘䅁䅁䅯允䅁䅁䅯睂䅁䅁䅅䅁䉁䅁䅁兂䑄匹捨㡪ㅌ睐杷允䅁䅁䅑䅁䑁䅁䅷䅁䭁䥁䅍䅁䭁䅁䅅䅁䭁䕁䅫䅁䉁䅁䅁允䅁䅁䅕䬸䝦穓䩥啁䵁䅉䅅䅁䕁䅁䅁睁䵁䅁䅁权佄䅁䅁权䉁䅁䅁权橁䅁䅁允䅁䅁䅅䅁䙁䥁牘払敧敨⽍䍄䉁䅁䅁䅂䅁䅁䅍䅄䅁䅁䅯儲䅁䅁䅯允䅁䅁䅯睎䅁䅁䅅䅁䉁䅁䅁兂晁敨剴䉵氷睐杷允䅁䅁䅑䅁䑁䅁䅷䅁䭁偁䅍䅁䭁䅁䅅䅁䭁䑁䅣䅁䉁䅁䅁允䅁䅁䅕䥘䌯匹捨㡁䵁䅉䅅䅁䕁䅁䅁睁䵁䅁䅁权楁允䅁权䉁䅁䅁权瑁䅁䅁允䅁䅁䅅䅁䙁䭁睒児塲⽯⽁䍄䉁䅁䅁䅂䅁䅁䅍䅄䅁䅁䅯䅁䅁䅁䅯允䅁䅁䅯睄䅁䅁䅅䅁䉁䅁䅁兂㝂䭆䠵場睲睐杷允䅁䅁䅑䅁䑁䅁䅷䅁䭁䝁䅷䅁䭁䅁䅅䅁䭁䉁䅕䅁䉁䅁䅁允䅁䅁䅕呣䬰㘱睎㡁䵁䅉䅅䅁䕁䅁䅁睁䵁䅁䅁权䥁䅁䅁权䩁䅁䅁权祁䅁䅁允䅁䅁䅅䅁啁䡁瑃癡⼯⼯⼯䍄䉁䅁䅁䅂䅁䅁䅍䅄䅁䅁䅯睃䅁䅁䅯元䅁䅁䅯杍䅁䅁䅅䅁䉁䅁䅁䅆睂坲⽲⼯⼯眯杷允䅁䅁䅑䅁䑁䅁䅷䅁䭁䥁䅉䅁䭁䅁䅅䅁䭁䅁䄸䅁䉁䅁䅁允䅁䅁䅕余兘瑉㕶樹䴸䅉䅅䅁䕁䅁䅁睁䵁䅁䅁权敁允䅁权䉁䅁䅁权䡁䅁䅁允䅁䅁䅅䅁䙁䱁敧敨剴䅵䅂䍄䉁䅁䅁䅂䅁䅁䅍䅄䅁䅁䅯睆䅁䅁䅯允䅁䅁䅯睊䅁䅁䅅䅁䉁䅁䅁兂坂楄礲敮䄸䅑杷允䅁䅁䅑䅁䑁䅁䅷䅁䭁䙁䄸䅁䭁䅁䅅䅁䭁䑁䅉䅁䉁䅁䅁允䅁䅁䅕歯㉗⼸唳䐶䴸䅉䅅䅁䕁䅁䅁睁䵁䅁䅁权啄䅁䅁权䉁䅁䅁权剁䅁䅁允䅁䅁䅅䅁䙁佁剸䉵䘶砶䅂䍄䉁䅁䅁䅂䅁䅁䅍䅄䅁䅁䅯兒䅅䅁䅯允䅁䅁䅯睏䅁䅁䅅䅁䉁䅁䅁兂偃癷潕䥘㘯睐杷允䅁䅁䅑䅁䑁䅁䅷䅁䭁䩁䄸䅁䭁䅁䅅䅁䭁䕁䅫䅁䉁䅁䅁允䅁䅁䅕㘱睎児塲稲䴸䅉䅅䅁䕁䅁䅁睁䵁䅁䅁权䝃䅁䅁权䉁䅁䅁权杁䅁䅁允䅁䅁䅅䅁䙁䝁浚浚浚畚⼴䍄䉁䅁䅁䅂䅁䅁䅍䅄䅁䅁䅯䅁䅁䅁䅯允䅁䅁䅯䅑䅁䅁䅅䅁䉁䅁䅁兂桄桥畓⭒楈睐杷允䅁䅁䅑䅁䑁䅁䅷䅁䭁䱁䅅䅁䭁䅁䅅䅁䭁䉁䅫䅁䉁䅁䅁允䅁䅁䅕硥畓⭒㙆䱬䴸䅉䅅䅁䕁䅁䅁睁䵁䅁䅁权偂允䅁权䉁䅁䅁权橁䅁䅁允䅁䅁䅅䅁䙁䅁塲㍯㥁桃䅊䍄䉁䅁䅁䅂䅁䅁䅍䅄䅁䅁䅯䅙䅁䅁䅯允䅁䅁䅯兌䅁䅁䅅䅁䉁䅁䅁兂䑃䵷桱扒湢睐杷允䅁䅁䅑䅁䑁䅁䅷䅁䭁䙁䅧䅁䭁䅁䅅䅁䭁䉁䅕䅁䉁䅁䅁允䅁䅁䅕䭃捷浗㝑歃䵁䅉䅅䅁䕁䅁䅁睁䵁䅁䅁权扂䅁䅁权䉁䅁䅁权扁䅁䅁允䅁䅁䅅䅁䙁䡁㥅瑃橥䵣⼰䍄䉁䅁䅁䅂䅁䅁䅍䅄䅁䅁䅯䅴䅁䅁䅯允䅁䅁䅯睎䅁䅁䅅䅁䉁䅁䅁兂桄桥畓⭒午睶杷允䅁䅁䅑䅁䑁䅁䅷䅁䭁䝁䅉䅁䭁䅁䅅䅁䭁䉁䅷䅁䉁䅁䅁允䅁䅁䅕倹唳佥浫呷䴸䅉䅅䅁䕁䅁䅁睁䵁䅁䅁权塁允䅁权䉁䅁䅁权摂䅁䅁允䅁䅁䅅䅁䙁䩁婱婭婭敭⽫䍄䉁䅁䅁䅂䅁䅁䅍䅄䅁䅁䅯杅䅁䅁䅯允䅁䅁䅯睊䅁䅁䅅䅁䉁䅁䅁兂偃癷潕䥘愯睐杷允䅁䅁䅑䅁䑁䅁䅷䅁䭁䉁䅯䅁䭁䅁䅅䅁䭁䍁䅣䅁䉁䅁䅁允䅁䅁䅕⽺呤㘴扗樸䴸䅉䅅䅁䕁䅁䅁睁䵁䅁䅁权療䅁䅁权䉁䅁䅁权瑁䅁䅁允䅁䅁䅅䅁䙁䥁䌯匹捨⽪⼴䍄䉁䅁䅁䅂䅁䅁䅍䅄䅁䅁䅯䅅䅁䅁䅯允䅁䅁䅯杍䅁䅁䅅䅁䉁䅁䅁兂浂浚浚浚䅙䅑杷允䅁䅁䅑䅁䑁䅁䅷䅁䭁䝁䅍䅁䭁䅁䅅䅁䭁䕁䅁䅁䉁䅁䅁允䅁䅁䅕牕敧敨剴䐲䴸䅉䅅䅁䕁䅁䅁睁䵁䅁䅁权䡄䅁䅁权時允䅁权剁䅁䅁允䅁䅁䅅䅁啁乁潩朰䅅䅁䅁䍄䉁䅁䅁䅂䅁䅁䅍䅄䅁䅁䅯䄸䅁䅁䅯允䅁䅁䅯兆䅁䅁䅅䅁䉁䅁䅁兂硁䭃捷浗癔睐杷允䅁䅁䅑䅁䑁䅁䅷䅁䭁䉁䅁䅁䭁䅁䅅䅁䭁䅁䄰䅁䉁䅁䅁允䅁䅁䅕体㙆䭆䠵吶䴸䅉䅅䅁䕁䅁䅁睁䵁䅁䅁权䕂允䅁权䉁䅁䅁权䍁䅁䅁允䅁䅁䅅䅁䭁䅁䅍䅁䵁䅉䅅䅁䕁䅁䅁睁䵁䅁䅁权慁䅁䅁权䉁䅁䅁权呁䅁䅁允䅁䅁䅅䅁䙁䱁䥔牤昶畇⽍䍄䉁䅁䅁䅂䅁䅁䅍䅄䅁䅁䅯朶䅁䅁䅯允䅁䅁䅯兌䅁䅁䅅䅁䉁䅁䅁兂硂児塲㍯乄睐杷允䅁䅁䅑䅁䑁䅁䅷䅁䭁䝁䅑䅁䭁䅁䅅䅁䭁䅁䅯䅁䉁䅁䅁允䅁䅁䅕䘷㑇潈牘含䴸䅉䅅䅁䕁䅁䅁睁䵁䅁䅁权慁䅁䅁权䉁䅁䅁权乁䅁䅁允䅁䅁䅅䅁䙁䭁睒児塲⽯⽁䍄䉁䅁䅁䅂䅁䅁䅍䅄䅁䅁䅯儳䅁䅁䅯允䅁䅁䅯兆䅁䅁䅅䅁䉁䅁䅁兂い搯㑒匶穢睐杷允䅁䅁䅑䅁䑁䅁䅷䅁䭁䉁䄸䅁䭁䅁䅅䅁䭁䅁䅣䅁䉁䅁䅁允䅁䅁䅕瑃橥䑣䬰稯䴸䅉䅅䅁䕁䅁䅁睁䵁䅁䅁权畄䅁䅁权䉁䅁䅁权剁䅁䅁允䅁䅁䅅䅁䙁䵁ㅐ䙋偹畷⽕䍄䉁䅁䅁䅂䅁䅁䅍䅄䅁䅁䅯党䅁䅁䅯允䅁䅁䅯充䅁䅁䅅䅁䉁䅁䅁兂慃婭婭婭䩮睐杷允䅁䅁䅑䅁䑁䅁䅷䅁䭁䥁䅯䅁䭁䅁䅅䅁䭁䉁䅅䅁䉁䅁䅁允䅁䅁䅕䉵䘶ㄶ㑇樵䴸䅉䅅䅁䕁䅁䅁睁䵁䅁䅁权塁允䅁权䉁䅁䅁权扁䅁䅁允䅁䅁䅅䅁䙁䥁䌯匹捨⭪⽯䍄䉁䅁䅁䅂䅁䅁䅍䅄䅁䅁䅯杵䅁䅁䅯允䅁䅁䅯睇䅁䅁䅅䅁䉁䅁䅁兂歃䑣䬰㘱潐睐杷允䅁䅁䅑䅁䑁䅁䅷䅁䭁佁䅳䅁䭁䅁䅅䅁䭁䕁䅫䅁䉁䅁䅁允䅁䅁䅕硥畓⭒㙆䱸䴸䅉䅅䅁䕁䅁䅁睁䵁䅁䅁权䕂䅁䅁权䉁䅁䅁权䙁䅁䅁允䅁䅁䅅䅁䙁䝁渳㘫确琰⽗䍄䉁䅁䅁䅂䅁䅁䅍䅄䅁䅁䅯兔䅁䅁䅯允䅁䅁䅯杉䅁䅁䅅䅁䉁䅁䅁兂扄堫焵䡶橓睐杷允䅁䅁䅑䅁䑁䅁䅷䅁䭁䙁䅁䅁䭁䅁䅫䅁䭁䍁䅉䅁䉁䅁䅁允䅁䉁䅑䉣䝣⼯⼯⼯䴸䅉䅅䅁䕁䅁䅁睁䵁䅁䅁权乂䅁䅁权䉁䅁䅁权瑁䅁䅁允䅁䅁䅅䅁䙁佁浫免獩佈⽯䍄䉁䅁䅁䅂䅁䅁䅍䅄䅁䅁䅯睵䅁䅁䅯允䅁䅁䅯䅑䅁䅁䅅䅁䉁䅁䅁兂剃堷⽷噎头䅷杷允䅁䅁䅑䅁䑁䅁䅷䅁䭁䕁䄸䅁䭁䅁䅅䅁䭁䉁䅳䅁䉁䅁䅁允䅁䅁䅕灰䕶䱉祂䕁䵁䅉䅅䅁䕁䅁䅁睁䵁䅁䅁权兄䅁䅁权䉁䅁䅁权橁䅁䅁允䅁䅁䅅䅁䙁偁湃歸㍳敩⽫䍄䉁䅁䅁䅂䅁䅁䅍䅄䅁䅁䅯杆䅅䅁䅯允䅁䅁䅯睊䅁䅁䅅䅁䉁䅁䅁兂䱄啯㉗㌸娰䅑杷允䅁䅁䅑䅁䑁䅁䅷䅁䭁䝁䅫䅁䭁䅁䅅䅁䭁䍁䅧䅁䉁䅁䅁允䅁䅁䅕㡪ㅌ䙋偹樶䴸䅉䅅䅁䕁䅁䅁睁䵁䅁䅁权㉃䅁䅁权䉁䅁䅁权瑁䅁䅁允䅁䅁䅅䅁䙁偁潙䥘䌯改⽁䍄䉁䅁䅁䅂䅁䅁䅍䅄䅁䅁䅯条䅁䅁䅯允䅁䅁䅯䅋䅁䅁䅅䅁䉁䅁䅁兂穁積積積㝐睐杷允䅁䅁䅑䅁䑁䅁䅷䅁䭁䡁䅳䅁䭁䅁䅅䅁䭁䍁䄰䅁䉁䅁䅁允䅁䅁䅕積積積積㝷䴸䅉䅅䅁䕁䅁䅁睁䵁䅁䅁权ㅁ䅁䅁权䉁䅁䅁权瑁䅁䅁允䅁䅁䅅䅁䙁乁橥䑣䬰⼱⽍䍄䉁䅁䅁䅂䅁䅁䅍䅄䅁䅁䅯睨䅁䅁䅯允䅁䅁䅯睂䅁䅁䅅䅁䉁䅁䅁兂硂児塲㍯䙁䅑杷允䅁䅁䅑䅁䑁䅁䅷䅁䭁䩁䅕䅁䭁䅁䅅䅁䭁䉁䅷䅁䉁䅁䅁允䅁䅁䅕椹捨㡪ㅌ歄䵁䅉䅅䅁䕁䅁䅁睁䵁䅁䅁权䥁䅁䅁权䩁䅁䅁权㝁䅁䅁允䅁䅁䅅䅁啁䕁穪⽬⼯⼯⼯䍄䉁䅁䅁䅂䅁䅁䅍䅄䅁䅁䅯杒䅁䅁䅯允䅁䅁䅯充䅁䅁䅅䅁䉁䅁䅁兂塄㍯㥁瑃㍦睐杷允䅁䅁䅑䅁䑁䅁䅷䅁䭁䱁䄸䅁䭁䅁䅅䅁䭁䑁䅉䅁䉁䅁䅁允䅁䅁䅕捺䵺䵺䵺䐯䴸䅉䅅䅁䕁䅁䅁睁䵁䅁䅁权汁允䅁权䉁䅁䅁权䭁䅁䅁允䅁䅁䅅䅁䙁䩁婱婭婭剭䅖䍄䉁䅁䅁䅂䅁䅁䅍䅄䅁䅁䅯睃䅁䅁䅯元䅁䅁䅯睏䅁䅁䅅䅁䉁䅁䅁䅆䥂㔸⽦⼯⼯眯杷允䅁䅁䅑䅁䑁䅁䅷䅁䭁䥁䅉䅁䭁䅁䅅䅁䭁䕁䅫䅁䉁䅁䅁允䅁䅁䅕㑈牘払敧吷䴸䅉䅅䅁䕁䅁䅁睁䵁䅁䅁权䙄䅁䅁权䉁䅁䅁权剁䅁䅁允䅁䅁䅅䅁䙁偁潙䥘䌯儹䄵䍄䉁䅁䅁䅂䅁䅁䅍䅄䅁䅁䅯兕䅅䅁䅯允䅁䅁䅯兇䅁䅁䅅䅁䉁䅁䅁兂潂敫㠱穐坘睐杷允䅁䅁䅑䅁䑁䅁䅷䅁䭁䑁䅁䅁䭁䅁䅅䅁䭁䉁䅅䅁䉁䅁䅁允䅁䅁䅕牕敧敨剴䕄䵁䅉䅅䅁䕁䅁䅁睁䵁䅁䅁权㍃䅁䅁权䉁䅁䅁权杁䅁䅁允䅁䅁䅅䅁䙁䑁積積積⽍⼸䍄䉁䅁䅁䅂䅁䅁䅍䅄䅁䅁䅯兕䅅䅁䅯允䅁䅁䅯兌䅁䅁䅅䅁䉁䅁䅁兂湁免獩䙈杲睐杷允䅁䅁䅑䅁䑁䅁䅷䅁䭁䥁䅅䅁䭁䅁䅅䅁䭁䉁䅍䅁䉁䅁䅁允䅁䅁䅯睁䅁䅁杷允䅁䅁䅑䅁䑁䅁䅷䅁䭁䱁䅧䅁䭁䅁䅅䅁䭁䑁䅳䅁䉁䅁䅁允䅁䅁䅕㡪ㅌ䙋偹樯䴸䅉䅅䅁䕁䅁䅁睁䵁䅁䅁权䡃䅁䅁权䉁䅁䅁权扁䅁䅁允䅁䅁䅅䅁䙁䵁ㅐ䙋偹桷䅆䍄䉁䅁䅁䅂䅁䅁䅍䅄䅁䅁䅯杪䅁䅁䅯允䅁䅁䅯睏䅁䅁䅅䅁䉁䅁䅁兂䑄匹捨㡪䉉䅑杷允䅁䅁䅑䅁䑁䅁䅷䅁䭁䱁䅳䅁䭁䅁䅅䅁䭁䍁䅁䅁䉁䅁䅁允䅁䅁䅕牡へ硫䕧爵䴸䅉䅅䅁䕁䅁䅁睁䵁䅁䅁权允䅁䅁权䉁䅁䅁权䭁䅁䅁允䅁䅁䅅䅁䙁䑁䬰㘱睎晐⽙䍄䉁䅁䅁䅂䅁䅁䅍䅄䅁䅁䅯䅦䅁䅁䅯允䅁䅁䅯䅑䅁䅁䅅䅁䉁䅁䅁兂晁敨剴䉵砷睐杷允䅁䅁䅑䅁䑁䅁䅷䅁䭁乁䅉䅁䭁䅁䅅䅁䭁䅁䅉䅁䉁䅁䅁允䅁䅁䅕体㙆䭆䠵啁䵁䅉䅅䅁䕁䅁䅁睁䵁䅁䅁权ぁ䅁䅁权䉁䅁䅁权橁䅁䅁允䅁䅁䅅䅁䙁䑁䬰㘱睎晐⽉䍄䉁䅁䅁䅂䅁䅁䅍䅄䅁䅁䅯杈䅅䅁䅯允䅁䅁䅯杁䅁䅁䅅䅁䉁䅁䅁权䑁䅁䅁䍄䉁䅁䅁䅂䅁䅁䅍䅄䅁䅁䅯杯䅁䅁䅯允䅁䅁䅯睊䅁䅁䅅䅁䉁䅁䅁兂硁䭃捷浗癔睐杷允䅁䅁䅑䅁䑁䅁䅷䅁䭁䕁䉅䅁䭁䅁䅅䅁䭁䉁䅷䅁䉁䅁䅁允䅁䅁䅕䭃捷浗㝑㝶䴸䅉䅅䅁䕁䅁䅁睁䵁䅁䅁权呄䅁䅁权䉁䅁䅁权䍁䅁䅁允䅁䅁䅅䅁䭁䅁䅍䅁䵁䅉䅅䅁䕁䅁䅁睁䵁䅁䅁权佁允䅁权䉁䅁䅁权橁䅁䅁允䅁䅁䅅䅁䙁䅁䅁䅁䅁䅁䅚䍄䉁䅁䅁䅂䅁䅁䅍䅄䅁䅁䅯䅢䅁䅁䅯允䅁䅁䅯䅑䅁䅁䅅䅁䉁䅁䅁兂偃癷潕䥘堸䅑杷允䅁䅁䅑䅁䑁䅁䅷䅁䭁䝁䄰䅁䭁䅁䅅䅁䭁䕁䅫䅁䉁䅁䅁允䅁䅁䅕䙅㕧䵴㉨橶䴸䅉䅅䅁䕁䅁䅁睁䵁䅁䅁权ㅂ䅁䅁权䉁䅁䅁权䙁䅁䅁允䅁䅁䅅䅁䙁䩁䕺䱉祂䵡⽇䍄䉁䅁䅁䅂䅁䅁䅍䅄䅁䅁䅯杸䅁䅁䅯允䅁䅁䅯睇䅁䅁䅅䅁䉁䅁䅁兂䭁㘱睎児癲睐杷允䅁䅁䅑䅁䑁䅁䅷䅁䭁䵁䄴䅁䭁䅁䅅䅁䭁䅁䄸䅁䉁䅁䅁允䅁䅁䅕敢㝦晱午獁䵁䅉䅅䅁䕁䅁䅁睁䵁䅁䅁权㙁允䅁权䉁䅁䅁权婁䅁䅁允䅁䅁䅅䅁䙁䡁啳歲桦略⽷䍄䉁䅁䅁䅂䅁䅁䅍䅄䅁䅁䅯杒䅅䅁䅯允䅁䅁䅯兓䅁䅁䅅䅁䉁䅁䅁兂䥂場啯歲剦睐杷允䅁䅁䅑䅁䑁䅁䅷䅁䭁䕁䈴䅁䭁䅁䅅䅁䭁䍁䅣䅁䉁䅁䅁允䅁䅁䅕䙅㕧䵴㉨䰹䴸䅉䅅䅁䕁䅁䅁睁䵁䅁䅁权佂䅁䅁权䉁䅁䅁权䙁䅁䅁允䅁䅁䅅䅁䙁䕁桪桥畓睒䅴䍄䉁䅁䅁䅂䅁䅁䅍䅄䅁䅁䅯兓䅅䅁䅯允䅁䅁䅯充䅁䅁䅅䅁䉁䅁䅁兂硂児塲ㅯ時䅑杷允䅁䅁䅑䅁䑁䅁䅷䅁䭁䝁䄴䅁䭁䅁䅅䅁䭁䅁䅕䅁䉁䅁䅁允䅁䅁䅕㡪ㅌ䙋偹歅䵁䅉䅅䅁䕁䅁䅁睁䵁䅁䅁权佃䅁䅁权䉁䅁䅁权噁䅁䅁允䅁䅁䅅䅁䙁䍁捬㡪ㅌ䍋䅂䍄䉁䅁䅁䅂䅁䅁䅍䅄䅁䅁䅯杴䅁䅁䅯允䅁䅁䅯䅋䅁䅁䅅䅁䉁䅁䅁兂䥂場啯歲灦睐杷允䅁䅁䅑䅁䑁䅁䅷䅁䭁䅁䅑䅁䭁䅁䅅䅁䭁䕁䅫䅁䉁䅁䅁允䅁䅁䅕匶硙䭃捷樹䴸䅉䅅䅁䕁䅁䅁睁䵁䅁䅁权乂䅁䅁权䉁䅁䅁权湁䅁䅁允䅁䅁䅅䅁䙁䭁䝪穓䩥晑⽉䍄䉁䅁䅁䅂䅁䅁䅍䅄䅁䅁䅯杚䅁䅁䅯允䅁䅁䅯睏䅁䅁䅅䅁䉁䅁䅁兂慂䑚晶㑔丰䅑杷允䅁䅁䅑䅁䑁䅁䅷䅁䭁䩁䅧䅁䭁䅁䅅䅁䭁䅁䄸䅁䉁䅁䅁允䅁䅁䅕椹捨㡪ㅌ䐯䴸䅉䅅䅁䕁䅁䅁睁䵁䅁䅁权療䅁䅁权䉁䅁䅁权婁䅁䅁允䅁䅁䅅䅁䙁䡁呗䅇坒瑄⼰䍄䉁䅁䅁䅂䅁䅁䅍䅄䅁䅁䅯兊䅁䅁䅯允䅁䅁䅯睊䅁䅁䅅䅁䉁䅁䅁兂湄㘫确欰眳睐杷允䅁䅁䅑䅁䑁䅁䅷䅁䭁䝁䅅䅁䭁䅁䅅䅁䭁䑁䅣䅁䉁䅁䅁允䅁䅁䅕場啯歲桦特䴸䅉䅅䅁䕁䅁䅁睁䵁䅁䅁权䝄䅁䅁权䉁䅁䅁权瑁䅁䅁允䅁䅁䅅䅁䙁䝁匸㡧䭄敯⽅䍄䉁䅁䅁䅂䅁䅁䅍䅄䅁䅁䅯䅣䅁䅁䅯允䅁䅁䅯兇䅁䅁䅅䅁䉁䅁䅁兂䭂䅄牉硨㕡睐杷允䅁䅁䅑䅁䑁䅁䅷䅁䭁䉁䅯䅁䭁䅁䅅䅁䭁䑁䅳䅁䉁䅁䅁允䅁䅁䅕歲桦桥畓㜹䴸䅉䅅䅁䕁䅁䅁睁䵁䅁䅁权ㅂ䅁䅁权䉁䅁䅁权湁䅁䅁允䅁䅁䅅䅁䙁偁周㘴扗乸⽁䍄䉁䅁䅁䅂䅁䅁䅍䅄䅁䅁䅯䅊䅅䅁䅯允䅁䅁䅯睉䅁䅁䅅䅁䉁䅁䅁兂硂児塲㍯剁䅑杷允䅁䅁䅑䅁䑁䅁䅷䅁䭁䵁䅯䅁䭁䅁䅅䅁䭁䍁䅁䅁䉁䅁䅁允䅁䅁䅕㡧䭄啯㉗啅䵁䅉䅅䅁䕁䅁䅁睁䵁䅁䅁权浄䅁䅁权䉁䅁䅁权䩂䅁䅁允䅁䅁䅅䅁䙁䡁啳歲桦来䅨䍄䉁䅁䅁䅂䅁䅁䅍䅄䅁䅁䅯儫䅁䅁䅯允䅁䅁䅯兄䅁䅁䅅䅁䉁䅁䅁兂瑁灳瘳㡰䱢睐杷允䅁䅁䅑䅁䑁䅁䅷䅁䭁䕁䅕䅁䭁䅁䅅䅁䭁䕁䅫䅁䉁䅁䅁允䅁䅁䅕㑈牘払敧吶䴸䅉䅅䅁䕁䅁䅁睁䵁䅁䅁权䭄䅁䅁权䉁䅁䅁权䭁䅁䅁允䅁䅁䅅䅁䙁䵁ㅐ䙋偹桷䅂䍄䉁䅁䅁䅂䅁䅁䅍䅄䅁䅁䅯兑䅁䅁䅯允䅁䅁䅯䅉䅁䅁䅅䅁䉁䅁䅁兂灁䥘䌯匹獪睐杷允䅁䅁䅑䅁䑁䅁䅷䅁䭁䥁䅁䅁䭁䅁䅅䅁䭁䍁䅍䅁䉁䅁䅁允䅁䅁䅯睁䅁䅁杷允䅁䅁䅑䅁䑁䅁䅷䅁䭁䡁䅅䅁䭁䅁䅅䅁䭁䉁䅍䅁䉁䅁䅁允䅁䅁䅕灭婭婭婭含䴸䅉䅅䅁䕁䅁䅁睁䵁䅁䅁权㑂䅁䅁权䉁䅁䅁权䡁䅁䅁允䅁䅁䅅䅁䙁䩁婱婭婭扭⽫䍄䉁䅁䅁䅂䅁䅁䅍䅄䅁䅁䅯䅐䅅䅁䅯允䅁䅁䅯杁䅁䅁䅅䅁䉁䅁䅁权䑁䅁䅁䍄䉁䅁䅁䅂䅁䅁䅍䅄䅁䅁䅯䅕䅁䅁䅯睘䅅䅁䅯䅑䅁䅁䅅䅁䉁䅁䅁䅆杂牪䅙䅁䅁䅁杷允䅁䅁䅑䅁䑁䅁䅷䅁䭁䱁䅫䅁䭁䅁䅅䅁䭁䅁䅣䅁䉁䅁䅁允䅁䅁䅕場啯歲桦橹䴸䅉䅅䅁䕁䅁䅁睁䵁䅁䅁权晃䅁䅁权䉁䅁䅁权䅂䅁䅁允䅁䅁䅅䅁䙁佁汏㡭村偳⽁䍄䉁䅁䅁䅂䅁䅁䅍䅄䅁䅁䅯杶䅁䅁䅯允䅁䅁䅯䅑䅁䅁䅅䅁䉁䅁䅁兂䙄䱉祂䩡案睐杷允䅁䅁䅑䅁䑁䅁䅷䅁䭁䝁䅅䅁䭁䅁䅅䅁䭁䅁䅯䅁䉁䅁䅁允䅁䅁䅕牕敧敨剴䑹䴸䅉䅅䅁䕁䅁䅁睁䵁䅁䅁权⽂䅁䅁权䉁䅁䅁权捁䅁䅁允䅁䅁䅅䅁䙁䭁捷浗㝑⬳⽳䍄䉁䅁䅁䅂䅁䅁䅍䅄䅁䅁䅯睩䅁䅁䅯允䅁䅁䅯睅䅁䅁䅅䅁䉁䅁䅁兂歃䑣䬰㘱免䅑杷允䅁䅁䅑䅁䑁䅁䅷䅁䭁䑁䉙䅁䭁䅁䅅䅁䭁䕁䅫䅁䉁䅁䅁允䅁䅁䅕㘱睎児塲稴䴸䅉䅅䅁䕁䅁䅁睁䵁䅁䅁权瑂䅁䅁权䉁䅁䅁权䙁䅁䅁允䅁䅁䅅䅁䙁䵁㉬灶愸㝌⼰䍄䉁䅁䅁䅂䅁䅁䅍䅄䅁䅁䅯杣䅁䅁䅯允䅁䅁䅯睎䅁䅁䅅䅁䉁䅁䅁兂卂䉵䘶砶ㅅ䅑杷允䅁䅁䅑䅁䑁䅁䅷䅁䭁䵁䅫䅁䭁䅁䅅䅁䭁䅁䄰䅁䉁䅁䅁允䅁䅁䅕䡶呓䅇坒䰸䴸䅉䅅䅁䕁䅁䅁睁䵁䅁䅁权癃䅁䅁权䉁䅁䅁权剁䅁䅁允䅁䅁䅅䅁䙁䍁捬㡪ㅌ䅋䅂䍄䉁䅁䅁䅂䅁䅁䅍䅄䅁䅁䅯䅆䅅䅁䅯允䅁䅁䅯睇䅁䅁䅅䅁䉁䅁䅁兂歃䑣䬰㘱䕍䅑杷允䅁䅁䅑䅁䑁䅁䅷䅁䭁䅁䅧䅁䭁䅁䅫䅁䭁䙁䄰䅁䉁䅁䅁允䅁䉁䅑䙅汗⼯⼯⼯䴸䅉䅅䅁䕁䅁䅁睁䵁䅁䅁权䱁䅁䅁权䩁䅁䅁权摂䅁䅁允䅁䅁䅅䅁啁䉁噂晰⼯⼯⼯䍄䉁䅁䅁䅂䅁䅁䅍䅄䅁䅁䅯䅳䅁䅁䅯允䅁䅁䅯䅉䅁䅁䅅䅁䉁䅁䅁兂汄䌰扌堫焷睐杷允䅁䅁䅑䅁䑁䅁䅷䅁䭁䙁䅁䅁䭁䙁䈸䅁䭁䍁䅍䅁䉁䅁䅁允䅁䉁䅑䄫䍐䅁䅁䅁䵁䅉䅅䅁䕁䅁䅁睁䵁䅁䅁权楂䅁䅁权䉁䅁䅁权潁䅁䅁允䅁䅁䅅䅁䙁䉁䘫ㄶ㑇瑈⽕䍄䉁䅁䅁䅂䅁䅁䅍䅄䅁䅁䅯克䅁䅁䅯允䅁䅁䅯杉䅁䅁䅅䅁䉁䅁䅁兂浂浚浚浚䵙䅑杷允䅁䅁䅑䅁䑁䅁䅷䅁䭁䩁䅑䅁䭁䅁䅅䅁䭁䍁䅧䅁䉁䅁䅁允䅁䅁䅕積積積積稫䴸䅉䅅䅁䕁䅁䅁睁䵁䅁䅁权偁允䅁权䉁䅁䅁权㝁䅁䅁允䅁䅁䅅䅁䙁偁⭰牡へ⭫⽑䍄䉁䅁䅁䅂䅁䅁䅍䅄䅁䅁䅯䅄䅁䅁䅯允䅁䅁䅯䅋䅁䅁䅅䅁䉁䅁䅁兂畃⭒㙆䭆㌷睐杷允䅁䅁䅑䅁䑁䅁䅷䅁䭁䡁䅑䅁䭁䅁䅅䅁䭁䍁䅧䅁䉁䅁䅁允䅁䅁䅕䉵䘶ㄶ㑇樳䴸䅉䅅䅁䕁䅁䅁睁䵁䅁䅁权䕂允䅁权䉁䅁䅁权婁䅁䅁允䅁䅁䅅䅁䙁䉁癳匳䝑执⽕䍄䉁䅁䅁䅂䅁䅁䅍䅄䅁䅁䅯儳䅁䅁䅯允䅁䅁䅯充䅁䅁䅅䅁䉁䅁䅁兂捂㡪ㅌ䙋空睐杷允䅁䅁䅑䅁䑁䅁䅷䅁䭁䙁䉳䅁䭁䅁䅅䅁䭁䉁䅕䅁䉁䅁䅁允䅁䅁䅕倹唳佥浫商䵁䅉䅅䅁䕁䅁䅁睁䵁䅁䅁权奁䅁䅁权䉁䅁䅁权剁䅁䅁允䅁䅁䅅䅁䙁偁潙䥘䌯儹䅒䍄䉁䅁䅁䅂䅁䅁䅍䅄䅁䅁䅯內䅁䅁䅯允䅁䅁䅯䅋䅁䅁䅅䅁䉁䅁䅁兂偃癷潕䥘匯睐杷允䅁䅁䅑䅁䑁䅁䅷䅁䭁䕁䄸䅁䭁䅁䅅䅁䭁䍁䅉䅁䉁䅁䅁允䅁䅁䅕䉵䘶ㄶ㑇歅䵁䅉䅅䅁䕁䅁䅁睁䵁䅁䅁权䑄䅁䅁权䉁䅁䅁权杁䅁䅁允䅁䅁䅅䅁䙁乁楅⼲⭬獡⽷䍄䉁䅁䅁䅂䅁䅁䅍䅄䅁䅁䅯眷䅁䅁䅯允䅁䅁䅯杉䅁䅁䅅䅁䉁䅁䅁兂偄ㄹ橐婰䕶睶杷允䅁䅁䅑䅁䑁䅁䅷䅁䭁䡁䅣䅁䭁䅁䅅䅁䭁䍁䄰䅁䉁䅁䅁允䅁䅁䅯睁䅁䅁杷允䅁䅁䅑䅁䑁䅁䅷䅁䭁䵁䅣䅁䭁䙁䈸䅁䭁䍁䅉䅁䉁䅁䅁允䅁䉁䅑偍桬允䅁䅁䵁䅉䅅䅁䕁䅁䅁睁䵁䅁䅁权摄䅁䅁权䉁䅁䅁权㍁䅁䅁允䅁䅁䅅䅁䙁䥁䅐煹䙆畴⼸䍄䉁䅁䅁䅂䅁䅁䅍䅄䅁䅁䅯兒䅁䅁䅯允䅁䅁䅯䅉䅁䅁䅅䅁䉁䅁䅁兂㉄䙋偹癷潘睐杷允䅁䅁䅑䅁䑁䅁䅷䅁䭁䭁䅳䅁䭁䅁䅅䅁䭁䉁䅫䅁䉁䅁䅁允䅁䅁䅕免獩䙈歰稲䴸䅉䅅䅁䕁䅁䅁睁䵁䅁䅁权呁允䅁权䉁䅁䅁权祁䅁䅁允䅁䅁䅅䅁䙁䩁畨潅䅐獹⽅䍄䉁䅁䅁䅂䅁䅁䅍䅄䅁䅁䅯杢䅁䅁䅯允䅁䅁䅯兆䅁䅁䅅䅁䉁䅁䅁兂乄䵺䵺䵺獺睐杷允䅁䅁䅑䅁䑁䅁䅷䅁䭁乁䅙䅁䭁䅁䅅䅁䭁䉁䅷䅁䉁䅁䅁允䅁䅁䅕牡へ硫䕧樷䴸䅉䅅䅁䕁䅁䅁睁䵁䅁䅁权瑂䅁䅁权䉁䅁䅁权噁䅁䅁允䅁䅁䅅䅁䙁䡁㥅瑃橥䱣⼰䍄䉁䅁䅁䅂䅁䅁䅍䅄䅁䅁䅯杢䅁䅁䅯允䅁䅁䅯睏䅁䅁䅅䅁䉁䅁䅁兂䕁杖琴灳䄰䅑杷允䅁䅁䅑䅁䑁䅁䅷䅁䭁䱁䅉䅁䭁䅁䅅䅁䭁䑁䅣䅁䉁䅁䅁允䅁䅁䅕㘱睎児塲稹䴸䅉䅅䅁䕁䅁䅁睁䵁䅁䅁权䅂允䅁权䉁䅁䅁权䙁䅁䅁允䅁䅁䅅䅁䙁䵁ㅐ䙋偹杷䄹䍄䉁䅁䅁䅂䅁䅁䅍䅄䅁䅁䅯睑䅅䅁䅯允䅁䅁䅯兆䅁䅁䅅䅁䉁䅁䅁兂歃䑣䬰㘱睐睐杷允䅁䅁䅑䅁䑁䅁䅷䅁䭁䡁䅫䅁䭁䅁䅅䅁䭁䉁䅍䅁䉁䅁䅁允䅁䅁䅕㥏倹婪畤樰䴸䅉䅅䅁䕁䅁䅁睁䵁䅁䅁权佃䅁䅁权䉁䅁䅁权楁䅁䅁允䅁䅁䅅䅁䙁䙁偹癷潕䉘䄹䍄䉁䅁䅁䅂䅁䅁䅍䅄䅁䅁䅯睲䅁䅁䅯允䅁
