Workbook
Name IQ_CH: 110000
Name IQ_CQ: 5000
Name IQ_CY: 10000
Name IQ_DAILY: 500000
Name IQ_FH: 100000
Name IQ_FQ: 500
Name IQ_FY: 1000
Name IQ_LTM: 2000
Name IQ_MONTH: 15000
Name IQ_NTM: 6000
Name IQ_WEEK: 50000
Name IQ_YTD: 3000

Sheet __snloffice
A1: 允䅁䑁䅯䅁䍁䅁䅁䅁䡁䅁䅁䅕䅁䍁䅣睗求䍁䄴杚ㅂ䝁䄴䅚桂䝁䄰党畂䡁䅑兙獂䍁䄴䅥獂䡁䅍䅥摂䑁䅫兌歂䝁䅫兢瑁䙁䅍睙療䡁䅉党穂䍁䅣光歁䕁䅅䅊硁䅁䅁䅎䅁䝁䅁䅁湁䙁䅳党畁䝁䅙兤畂䝁䅑兙瑂䝁䅕杢あ䝁䅅䅢畁䡁䅧䅢穂䡁䅧兘㕁䍁䄰䅚灂䝁䄰兌呂䝁䅍睢祂䝁䅕督湁䍁䅅䅊䍂䍁䅑李㙁䍁䅑村歁䑁䅑䅎㉁䑁䅅䅁ㅁ䅁䅁䅘䅁䍁䅣睗求䍁䄴杚ㅂ䝁䄴䅚桂䝁䄰党畂䡁䅑兙獂䍁䄴䅥獂䡁䅍䅥摂䑁䅫兌歂䝁䅫兢瑁䙁䅍睙療䡁䅉党穂䍁䅣光歁䕁䅍䅊穁䑁䅯䅊䉂䕁䅑䅊穁䅁䅁李䅁䕁䅷䅁湁䙁䅳杚ㅂ䝁䄴䅚桂䝁䄰党畂䡁䅑兙獂䍁䄴䅥獂䡁䅍䅥摂䑁䅫兌歂䝁䅫兢瑁䙁䅍睙療䡁䅉党穂䍁䅣光歁䕁䅅䅊硁䅁䅁睎䅁䙁䅷䅁湁䙁䅳杚ㅂ䝁䄴䅚桂䝁䄰党畂䡁䅑兙獂䍁䄴䅥獂䡁䅍䅥摂䑁䅫兌歂䝁䅫兢瑁䙁䅍睙療䡁䅉党穂䍁䅣光歁䕁䅉䅊㉁䑁䅯䅊䍂䍁䅑䅎ぁ䑁䅙免䅁䑁䅧䅁奂䅁䅁睊扂䝁䅙兤畂䝁䅑兙瑂䝁䅕杢あ䝁䅅䅢畁䡁䅧䅢穂䡁䅧兘㕁䍁䄰䅚灂䝁䄰兌呂䝁䅍睢祂䝁䅕督湁䍁䅅䅊䑂䍁䅑睍㙁䍁䅑兑䕂䍁䅑睍䅁䑁䅫䅁啁䅁䅁䅐⭁䕁䅍兤祂䡁䅉党畂䡁䅑䅁䕁䅁䅁䅆䅁䑁䅷材兂䡁䅉兡瑂䝁䅅杣㕂䅁䅁允䅁䍁䅷䅁䑂䝁䅅督潂䍁䅁杚祂䝁䄸兢杁䕁䄸䅣穂䍁䄴䅉潁䍁䅑䅍睁䑁䅁克䅁䍁䅳䅁䝂䅁䅁睑療䝁䄰兢療䝁䄴䅉呂䝁䅧兙祂䝁䅕督杁䕁䄸兤あ䡁䅍䅤桂䝁䄴䅚灂䝁䄴睚杁䍁䅧兙橂䡁䅑兤桂䝁䅷克䅁䉁䅷䅁允䅁䅁睑ㅂ䡁䅉杣求䝁䄴䅤䅁䅁䅕䅁潁䅁䅁䅒桂䡁䅫䅉䑂䝁䅷睢穂䝁䅕䅉兂䡁䅉兡橂䝁䅕䅉潁䍁䅑克䅁䉁䅯䅁奁䅁䅁兒䍂䕁䅫䅖杁䍁䅧䅊睁䑁䅁䅍灁䅁䅁克䅁䉁䅷䅁䙂䕁䅉兓啂䕁䅑兑杁䍁䅧䅊睁䑁䅁䅍灁䅁䅁睊䅁䉁䅙䅁䙂䝁䄴䅤灂䡁䅑入杁䕁䅫䅒杁䅁䅁睆䅁䉁䅯䅁䙂䝁䄴䅤灂䡁䅑入杁䕁䄴兙瑂䝁䅕䅉䅁䅁䅫䅁啁䅁䅁兒㑂䝁䅍䅡桂䝁䄴睚求䍁䅁䅁呁䅁䅁杇䅁䕁䅫兕時䕁䅍兑呂䕁䅧睘偂䙁䅁兒卂䅁䅁杋䅁䉁䅧䅁䩂䙁䅅睘䩂䕁䄴䅒噂䙁䅍䅖卂䙁䅫䅁桁䅁䅁䅊䅁䕁䅫兕時䕁䅫杔䕂䙁䅕睕啂䙁䅉兗時䕁䅣杕偂䙁䅕䅕䅁䉁䄸䅁敁䅁䅁兓剂䙁䄸䅔啂䙁䄸䅒䙂䕁䅉䅖時䕁䅉杔䱂䅁䅁兄䅁䍁䅧䅁䩂䙁䅅睘兂䙁䅉兓乂䕁䅅杕婂䙁䄸兓佂䕁䅑兖呂䙁䅑杕婂䅁䅁䅆䅁䉁䅑䅁䩂䙁䅅睘呂䕁䅕睑啂䕁䄸杕䅁䉁䄰䅁啁䅁䅁兓畂䝁䅑兤穂䡁䅑杣㕂䍁䅁䅁楁䅁䅁䅉䅁䕁䅫杢歂䡁䅕督あ䡁䅉入杁䕁䅣杣療䡁䅕䅣杁䅁䅁䅉䅁䅁䅧䅁䵂䙁䅑兔䅁䅁䅳䅁䵁䅁䅁䅔啂䕁䄰兌硁䅁䅁杄䅁䍁䅷䅁䵂䝁䄸杢湂䍁䄰䅖求䡁䅉兢杁䕁䅑党楂䡁䅑䅉潁䍁䅑䅍睁䑁䅁克䅁䅁䄸䅁㉁䅁䅁兔桂䡁䅉睡求䡁䅑䅉䑂䝁䅅䅣灂䡁䅑兙獂䝁䅫来桂䡁䅑兡療䝁䄴䅉潁䍁䅑兔灁䅁䅁兇䅁䉁䅧䅁佂䕁䅅兓䑂䙁䅍䅉䑂䝁䄸䅚求䍁䅁䅁橁䅁䅁杆䅁䕁䄴兑䩂䕁䅍睕時䕁䅍睔䕂䕁䅕䅁䅁䅁䅁䅊䅁䕁䄴党あ䍁䅁兓畂䝁䅍睢瑂䝁䅕䅉潁䍁䅑䅍睁䑁䅁克䅁䍁䅕䅁䵃䅁䅁睔睂䡁䅑兡療䝁䄴督㙁䕁䅍兤祂䡁䅉児噂䙁䅍䅒獁䕁䄰兙湂䑁䄰睕あ䝁䅅杢歂䝁䅅杣歂䍁䅷睑療䝁䄴杤乂䝁䅕䅤潂䝁䄸䅚㥁䙁䅉䅌䝂䝁䅫䅢灂䝁䄴睚坂䝁䅕杣㥁䕁䅍兤祂䡁䅉党畂䡁䅑睌卂䝁䅕督あ䝁䅅䅤求䝁䅑䅁䥁䅁䅁䅅䅁䙁䅁杣灂䝁䄰兙祂䡁䅫䅁䍁䅁䅁䅊䅁䙁䅁杣灂䝁䄰兙祂䡁䅫䅉䩂䝁䄴䅚ㅂ䡁䅍䅤祂䡁䅫䅉䅁䉁䅕䅁十䅁䅁睕兂䕁䅣䅖桂䝁䅉䅢求䅁䅁睍䅁䍁䅑䅁呂䙁䅁睘䑂䙁䅕杕卂䕁䅕杔啂䙁䄸兑呂䙁䅍兒啂䙁䅍䅁畁䅁䅁䅉䅁䙁䅍䅕時䕁䅍兖卂䙁䅉兒佂䙁䅑睘䵂䕁䅫兑䍂䅁䅁䅅䅁䉁䅁䅁呂䙁䅁睘䙂䕁䅉兓啂䅁䅁䅋䅁䉁䅑䅁呂䙁䅁睘䙂䕁䅉兓啂䕁䅑兑䅁䍁䅙䅁慁䅁䅁睕兂䙁䄸兒佂䙁䅑兓啂䙁䅫睘䩂䕁䅑䅁坁䅁䅁杈䅁䙁䅍䅕時䕁䅕杔啂䕁䅫䅖婂䙁䄸杔䉂䕁䄰兒䅁䅁䅙䅁奁䅁䅁睕兂䙁䄸兒奂䕁䅍䅓䉂䕁䄴睒䙂䅁䅁杅䅁䉁䅯䅁呂䙁䅁睘乂䕁䅅杕䱂䕁䅕䅖䑂䕁䅅䅕䅁䉁䅧䅁坁䅁䅁睕兂䙁䄸杔䙂䙁䅑睘䩂䕁䄴睑䅁䍁䅑䅁敁䅁䅁睕兂䙁䄸䅕卂䕁䅫睑䙂䙁䄸睑䵂䕁䄸睕䙂䅁䅁睁䅁䑁䅉䅁呂䙁䅁睘呂䕁䅧兑卂䕁䅕睕時䕁䄸兖啂䙁䄸䅕䙂䙁䅉兓偂䕁䅑睘䙂䕁䄴䅒䅁䉁䅳䅁杁䅁䅁睕兂䙁䄸䅖偂䙁䅑兑䵂䙁䄸兑呂䙁䅍兒啂䙁䅍䅁獁䅁䅁杇䅁䙁䅍䅕時䙁䅑睔啂䕁䅅䅔時䙁䅉兒坂䅁䅁权䅁䉁䅁䅁呂䝁䅕睙あ䝁䄸杣杁䅁䅁杈䅁䍁䅧䅁啂䝁䄸䅤桂䝁䅷䅉䉂䡁䅍督求䡁䅑督杁䍁䅧䅊睁䑁䅁䅍灁䅁䅁兌䅁䑁䅧䅁啂䝁䄸䅤桂䝁䅷䅉䑂䡁䅕杣祂䝁䅕杢あ䍁䅁兑穂䡁䅍党あ䡁䅍䅉潁䍁䅑䅍睁䑁䅁克䅁䍁䄸䅁䍂䅁䅁䅖療䡁䅑兙獂䍁䅁睑ㅂ䡁䅉杣求䝁䄴䅤杁䕁䅷兡桂䝁䅉兡獂䝁䅫䅤灂䝁䅕督杁䍁䅧䅊睁䑁䅁䅍灁䅁䅁充䅁䍁䅯䅁啂䝁䄸䅤桂䝁䅷䅉卂䝁䅕杤求䝁䄴兤求䍁䅁䅋歁䑁䅁䅍睁䍁䅫䅁䵁䅁䅁䅑䅁䙁䅳党畁䝁䅙兤畂䝁䅑兙瑂䝁䅕杢あ䝁䅅䅢畁䡁䅧䅢穂䡁䅧兘呂䝁䅧党求䡁䅑杍桁䍁䅑兑歁䑁䅅䅁睁䅁䅁䅕䅁䙁䅳党畁䝁䅙兤畂䝁䅑兙瑂䝁䅕杢あ䝁䅅䅢畁䡁䅧䅢穂䡁䅧兘呂䝁䅧党求䡁䅑杍桁䍁䅑村歁䑁䅙杏歁䕁䅉䅊ぁ䑁䅑李硁䅁䅁免䅁䕁䅷䅁扂䝁䅕杌浂䡁䅕杢歂䝁䅅兢求䝁䄴䅤桂䝁䅷杌㑂䝁䅷督㑂䙁䄰睕潂䝁䅕党あ䑁䅉光歁䕁䅍䅊穁䑁䅯䅊䉂䕁䅑䅊穁䅁䅁杍䅁䍁䅅䅁䵁䅉䅅䅁䕁䅁䅁睁偁䅁䅁兂䅁䅁䅁䕎兙兑䅯䅁䅁䅁䅯允䅁䅁䅅䅁䉁䅁䅁权䍁䅁䅁䍄䉁䅁䅁䅂䅁䅁䅍睄䅁䅁䅕䅁䅁䑁䝒䕅䭅䅁䅍䅁䭁䅁䅑䅁䉁䅁䅁允䅁䅁䅯兂䅁䅁杷允䅁䅁䅙䅁䑁䅁䄸䅁䙁䅁䅁䅁ぁ桒䉂权潁䅁䅁权䱁䅁䅁权䡁䅁䅁权䥁䅁䅁允䅁䅁䅅䅁䭁䍁䅫䅁䵁䅉䅅䅁䝁䅁䅁睁偁䅁䅁兂䅁䅁䅁䕎兙兑䅯权䅁䅁䅯睃䅁䅁䅯睂䅁䅁䅯䅃䅁䅁䅅䅁䉁䅁䅁权䵁䅁䅁䍄䉁䅁䅁杂䅁䅁䅍睄䅁䅁䅕䅁䅁䑁䝒䕅䭅䅁䅙䅁䭁䅁䅣䅁䭁䅁䅣䅁䭁䅁䅧䅁䉁䅁䅁允䅁䅁䅯元䅁䅁杷允䅁䅁䅙䅁䑁䅁䄸䅁䙁䅁䅁䅁ぁ桒䉂权乁䅁䅁权佁䅁䅁权䡁䅁䅁权䥁䅁䅁允䅁䅁䅅䅁䭁䅁䄸䅁䵁䅉䅅䅁䝁䅁䅁睁偁䅁䅁兂䅁䅁䅁䕎兙兑䅯䅊䅁䅁䅯杄䅁䅁䅯睂䅁䅁䅯䅃䅁䅁䅅䅁䉁䅁䅁权汁䅁䅁䍄䉁䅁䅁杂䅁䅁䅍睄䅁䅁䅕䅁䅁䑁䝒䕅䭅䉁䅁䅁䭁䅁䄴䅁䭁䅁䅣䅁䭁䅁䅧䅁䉁䅁䅁允䅁䅁䅯充䅁䅁杷允䅁䅁䅙䅁䑁䅁䄸䅁䙁䅁䅁䅁ぁ桒䉂权十䅁䅁权䡁䅁䅁权䡁䅁䅁权䥁䅁䅁允䅁䅁䅅䅁䭁䉁䅍䅁䵁䅉䅅䅁䝁䅁䅁睁偁䅁䅁兂䅁䅁䅁䕎兙兑䅯䅆䅁䅁䅯睂䅁䅁䅯睂䅁䅁䅯䅃䅁䅁䅅䅁䉁䅁䅁权噁䅁䅁䍄䉁䅁䅁杂䅁䅁䅍睄䅁䅁䅕䅁䅁䑁䝒䕅䭅䉁䅙䅁䭁䅁䅣䅁䭁䅁䅣䅁䭁䅁䅧䅁䉁䅁䅁允䅁䅁䅯睆䅁䅁杷允䅁䅁䅙䅁䑁䅁䄸䅁䙁䅁䅁䅁ぁ桒䉂权奁䅁䅁权䡁䅁䅁权䡁䅁䅁权䥁䅁䅁允䅁䅁䅅䅁䭁䉁䅫䅁䵁䅉䅅䅁䝁䅁䅁睁偁䅁䅁兂䅁䅁䅁䕎兙兑䅯睁䅁䅁䅯兂䅁䅁䅯睂䅁䅁䅯䅃䅁䅁䅅䅁䉁䅁䅁权慁䅁䅁䍄䉁䅁䅁杂䅁䅁䅍睄䅁䅁䅕䅁䅁䑁䝒䕅䭅䍁䄴䅁䭁䅁䅳䅁䭁䅁䅣䅁䭁䅁䅧䅁䉁䅁䅁允䅁䅁䅯睌䅁䅁杷允䅁䅁䅙䅁䑁䅁䄸䅁䙁䅁䅁䅁ぁ桒䉂权扁䅁䅁权佁䅁䅁权䡁䅁䅁权䥁䅁䅁允䅁䅁䅅䅁䭁䉁䅷䅁䵁䅉䅅䅁䝁䅁䅁睁偁䅁䅁兂䅁䅁䅁䕎兙兑䅯先䅁䅁䅯睂䅁䅁䅯睂䅁䅁䅯䅃䅁䅁䅅䅁䉁䅁䅁权敁䅁䅁䍄䉁䅁䅁杂䅁䅁䅍睄䅁䅁䅕䅁䅁䑁䝒䕅䭅䉁䄸䅁䭁䅁䅣䅁䭁䅁䅣䅁䭁䅁䅧䅁䉁䅁䅁允䅁䅁䅯䅉䅁䅁杷允䅁䅁䅙䅁䑁䅁䄸䅁䙁䅁䅁䅁ぁ桒䉂权桁䅁䅁权䡁䅁䅁权䡁䅁䅁权䥁䅁䅁允䅁䅁䅅䅁䭁䍁䅉䅁䵁䅉䅅䅁䝁䅁䅁睁偁䅁䅁兂䅁䅁䅁䕎兙兑䅯杋䅁䅁䅯杄䅁䅁䅯睂䅁䅁䅯䅃䅁䅁䅅䅁䉁䅁䅁权牁䅁䅁䍄䉁䅁䅁杂䅁䅁䅍睄䅁䅁䅕䅁䅁䑁䝒䕅䭅䉁䅳䅁䭁䅁䅳䅁䭁䅁䅣䅁䭁䅁䅧䅁䉁䅁䅁允䅁䅁䅯䅈䅁䅁杷允䅁䅁䅙䅁䑁䅁䄸䅁䙁䅁䅁䅁ぁ桒䉂权䅁䅁䅁权䍁䅁䅁权䡁䅁䅁权䥁䅁䅁允䅁䅁䅅䅁䭁䍁䅍䅁䵁䅉䅅䅁䝁䅁䅁睁偁䅁䅁兂䅁䅁䅁䕎兙兑䅯杊䅁䅁䅯杄䅁䅁䅯睂䅁䅁䅯䅃䅁䅁䅅䅁䉁䅁䅁权湁䅁䅁䍄䉁䅁䅁杂䅁䅁䅍睄䅁䅁䅕䅁䅁䑁䝒䕅䭅䍁䅑䅁䭁䅁䅳䅁䭁䅁䅣䅁䭁䅁䅧䅁䉁䅁䅁允䅁䅁䅯兊䅁䅁杷允䅁䅁䅙䅁䑁䅁䄸䅁䙁䅁䅁䅁ぁ桒䉂权䭁䅁䅁权佁䅁䅁权䡁䅁䅁权䥁䅁䅁允䅁䅁䅅䅁䭁䅁䅷䅁䵁䅉䅅䅁䝁䅁䅁睁偁䅁䅁兂䅁䅁䅁䕎兙兑䅯杋䅁䅁䅯睃䅁䅁䅯睂䅁䅁䅯䅃䅁䅁䅅䅁䉁䅁䅁权牁䅁䅁䍄䉁䅁䅁杂䅁䅁䅍睄䅁䅁䅕䅁䅁䑁䝒䕅䭅䍁䅙䅁䭁䅁䅳䅁䭁䅁䅣䅁䭁䅁䅧䅁䉁䅁䅁允䅁䅁䅯睊䅁䅁杷允䅁䅁䅙䅁䑁䅁䄸䅁䙁䅁䅁䅁ぁ桒䉂权潁䅁䅁权佁䅁䅁权䡁䅁䅁权䥁䅁䅁允䅁䅁䅅䅁䭁䍁䅫䅁䵁䅉䅅䅁䝁䅁䅁睁偁䅁䅁兂䅁䅁䅁䕎兙兑䅯兄䅁䅁䅯睃䅁䅁䅯睂䅁䅁䅯䅃䅁䅁䅅䅁䉁䅁䅁权偁䅁䅁䍄䉁䅁䅁杂䅁䅁䅍睄䅁䅁䅕䅁䅁䑁䝒䕅䭅䍁䅷䅁䭁䅁䅳䅁䭁䅁䅣䅁䭁䅁䅧䅁䉁䅁䅁允䅁䅁䅯兌䅁䅁杷允䅁䅁䅙䅁䑁䅁䄸䅁䙁䅁䅁䅁ぁ桒䉂权獁䅁䅁权佁䅁䅁权䡁䅁䅁权䥁䅁䅁允䅁䅁䅅䅁䭁䍁䄰䅁䵁䅉䅅䅁䝁䅁䅁睁偁䅁䅁兂䅁䅁䅁䕎兙兑䅯杌䅁䅁䅯杄䅁䅁䅯睂䅁䅁䅯䅃䅁䅁䅅䅁䉁䅁䅁权癁䅁䅁䍄䉁䅁䅁杂䅁䅁䅍睄䅁䅁䅕䅁䅁䑁䝒䕅䭅䉁䅁䅁䭁䅁䅳䅁䭁䅁䅣䅁䭁䅁䅧䅁䉁䅁䅁允䅁䅁䅯充䅁䅁杷允䅁䅁䅧䅁䵁䅉䅅䅁䙁䅁䅁权㍁䅁䅁权㑁䅁䅁权㕁䅁䅁权䕁䅁䅋权䥁䅁䅁䅆扂硦橃塳䘴剄䅑噐塂兮䥶㍌啕䑁瘶䥐桌橶䝊䅆ぁ䌴剘儸䵉硫䅑䙚奥㍒䭦煋唰䩁婢⬵䄷牥丫䅆歂㕖䡨㡤煯兲䅅䅁䉁䅁䅁权穁䅁䅁

Sheet Score
A1: Net Income > 0 | B1: Cash flow from Op > 0 | C1: Delta RoA > 0 | D1: CFO > Net Income | E1: Delta LT Debt / Asset < 0 | F1: Delta C Asset / Liability > 0 | G1: Delta EBIT Margin > 0 | H1: Delta Rev / Asset > 0 | I1: Delta O/S shares < 0
L2: Net Income > 0 | M2: Cash flow from Op > 0 | N2: Delta RoA > 0 | O2: CFO > Net Income | P2: Delta LT Debt / Asset < 0 | Q2: Delta C Asset / Liability > 0 | R2: Delta EBIT Margin > 0 | S2: Delta Rev / Asset > 0 | T2: Delta O/S shares < 0 | U2: Sum
A5: {=_xlfn._xlws.FILTER('9-dim-Scores'!A:A,'9-dim-Scores'!AP:AP=1, "")} -> 1st Source Corporation (NASDAQGS:SRCE) | B5: {=_xlfn._xlws.FILTER('9-dim-Scores'!A:A,'9-dim-Scores'!AQ:AQ=1, "")} -> 10x Genomics, Inc. (NASDAQGS:TXG) | C5: {=_xlfn._xlws.FILTER('9-dim-Scores'!A:A,'9-dim-Scores'!AR:AR=1, "")} -> 10x Genomics, Inc. (NASDAQGS:TXG) | D5: {=_xlfn._xlws.FILTER('9-dim-Scores'!A:A,'9-dim-Scores'!AS:AS=1, "")} -> 10x Genomics, Inc. (NASDAQGS:TXG) | E5: {=_xlfn._xlws.FILTER('9-dim-Scores'!A:A,'9-dim-Scores'!AT:AT=1, "")} -> 1-800-FLOWERS.COM, Inc. (NASDAQGS:FLWS) | F5: {=_xlfn._xlws.FILTER('9-dim-Scores'!A:A,'9-dim-Scores'!AU:AU=1, "")} -> 3M Company (NYSE:MMM) | G5: {=_xlfn._xlws.FILTER('9-dim-Scores'!A:A,'9-dim-Scores'!AV:AV=1, "")} -> 10x Genomics, Inc. (NASDAQGS:TXG) | H5: {=_xlfn._xlws.FILTER('9-dim-Scores'!A:A,'9-dim-Scores'!AW:AW=1, "")} -> 1895 Bancorp of Wisconsin, Inc. (NASDAQCM:BCOW) | I5: {=_xlfn._xlws.FILTER('9-dim-Scores'!A:A,'9-dim-Scores'!AX:AX=1, "")} -> 1-800-FLOWERS.COM, Inc. (NASDAQGS:FLWS) | K5: Target
A6: 3M Company (NYSE:MMM) | B6: 1-800-FLOWERS.COM, Inc. (NASDAQGS:FLWS) | C6: 1895 Bancorp of Wisconsin, Inc. (NASDAQCM:BCOW) | D6: 1-800-FLOWERS.COM, Inc. (NASDAQGS:FLWS) | E6: A. O. Smith Corporation (NYSE:AOS) | F6: a.k.a. Brands Holding Corp. (NYSE:AKA) | G6: 1895 Bancorp of Wisconsin, Inc. (NASDAQCM:BCOW) | H6: 1st Source Corporation (NASDAQGS:SRCE) | I6: 1895 Bancorp of Wisconsin, Inc. (NASDAQCM:BCOW) | K6: Carvana Co. (NYSE:CVNA) | L6: =IF(COUNTIF(A:A,$K6)>0,1,0) -> 1 | M6: =IF(COUNTIF(B:B,$K6)>0,1,0) -> 1 | N6: =IF(COUNTIF(C:C,$K6)>0,1,0) -> 0 | O6: =IF(COUNTIF(D:D,$K6)>0,1,0) -> 1 | P6: =IF(COUNTIF(E:E,$K6)>0,1,0) -> 1 | Q6: =IF(COUNTIF(F:F,$K6)>0,1,0) -> 1 | R6: =IF(COUNTIF(G:G,$K6)>0,1,0) -> 1 | S6: =IF(COUNTIF(H:H,$K6)>0,1,0) -> 1 | T6: =IF(COUNTIF(I:I,$K6)>0,1,0) -> 0 | U6: =SUM(L6:T6) -> 7 | X6: sum
A7: A. O. Smith Corporation (NYSE:AOS) | B7: 1st Source Corporation (NASDAQGS:SRCE) | C7: 1st Source Corporation (NASDAQGS:SRCE) | D7: 1895 Bancorp of Wisconsin, Inc. (NASDAQCM:BCOW) | E7: A2Z Cust2Mate Solutions Corp. (NASDAQCM:AZ) | F7: A2Z Cust2Mate Solutions Corp. (NASDAQCM:AZ) | G7: 1st Source Corporation (NASDAQGS:SRCE) | H7: 3M Company (NYSE:MMM) | I7: 3M Company (NYSE:MMM) | K7: MicroStrategy Incorporated (NASDAQGS:MSTR) | L7: =IF(COUNTIF(A:A,$K7)>0,1,0) -> 0 | M7: =IF(COUNTIF(B:B,$K7)>0,1,0) -> 0 | N7: =IF(COUNTIF(C:C,$K7)>0,1,0) -> 0 | O7: =IF(COUNTIF(D:D,$K7)>0,1,0) -> 1 | P7: =IF(COUNTIF(E:E,$K7)>0,1,0) -> 1 | Q7: =IF(COUNTIF(F:F,$K7)>0,1,0) -> 1 | R7: =IF(COUNTIF(G:G,$K7)>0,1,0) -> 0 | S7: =IF(COUNTIF(H:H,$K7)>0,1,0) -> 0 | T7: =IF(COUNTIF(I:I,$K7)>0,1,0) -> 0 | U7: =SUM(L7:T7) -> 3
A8: A10 Networks, Inc. (NYSE:ATEN) | B8: 3M Company (NYSE:MMM) | C8: 3M Company (NYSE:MMM) | D8: 1st Source Corporation (NASDAQGS:SRCE) | E8: AAON, Inc. (NASDAQGS:AAON) | F8: AAON, Inc. (NASDAQGS:AAON) | G8: 3M Company (NYSE:MMM) | H8: A. O. Smith Corporation (NYSE:AOS) | I8: 5:01 Acquisition Corp. (NASDAQCM:FVAM) | K8: Lumen Technologies, Inc. (NYSE:LUMN) | L8: =IF(COUNTIF(A:A,$K8)>0,1,0) -> 0 | M8: =IF(COUNTIF(B:B,$K8)>0,1,0) -> 1 | N8: =IF(COUNTIF(C:C,$K8)>0,1,0) -> 0 | O8: =IF(COUNTIF(D:D,$K8)>0,1,0) -> 1 | P8: =IF(COUNTIF(E:E,$K8)>0,1,0) -> 1 | Q8: =IF(COUNTIF(F:F,$K8)>0,1,0) -> 1 | R8: =IF(COUNTIF(G:G,$K8)>0,1,0) -> 0 | S8: =IF(COUNTIF(H:H,$K8)>0,1,0) -> 0 | T8: =IF(COUNTIF(I:I,$K8)>0,1,0) -> 1 | U8: =SUM(L8:T8) -> 5 | X8: Mean | Y8: 3.9840664
A9: AAON, Inc. (NASDAQGS:AAON) | B9: A. O. Smith Corporation (NYSE:AOS) | C9: a.k.a. Brands Holding Corp. (NYSE:AKA) | D9: 4D Molecular Therapeutics, Inc. (NASDAQGS:FDMT) | E9: AAR Corp. (NYSE:AIR) | F9: Abrdn Life Sciences Investors (NYSE:HQL) | G9: a.k.a. Brands Holding Corp. (NYSE:AKA) | H9: A10 Networks, Inc. (NYSE:ATEN) | I9: A. O. Smith Corporation (NYSE:AOS) | K9: Vistra Corp. (NYSE:VST) | L9: =IF(COUNTIF(A:A,$K9)>0,1,0) -> 1 | M9: =IF(COUNTIF(B:B,$K9)>0,1,0) -> 1 | N9: =IF(COUNTIF(C:C,$K9)>0,1,0) -> 1 | O9: =IF(COUNTIF(D:D,$K9)>0,1,0) -> 1 | P9: =IF(COUNTIF(E:E,$K9)>0,1,0) -> 0 | Q9: =IF(COUNTIF(F:F,$K9)>0,1,0) -> 1 | R9: =IF(COUNTIF(G:G,$K9)>0,1,0) -> 1 | S9: =IF(COUNTIF(H:H,$K9)>0,1,0) -> 1 | T9: =IF(COUNTIF(I:I,$K9)>0,1,0) -> 1 | U9: =SUM(L9:T9) -> 8 | X9: Standard Error | Y9: 0.037791523
A10: AAR Corp. (NYSE:AIR) | B10: a.k.a. Brands Holding Corp. (NYSE:AKA) | C10: A10 Networks, Inc. (NYSE:ATEN) | D10: 5:01 Acquisition Corp. (NASDAQCM:FVAM) | E10: Abbott Laboratories (NYSE:ABT) | F10: ACADIA Pharmaceuticals Inc. (NASDAQGS:ACAD) | G10: A10 Networks, Inc. (NYSE:ATEN) | H10: AAR Corp. (NYSE:AIR) | I10: A10 Networks, Inc. (NYSE:ATEN) | K10: IES Holdings, Inc. (NASDAQGM:IESC) | L10: =IF(COUNTIF(A:A,$K10)>0,1,0) -> 1 | M10: =IF(COUNTIF(B:B,$K10)>0,1,0) -> 1 | N10: =IF(COUNTIF(C:C,$K10)>0,1,0) -> 1 | O10: =IF(COUNTIF(D:D,$K10)>0,1,0) -> 1 | P10: =IF(COUNTIF(E:E,$K10)>0,1,0) -> 0 | Q10: =IF(COUNTIF(F:F,$K10)>0,1,0) -> 1 | R10: =IF(COUNTIF(G:G,$K10)>0,1,0) -> 1 | S10: =IF(COUNTIF(H:H,$K10)>0,1,0) -> 0 | T10: =IF(COUNTIF(I:I,$K10)>0,1,0) -> 1 | U10: =SUM(L10:T10) -> 7 | X10: Median | Y10: 4
A11: Abbott Laboratories (NYSE:ABT) | B11: A10 Networks, Inc. (NYSE:ATEN) | C11: A2Z Cust2Mate Solutions Corp. (NASDAQCM:AZ) | D11: 89bio, Inc. (NASDAQGM:ETNB) | E11: AbbVie Inc. (NYSE:ABBV) | F11: Accenture plc (NYSE:ACN) | G11: A2Z Cust2Mate Solutions Corp. (NASDAQCM:AZ) | H11: Abacus Life, Inc. (NASDAQCM:ABL) | I11: Abbott Laboratories (NYSE:ABT) | K11: FTAI Aviation Ltd. (NASDAQGS:FTAI) | L11: =IF(COUNTIF(A:A,$K11)>0,1,0) -> 1 | M11: =IF(COUNTIF(B:B,$K11)>0,1,0) -> 0 | N11: =IF(COUNTIF(C:C,$K11)>0,1,0) -> 1 | O11: =IF(COUNTIF(D:D,$K11)>0,1,0) -> 0 | P11: =IF(COUNTIF(E:E,$K11)>0,1,0) -> 1 | Q11: =IF(COUNTIF(F:F,$K11)>0,1,0) -> 0 | R11: =IF(COUNTIF(G:G,$K11)>0,1,0) -> 1 | S11: =IF(COUNTIF(H:H,$K11)>0,1,0) -> 1 | T11: =IF(COUNTIF(I:I,$K11)>0,1,0) -> 0 | U11: =SUM(L11:T11) -> 5 | X11: Mode | Y11: 0
A12: AbbVie Inc. (NYSE:ABBV) | B12: AAON, Inc. (NASDAQGS:AAON) | C12: AAON, Inc. (NASDAQGS:AAON) | D12: A. O. Smith Corporation (NYSE:AOS) | E12: Abeona Therapeutics Inc. (NASDAQCM:ABEO) | F12: ACI Worldwide, Inc. (NASDAQGS:ACIW) | G12: Abacus Life, Inc. (NASDAQCM:ABL) | H12: Abrdn Global Dynamic Dividend Fund (NYSE:AGD) | I12: Abercrombie & Fitch Co. (NYSE:ANF) | K12: Sprouts Farmers Market, Inc. (NASDAQGS:SFM) | L12: =IF(COUNTIF(A:A,$K12)>0,1,0) -> 1 | M12: =IF(COUNTIF(B:B,$K12)>0,1,0) -> 1 | N12: =IF(COUNTIF(C:C,$K12)>0,1,0) -> 1 | O12: =IF(COUNTIF(D:D,$K12)>0,1,0) -> 1 | P12: =IF(COUNTIF(E:E,$K12)>0,1,0) -> 0 | Q12: =IF(COUNTIF(F:F,$K12)>0,1,0) -> 1 | R12: =IF(COUNTIF(G:G,$K12)>0,1,0) -> 1 | S12: =IF(COUNTIF(H:H,$K12)>0,1,0) -> 0 | T12: =IF(COUNTIF(I:I,$K12)>0,1,0) -> 1 | U12: =SUM(L12:T12) -> 7 | X12: Standard Deviation | Y12: 2.522708
A13: Abercrombie & Fitch Co. (NYSE:ANF) | B13: AAR Corp. (NYSE:AIR) | C13: Abbott Laboratories (NYSE:ABT) | D13: a.k.a. Brands Holding Corp. (NYSE:AKA) | E13: ABM Industries Incorporated (NYSE:ABM) | F13: ACM Research, Inc. (NASDAQGM:ACMR) | G13: Abbott Laboratories (NYSE:ABT) | H13: Abrdn Healthcare Investors (NYSE:HQH) | I13: ABM Industries Incorporated (NYSE:ABM) | K13: Brinker International, Inc. (NYSE:EAT) | L13: =IF(COUNTIF(A:A,$K13)>0,1,0) -> 1 | M13: =IF(COUNTIF(B:B,$K13)>0,1,0) -> 1 | N13: =IF(COUNTIF(C:C,$K13)>0,1,0) -> 1 | O13: =IF(COUNTIF(D:D,$K13)>0,1,0) -> 1 | P13: =IF(COUNTIF(E:E,$K13)>0,1,0) -> 0 | Q13: =IF(COUNTIF(F:F,$K13)>0,1,0) -> 0 | R13: =IF(COUNTIF(G:G,$K13)>0,1,0) -> 1 | S13: =IF(COUNTIF(H:H,$K13)>0,1,0) -> 1 | T13: =IF(COUNTIF(I:I,$K13)>0,1,0) -> 1 | U13: =SUM(L13:T13) -> 7 | X13: Sample Variance | Y13: 6.3640558
A14: ABM Industries Incorporated (NYSE:ABM) | B14: Abbott Laboratories (NYSE:ABT) | C14: Abrdn Global Dynamic Dividend Fund (NYSE:AGD) | D14: A10 Networks, Inc. (NYSE:ATEN) | E14: Academy Sports and Outdoors, Inc. (NASDAQGS:ASO) | F14: Actuate Therapeutics, Inc. (NASDAQGM:ACTU) | G14: Abercrombie & Fitch Co. (NYSE:ANF) | H14: Abrdn Income Credit Strategies Fund (NYSE:ACP) | I14: Academy Sports and Outdoors, Inc. (NASDAQGS:ASO) | K14: Semtech Corporation (NASDAQGS:SMTC) | L14: =IF(COUNTIF(A:A,$K14)>0,1,0) -> 0 | M14: =IF(COUNTIF(B:B,$K14)>0,1,0) -> 1 | N14: =IF(COUNTIF(C:C,$K14)>0,1,0) -> 1 | O14: =IF(COUNTIF(D:D,$K14)>0,1,0) -> 1 | P14: =IF(COUNTIF(E:E,$K14)>0,1,0) -> 1 | Q14: =IF(COUNTIF(F:F,$K14)>0,1,0) -> 0 | R14: =IF(COUNTIF(G:G,$K14)>0,1,0) -> 1 | S14: =IF(COUNTIF(H:H,$K14)>0,1,0) -> 1 | T14: =IF(COUNTIF(I:I,$K14)>0,1,0) -> 0 | U14: =SUM(L14:T14) -> 6 | X14: Kurtosis | Y14: -1.0396099
A15: Abrdn Global Dynamic Dividend Fund (NYSE:AGD) | B15: AbbVie Inc. (NYSE:ABBV) | C15: Abrdn Healthcare Investors (NYSE:HQH) | D15: A2Z Cust2Mate Solutions Corp. (NASDAQCM:AZ) | E15: Acadia Healthcare Company, Inc. (NASDAQGS:ACHC) | F15: Acuity Brands, Inc. (NYSE:AYI) | G15: ABM Industries Incorporated (NYSE:ABM) | H15: Abrdn Japan Equity Fund Inc (NYSE:JEQ) | I15: Accel Entertainment, Inc. (NYSE:ACEL) | K15: Coinbase Global, Inc. (NASDAQGS:COIN) | L15: =IF(COUNTIF(A:A,$K15)>0,1,0) -> 1 | M15: =IF(COUNTIF(B:B,$K15)>0,1,0) -> 1 | N15: =IF(COUNTIF(C:C,$K15)>0,1,0) -> 1 | O15: =IF(COUNTIF(D:D,$K15)>0,1,0) -> 1 | P15: =IF(COUNTIF(E:E,$K15)>0,1,0) -> 1 | Q15: =IF(COUNTIF(F:F,$K15)>0,1,0) -> 1 | R15: =IF(COUNTIF(G:G,$K15)>0,1,0) -> 1 | S15: =IF(COUNTIF(H:H,$K15)>0,1,0) -> 1 | T15: =IF(COUNTIF(I:I,$K15)>0,1,0) -> 0 | U15: =SUM(L15:T15) -> 8 | X15: Skewness | Y15: -0.35265427
A16: Abrdn Healthcare Investors (NYSE:HQH) | B16: Abercrombie & Fitch Co. (NYSE:ANF) | C16: Abrdn Income Credit Strategies Fund (NYSE:ACP) | D16: AAON, Inc. (NASDAQGS:AAON) | E16: Acadia Realty Trust (NYSE:AKR) | F16: ACV Auctions Inc. (NASDAQGS:ACVA) | G16: Abrdn Global Dynamic Dividend Fund (NYSE:AGD) | H16: Abrdn Life Sciences Investors (NYSE:HQL) | I16: Accenture plc (NYSE:ACN) | K16: Coherent Corp. (NYSE:COHR) | L16: =IF(COUNTIF(A:A,$K16)>0,1,0) -> 0 | M16: =IF(COUNTIF(B:B,$K16)>0,1,0) -> 1 | N16: =IF(COUNTIF(C:C,$K16)>0,1,0) -> 1 | O16: =IF(COUNTIF(D:D,$K16)>0,1,0) -> 1 | P16: =IF(COUNTIF(E:E,$K16)>0,1,0) -> 1 | Q16: =IF(COUNTIF(F:F,$K16)>0,1,0) -> 0 | R16: =IF(COUNTIF(G:G,$K16)>0,1,0) -> 1 | S16: =IF(COUNTIF(H:H,$K16)>0,1,0) -> 1 | T16: =IF(COUNTIF(I:I,$K16)>0,1,0) -> 0 | U16: =SUM(L16:T16) -> 6 | X16: Range | Y16: 9
A17: Abrdn Income Credit Strategies Fund (NYSE:ACP) | B17: ABM Industries Incorporated (NYSE:ABM) | C17: Abrdn Japan Equity Fund Inc (NYSE:JEQ) | D17: AAR Corp. (NYSE:AIR) | E17: Accel Entertainment, Inc. (NYSE:ACEL) | F17: AdaptHealth Corp. (NASDAQCM:AHCO) | G17: Abrdn Healthcare Investors (NYSE:HQH) | H17: Acadia Realty Trust (NYSE:AKR) | I17: ACCO Brands Corporation (NYSE:ACCO) | K17: Tenet Healthcare Corporation (NYSE:THC) | L17: =IF(COUNTIF(A:A,$K17)>0,1,0) -> 1 | M17: =IF(COUNTIF(B:B,$K17)>0,1,0) -> 1 | N17: =IF(COUNTIF(C:C,$K17)>0,1,0) -> 1 | O17: =IF(COUNTIF(D:D,$K17)>0,1,0) -> 0 | P17: =IF(COUNTIF(E:E,$K17)>0,1,0) -> 1 | Q17: =IF(COUNTIF(F:F,$K17)>0,1,0) -> 1 | R17: =IF(COUNTIF(G:G,$K17)>0,1,0) -> 1 | S17: =IF(COUNTIF(H:H,$K17)>0,1,0) -> 0 | T17: =IF(COUNTIF(I:I,$K17)>0,1,0) -> 1 | U17: =SUM(L17:T17) -> 7 | X17: Minimum | Y17: 0
A18: Abrdn Japan Equity Fund Inc (NYSE:JEQ) | B18: Abrdn Japan Equity Fund Inc (NYSE:JEQ) | C18: Abrdn Life Sciences Investors (NYSE:HQL) | D18: Abbott Laboratories (NYSE:ABT) | E18: ACCO Brands Corporation (NYSE:ACCO) | F18: Addus HomeCare Corporation (NASDAQGS:ADUS) | G18: Abrdn Income Credit Strategies Fund (NYSE:ACP) | H18: Accel Entertainment, Inc. (NYSE:ACEL) | I18: ACRES Commercial Realty Corp. (NYSE:ACR) | K18: The GEO Group, Inc. (NYSE:GEO) | L18: =IF(COUNTIF(A:A,$K18)>0,1,0) -> 1 | M18: =IF(COUNTIF(B:B,$K18)>0,1,0) -> 1 | N18: =IF(COUNTIF(C:C,$K18)>0,1,0) -> 1 | O18: =IF(COUNTIF(D:D,$K18)>0,1,0) -> 1 | P18: =IF(COUNTIF(E:E,$K18)>0,1,0) -> 1 | Q18: =IF(COUNTIF(F:F,$K18)>0,1,0) -> 0 | R18: =IF(COUNTIF(G:G,$K18)>0,1,0) -> 0 | S18: =IF(COUNTIF(H:H,$K18)>0,1,0) -> 1 | T18: =IF(COUNTIF(I:I,$K18)>0,1,0) -> 0 | U18: =SUM(L18:T18) -> 6 | X18: Maximum | Y18: 9
A19: Abrdn Life Sciences Investors (NYSE:HQL) | B19: Academy Sports and Outdoors, Inc. (NASDAQGS:ASO) | C19: Acadia Healthcare Company, Inc. (NASDAQGS:ACHC) | D19: AbbVie Inc. (NYSE:ABBV) | E19: ACRES Commercial Realty Corp. (NYSE:ACR) | F19: Adeia Inc. (NASDAQGS:ADEA) | G19: Abrdn Japan Equity Fund Inc (NYSE:JEQ) | H19: ACCO Brands Corporation (NYSE:ACCO) | I19: Acushnet Holdings Corp. (NYSE:GOLF) | K19: Carpenter Technology Corporation (NYSE:CRS) | L19: =IF(COUNTIF(A:A,$K19)>0,1,0) -> 1 | M19: =IF(COUNTIF(B:B,$K19)>0,1,0) -> 1 | N19: =IF(COUNTIF(C:C,$K19)>0,1,0) -> 1 | O19: =IF(COUNTIF(D:D,$K19)>0,1,0) -> 1 | P19: =IF(COUNTIF(E:E,$K19)>0,1,0) -> 0 | Q19: =IF(COUNTIF(F:F,$K19)>0,1,0) -> 1 | R19: =IF(COUNTIF(G:G,$K19)>0,1,0) -> 1 | S19: =IF(COUNTIF(H:H,$K19)>0,1,0) -> 1 | T19: =IF(COUNTIF(I:I,$K19)>0,1,0) -> 0 | U19: =SUM(L19:T19) -> 7 | X19: Sum | Y19: 17753
A20: Abrdn Total Dynamic Dividend Fund (NYSE:AOD) | B20: Acadia Healthcare Company, Inc. (NASDAQGS:ACHC) | C20: ACADIA Pharmaceuticals Inc. (NASDAQGS:ACAD) | D20: Abeona Therapeutics Inc. (NASDAQCM:ABEO) | E20: Acuity Brands, Inc. (NYSE:AYI) | F20: Adient plc (NYSE:ADNT) | G20: Abrdn Life Sciences Investors (NYSE:HQL) | H20: ACI Worldwide, Inc. (NASDAQGS:ACIW) | I20: Adecoagro S.A. (NYSE:AGRO) | K20: RadNet, Inc. (NASDAQGM:RDNT) | L20: =IF(COUNTIF(A:A,$K20)>0,1,0) -> 1 | M20: =IF(COUNTIF(B:B,$K20)>0,1,0) -> 1 | N20: =IF(COUNTIF(C:C,$K20)>0,1,0) -> 0 | O20: =IF(COUNTIF(D:D,$K20)>0,1,0) -> 1 | P20: =IF(COUNTIF(E:E,$K20)>0,1,0) -> 1 | Q20: =IF(COUNTIF(F:F,$K20)>0,1,0) -> 1 | R20: =IF(COUNTIF(G:G,$K20)>0,1,0) -> 0 | S20: =IF(COUNTIF(H:H,$K20)>0,1,0) -> 1 | T20: =IF(COUNTIF(I:I,$K20)>0,1,0) -> 0 | U20: =SUM(L20:T20) -> 6 | X20: Count | Y20: 4456
A21: Academy Sports and Outdoors, Inc. (NASDAQGS:ASO) | B21: ACADIA Pharmaceuticals Inc. (NASDAQGS:ACAD) | C21: Acadia Realty Trust (NYSE:AKR) | D21: Abercrombie & Fitch Co. (NYSE:ANF) | E21: Acushnet Holdings Corp. (NYSE:GOLF) | F21: ADMA Biologics, Inc. (NASDAQGM:ADMA) | G21: Acadia Healthcare Company, Inc. (NASDAQGS:ACHC) | H21: ACNB Corporation (NASDAQCM:ACNB) | I21: Adient plc (NYSE:ADNT) | K21: StepStone Group Inc. (NASDAQGS:STEP) | L21: =IF(COUNTIF(A:A,$K21)>0,1,0) -> 1 | M21: =IF(COUNTIF(B:B,$K21)>0,1,0) -> 1 | N21: =IF(COUNTIF(C:C,$K21)>0,1,0) -> 0 | O21: =IF(COUNTIF(D:D,$K21)>0,1,0) -> 0 | P21: =IF(COUNTIF(E:E,$K21)>0,1,0) -> 1 | Q21: =IF(COUNTIF(F:F,$K21)>0,1,0) -> 0 | R21: =IF(COUNTIF(G:G,$K21)>0,1,0) -> 0 | S21: =IF(COUNTIF(H:H,$K21)>0,1,0) -> 1 | T21: =IF(COUNTIF(I:I,$K21)>0,1,0) -> 0 | U21: =SUM(L21:T21) -> 4
A22: Acadia Healthcare Company, Inc. (NASDAQGS:ACHC) | B22: Acadia Realty Trust (NYSE:AKR) | C22: ACI Worldwide, Inc. (NASDAQGS:ACIW) | D22: ABM Industries Incorporated (NYSE:ABM) | E22: AdaptHealth Corp. (NASDAQCM:AHCO) | F22: ADT Inc. (NYSE:ADT) | G22: ACADIA Pharmaceuticals Inc. (NASDAQGS:ACAD) | H22: ACRES Commercial Realty Corp. (NYSE:ACR) | I22: Adobe Inc. (NASDAQGS:ADBE) | K22: Fair Isaac Corporation (NYSE:FICO) | L22: =IF(COUNTIF(A:A,$K22)>0,1,0) -> 1 | M22: =IF(COUNTIF(B:B,$K22)>0,1,0) -> 1 | N22: =IF(COUNTIF(C:C,$K22)>0,1,0) -> 1 | O22: =IF(COUNTIF(D:D,$K22)>0,1,0) -> 1 | P22: =IF(COUNTIF(E:E,$K22)>0,1,0) -> 0 | Q22: =IF(COUNTIF(F:F,$K22)>0,1,0) -> 0 | R22: =IF(COUNTIF(G:G,$K22)>0,1,0) -> 1 | S22: =IF(COUNTIF(H:H,$K22)>0,1,0) -> 1 | T22: =IF(COUNTIF(I:I,$K22)>0,1,0) -> 1 | U22: =SUM(L22:T22) -> 7
A23: ACADIA Pharmaceuticals Inc. (NASDAQGS:ACAD) | B23: Accel Entertainment, Inc. (NYSE:ACEL) | C23: ACRES Commercial Realty Corp. (NYSE:ACR) | D23: Academy Sports and Outdoors, Inc. (NASDAQGS:ASO) | E23: Adecoagro S.A. (NYSE:AGRO) | F23: Adtalem Global Education Inc. (NYSE:ATGE) | G23: Acadia Realty Trust (NYSE:AKR) | H23: Acushnet Holdings Corp. (NYSE:GOLF) | I23: AECOM (NYSE:ACM) | K23: Royal Caribbean Cruises Ltd. (NYSE:RCL) | L23: =IF(COUNTIF(A:A,$K23)>0,1,0) -> 1 | M23: =IF(COUNTIF(B:B,$K23)>0,1,0) -> 1 | N23: =IF(COUNTIF(C:C,$K23)>0,1,0) -> 1 | O23: =IF(COUNTIF(D:D,$K23)>0,1,0) -> 1 | P23: =IF(COUNTIF(E:E,$K23)>0,1,0) -> 1 | Q23: =IF(COUNTIF(F:F,$K23)>0,1,0) -> 0 | R23: =IF(COUNTIF(G:G,$K23)>0,1,0) -> 1 | S23: =IF(COUNTIF(H:H,$K23)>0,1,0) -> 1 | T23: =IF(COUNTIF(I:I,$K23)>0,1,0) -> 0 | U23: =SUM(L23:T23) -> 7
A24: Accel Entertainment, Inc. (NYSE:ACEL) | B24: Accenture plc (NYSE:ACN) | C24: Actuate Therapeutics, Inc. (NASDAQGM:ACTU) | D24: ACADIA Pharmaceuticals Inc. (NASDAQGS:ACAD) | E24: Adeia Inc. (NASDAQGS:ADEA) | F24: Advance Auto Parts, Inc. (NYSE:AAP) | G24: Accenture plc (NYSE:ACN) | H24: ACV Auctions Inc. (NASDAQGS:ACVA) | I24: AerCap Holdings N.V. (NYSE:AER) | K24: United Airlines Holdings, Inc. (NASDAQGS:UAL) | L24: =IF(COUNTIF(A:A,$K24)>0,1,0) -> 1 | M24: =IF(COUNTIF(B:B,$K24)>0,1,0) -> 1 | N24: =IF(COUNTIF(C:C,$K24)>0,1,0) -> 0 | O24: =IF(COUNTIF(D:D,$K24)>0,1,0) -> 1 | P24: =IF(COUNTIF(E:E,$K24)>0,1,0) -> 0 | Q24: =IF(COUNTIF(F:F,$K24)>0,1,0) -> 1 | R24: =IF(COUNTIF(G:G,$K24)>0,1,0) -> 0 | S24: =IF(COUNTIF(H:H,$K24)>0,1,0) -> 1 | T24: =IF(COUNTIF(I:I,$K24)>0,1,0) -> 0 | U24: =SUM(L24:T24) -> 5
A25: Accenture plc (NYSE:ACN) | B25: ACCO Brands Corporation (NYSE:ACCO) | C25: Acuity Brands, Inc. (NYSE:AYI) | D25: Acadia Realty Trust (NYSE:AKR) | E25: Adient plc (NYSE:ADNT) | F25: Advanced Drainage Systems, Inc. (NYSE:WMS) | G25: ACI Worldwide, Inc. (NASDAQGS:ACIW) | H25: AdaptHealth Corp. (NASDAQCM:AHCO) | I25: AeroVironment, Inc. (NASDAQGS:AVAV) | K25: The Baldwin Insurance Group, Inc. (NASDAQGS:BWIN) | L25: =IF(COUNTIF(A:A,$K25)>0,1,0) -> 0 | M25: =IF(COUNTIF(B:B,$K25)>0,1,0) -> 1 | N25: =IF(COUNTIF(C:C,$K25)>0,1,0) -> 1 | O25: =IF(COUNTIF(D:D,$K25)>0,1,0) -> 1 | P25: =IF(COUNTIF(E:E,$K25)>0,1,0) -> 0 | Q25: =IF(COUNTIF(F:F,$K25)>0,1,0) -> 0 | R25: =IF(COUNTIF(G:G,$K25)>0,1,0) -> 1 | S25: =IF(COUNTIF(H:H,$K25)>0,1,0) -> 1 | T25: =IF(COUNTIF(I:I,$K25)>0,1,0) -> 0 | U25: =SUM(L25:T25) -> 5
A26: ACI Worldwide, Inc. (NASDAQGS:ACIW) | B26: ACI Worldwide, Inc. (NASDAQGS:ACIW) | C26: ACV Auctions Inc. (NASDAQGS:ACVA) | D26: Accel Entertainment, Inc. (NYSE:ACEL) | E26: ADMA Biologics, Inc. (NASDAQGM:ADMA) | F26: Aehr Test Systems, Inc. (NASDAQCM:AEHR) | G26: ACM Research, Inc. (NASDAQGM:ACMR) | H26: Adaptive Biotechnologies Corporation (NASDAQGS:ADPT) | I26: Affiliated Managers Group, Inc. (NYSE:AMG) | K26: Cinemark Holdings, Inc. (NYSE:CNK) | L26: =IF(COUNTIF(A:A,$K26)>0,1,0) -> 1 | M26: =IF(COUNTIF(B:B,$K26)>0,1,0) -> 1 | N26: =IF(COUNTIF(C:C,$K26)>0,1,0) -> 1 | O26: =IF(COUNTIF(D:D,$K26)>0,1,0) -> 1 | P26: =IF(COUNTIF(E:E,$K26)>0,1,0) -> 1 | Q26: =IF(COUNTIF(F:F,$K26)>0,1,0) -> 0 | R26: =IF(COUNTIF(G:G,$K26)>0,1,0) -> 1 | S26: =IF(COUNTIF(H:H,$K26)>0,1,0) -> 0 | T26: =IF(COUNTIF(I:I,$K26)>0,1,0) -> 0 | U26: =SUM(L26:T26) -> 6
A27: ACM Research, Inc. (NASDAQGM:ACMR) | B27: ACM Research, Inc. (NASDAQGM:ACMR) | C27: Adams Diversified Equity Fund, Inc. (NYSE:ADX) | D27: Accenture plc (NYSE:ACN) | E27: Adobe Inc. (NASDAQGS:ADBE) | F27: AerCap Holdings N.V. (NYSE:AER) | G27: ACNB Corporation (NASDAQCM:ACNB) | H27: Adecoagro S.A. (NYSE:AGRO) | I27: Affinity Bancshares, Inc. (NASDAQCM:AFBI) | K27: ACI Worldwide, Inc. (NASDAQGS:ACIW) | L27: =IF(COUNTIF(A:A,$K27)>0,1,0) -> 1 | M27: =IF(COUNTIF(B:B,$K27)>0,1,0) -> 1 | N27: =IF(COUNTIF(C:C,$K27)>0,1,0) -> 1 | O27: =IF(COUNTIF(D:D,$K27)>0,1,0) -> 1 | P27: =IF(COUNTIF(E:E,$K27)>0,1,0) -> 0 | Q27: =IF(COUNTIF(F:F,$K27)>0,1,0) -> 1 | R27: =IF(COUNTIF(G:G,$K27)>0,1,0) -> 1 | S27: =IF(COUNTIF(H:H,$K27)>0,1,0) -> 1 | T27: =IF(COUNTIF(I:I,$K27)>0,1,0) -> 0 | U27: =SUM(L27:T27) -> 7
A28: ACNB Corporation (NASDAQCM:ACNB) | B28: ACNB Corporation (NASDAQCM:ACNB) | C28: Adams Natural Resources Fund, Inc. (NYSE:PEO) | D28: ACCO Brands Corporation (NYSE:ACCO) | E28: ADT Inc. (NYSE:ADT) | F28: AeroVironment, Inc. (NASDAQGS:AVAV) | G28: Acuity Brands, Inc. (NYSE:AYI) | H28: ADMA Biologics, Inc. (NASDAQGM:ADMA) | I28: Aflac Incorporated (NYSE:AFL) | K28: SL Green Realty Corp. (NYSE:SLG) | L28: =IF(COUNTIF(A:A,$K28)>0,1,0) -> 0 | M28: =IF(COUNTIF(B:B,$K28)>0,1,0) -> 1 | N28: =IF(COUNTIF(C:C,$K28)>0,1,0) -> 1 | O28: =IF(COUNTIF(D:D,$K28)>0,1,0) -> 1 | P28: =IF(COUNTIF(E:E,$K28)>0,1,0) -> 1 | Q28: =IF(COUNTIF(F:F,$K28)>0,1,0) -> 0 | R28: =IF(COUNTIF(G:G,$K28)>0,1,0) -> 1 | S28: =IF(COUNTIF(H:H,$K28)>0,1,0) -> 0 | T28: =IF(COUNTIF(I:I,$K28)>0,1,0) -> 0 | U28: =SUM(L28:T28) -> 5
A29: ACRES Commercial Realty Corp. (NYSE:ACR) | B29: ACRES Commercial Realty Corp. (NYSE:ACR) | C29: AdaptHealth Corp. (NASDAQCM:AHCO) | D29: ACI Worldwide, Inc. (NASDAQGS:ACIW) | E29: Adtalem Global Education Inc. (NYSE:ATGE) | F29: AerSale Corporation (NASDAQCM:ASLE) | G29: Acushnet Holdings Corp. (NYSE:GOLF) | H29: Adobe Inc. (NASDAQGS:ADBE) | I29: Agilent Technologies, Inc. (NYSE:A) | K29: EchoStar Corporation (NASDAQGS:SATS) | L29: =IF(COUNTIF(A:A,$K29)>0,1,0) -> 0 | M29: =IF(COUNTIF(B:B,$K29)>0,1,0) -> 1 | N29: =IF(COUNTIF(C:C,$K29)>0,1,0) -> 1 | O29: =IF(COUNTIF(D:D,$K29)>0,1,0) -> 1 | P29: =IF(COUNTIF(E:E,$K29)>0,1,0) -> 0 | Q29: =IF(COUNTIF(F:F,$K29)>0,1,0) -> 1 | R29: =IF(COUNTIF(G:G,$K29)>0,1,0) -> 0 | S29: =IF(COUNTIF(H:H,$K29)>0,1,0) -> 0 | T29: =IF(COUNTIF(I:I,$K29)>0,1,0) -> 0 | U29: =SUM(L29:T29) -> 4
A30: Acuity Brands, Inc. (NYSE:AYI) | B30: Acuity Brands, Inc. (NYSE:AYI) | C30: Adaptive Biotechnologies Corporation (NASDAQGS:ADPT) | D30: ACNB Corporation (NASDAQCM:ACNB) | E30: Advance Auto Parts, Inc. (NYSE:AAP) | F30: Affiliated Managers Group, Inc. (NYSE:AMG) | G30: ACV Auctions Inc. (NASDAQGS:ACVA) | H30: ADS-TEC Energy PLC (NASDAQCM:ADSE) | I30: Air Transport Services Group, Inc. (NASDAQGS:ATSG) | K30: Construction Partners, Inc. (NASDAQGS:ROAD) | L30: =IF(COUNTIF(A:A,$K30)>0,1,0) -> 1 | M30: =IF(COUNTIF(B:B,$K30)>0,1,0) -> 1 | N30: =IF(COUNTIF(C:C,$K30)>0,1,0) -> 0 | O30: =IF(COUNTIF(D:D,$K30)>0,1,0) -> 1 | P30: =IF(COUNTIF(E:E,$K30)>0,1,0) -> 1 | Q30: =IF(COUNTIF(F:F,$K30)>0,1,0) -> 0 | R30: =IF(COUNTIF(G:G,$K30)>0,1,0) -> 0 | S30: =IF(COUNTIF(H:H,$K30)>0,1,0) -> 0 | T30: =IF(COUNTIF(I:I,$K30)>0,1,0) -> 1 | U30: =SUM(L30:T30) -> 5
A31: Acushnet Holdings Corp. (NYSE:GOLF) | B31: Acushnet Holdings Corp. (NYSE:GOLF) | C31: Addus HomeCare Corporation (NASDAQGS:ADUS) | D31: ACRES Commercial Realty Corp. (NYSE:ACR) | E31: Advanced Drainage Systems, Inc. (NYSE:WMS) | F31: Affirm Holdings, Inc. (NASDAQGS:AFRM) | G31: AdaptHealth Corp. (NASDAQCM:AHCO) | H31: ADT Inc. (NYSE:ADT) | I31: Akamai Technologies, Inc. (NASDAQGS:AKAM) | K31: Dycom Industries, Inc. (NYSE:DY) | L31: =IF(COUNTIF(A:A,$K31)>0,1,0) -> 1 | M31: =IF(COUNTIF(B:B,$K31)>0,1,0) -> 1 | N31: =IF(COUNTIF(C:C,$K31)>0,1,0) -> 0 | O31: =IF(COUNTIF(D:D,$K31)>0,1,0) -> 1 | P31: =IF(COUNTIF(E:E,$K31)>0,1,0) -> 0 | Q31: =IF(COUNTIF(F:F,$K31)>0,1,0) -> 0 | R31: =IF(COUNTIF(G:G,$K31)>0,1,0) -> 0 | S31: =IF(COUNTIF(H:H,$K31)>0,1,0) -> 0 | T31: =IF(COUNTIF(I:I,$K31)>0,1,0) -> 0 | U31: =SUM(L31:T31) -> 3
A32: Adams Diversified Equity Fund, Inc. (NYSE:ADX) | B32: ACV Auctions Inc. (NASDAQGS:ACVA) | C32: ADMA Biologics, Inc. (NASDAQGM:ADMA) | D32: Acrivon Therapeutics, Inc. (NASDAQGM:ACRV) | E32: Advanced Energy Industries, Inc. (NASDAQGS:AEIS) | F32: Afya Limited (NASDAQGS:AFYA) | G32: Adaptive Biotechnologies Corporation (NASDAQGS:ADPT) | H32: Adtalem Global Education Inc. (NYSE:ATGE) | I32: Alaska Air Group, Inc. (NYSE:ALK) | K32: Mercury General Corporation (NYSE:MCY) | L32: =IF(COUNTIF(A:A,$K32)>0,1,0) -> 1 | M32: =IF(COUNTIF(B:B,$K32)>0,1,0) -> 1 | N32: =IF(COUNTIF(C:C,$K32)>0,1,0) -> 1 | O32: =IF(COUNTIF(D:D,$K32)>0,1,0) -> 1 | P32: =IF(COUNTIF(E:E,$K32)>0,1,0) -> 1 | Q32: =IF(COUNTIF(F:F,$K32)>0,1,0) -> 0 | R32: =IF(COUNTIF(G:G,$K32)>0,1,0) -> 1 | S32: =IF(COUNTIF(H:H,$K32)>0,1,0) -> 1 | T32: =IF(COUNTIF(I:I,$K32)>0,1,0) -> 0 | U32: =SUM(L32:T32) -> 7
... A41: Adtalem Global Education Inc. (NYSE:ATGE) | B41: Adtalem Global Education Inc. (NYSE:ATGE) | C41: AECOM (NYSE:ACM) | D41: Adeia Inc. (NASDAQGS:ADEA) | E41: Air Products and Chemicals, Inc. (NYSE:APD) | F41: Akamai Technologies, Inc. (NASDAQGS:AKAM) | G41: Advanced Micro Devices, Inc. (NASDAQGS:AMD) | H41: Affirm Holdings, Inc. (NASDAQGS:AFRM) | I41: Alpha Star Acquisition Corporation (NASDAQGM:ALSA) | K41: Nu Holdings Ltd. (NYSE:NU) | L41: =IF(COUNTIF(A:A,$K41)>0,1,0) -> 1 | M41: =IF(COUNTIF(B:B,$K41)>0,1,0) -> 1 | N41: =IF(COUNTIF(C:C,$K41)>0,1,0) -> 1 | O41: =IF(COUNTIF(D:D,$K41)>0,1,0) -> 1 | P41: =IF(COUNTIF(E:E,$K41)>0,1,0) -> 1 | Q41: =IF(COUNTIF(F:F,$K41)>0,1,0) -> 0 | R41: =IF(COUNTIF(G:G,$K41)>0,1,0) -> 1 | S41: =IF(COUNTIF(H:H,$K41)>0,1,0) -> 0 | T41: =IF(COUNTIF(I:I,$K41)>0,1,0) -> 0 | U41: =SUM(L41:T41) -> 6
A42: Advance Auto Parts, Inc. (NYSE:AAP) | B42: ADTRAN Holdings, Inc. (NASDAQGS:ADTN) | C42: AerSale Corporation (NASDAQCM:ASLE) | D42: Adient plc (NYSE:ADNT) | E42: AirSculpt Technologies, Inc. (NASDAQGM:AIRS) | F42: Albany International Corp. (NYSE:AIN) | G42: AdvanSix Inc. (NYSE:ASIX) | H42: AG Mortgage Investment Trust, Inc. (NYSE:MITT) | I42: Alphabet Inc. (NASDAQGS:GOOGL)
A43: Advanced Drainage Systems, Inc. (NYSE:WMS) | B43: Advance Auto Parts, Inc. (NYSE:AAP) | C43: Affinity Bancshares, Inc. (NASDAQCM:AFBI) | D43: ADMA Biologics, Inc. (NASDAQGM:ADMA) | E43: Akamai Technologies, Inc. (NASDAQGS:AKAM) | F43: Albertsons Companies, Inc. (NYSE:ACI) | G43: Advent Convertible and Income Fund (NYSE:AVK) | H43: AGNC Investment Corp. (NASDAQGS:AGNC) | I43: Alphatec Holdings, Inc. (NASDAQGS:ATEC)
A44: Advanced Energy Industries, Inc. (NASDAQGS:AEIS) | B44: Advanced Drainage Systems, Inc. (NYSE:WMS) | C44: Affirm Holdings, Inc. (NASDAQGS:AFRM) | D44: ADS-TEC Energy PLC (NASDAQCM:ADSE) | E44: Alamo Group Inc. (NYSE:ALG) | F44: Alico, Inc. (NASDAQGS:ALCO) | G44: Advent Technologies Holdings, Inc. (NASDAQCM:ADN) | H44: Agnico Eagle Mines Limited (NYSE:AEM) | I44: Altria Group, Inc. (NYSE:MO)
A45: Advanced Flower Capital Inc. (NASDAQGM:AFCG) | B45: Advanced Energy Industries, Inc. (NASDAQGS:AEIS) | C45: AG Mortgage Investment Trust, Inc. (NYSE:MITT) | D45: ADT Inc. (NYSE:ADT) | E45: Alarm.com Holdings, Inc. (NASDAQGS:ALRM) | F45: Align Technology, Inc. (NASDAQGS:ALGN) | G45: AECOM (NYSE:ACM) | H45: Agree Realty Corporation (NYSE:ADC) | I45: Amdocs Limited (NASDAQGS:DOX)
A46: Advanced Micro Devices, Inc. (NASDAQGS:AMD) | B46: Advanced Flower Capital Inc. (NASDAQGM:AFCG) | C46: Agios Pharmaceuticals, Inc. (NASDAQGS:AGIO) | D46: Adtalem Global Education Inc. (NYSE:ATGE) | E46: Albany International Corp. (NYSE:AIN) | F46: Alkermes plc (NASDAQGS:ALKS) | G46: AerSale Corporation (NASDAQCM:ASLE) | H46: Airbnb, Inc. (NASDAQGS:ABNB) | I46: American Express Company (NYSE:AXP)
A47: AdvanSix Inc. (NYSE:ASIX) | B47: Advanced Micro Devices, Inc. (NASDAQGS:AMD) | C47: AGNC Investment Corp. (NASDAQGS:AGNC) | D47: ADTRAN Holdings, Inc. (NASDAQGS:ADTN) | E47: Albertsons Companies, Inc. (NYSE:ACI) | F47: Allegiant Travel Company (NASDAQGS:ALGT) | G47: Affinity Bancshares, Inc. (NASDAQCM:AFBI) | H47: Airgain, Inc. (NASDAQCM:AIRG) | I47: American International Group, Inc. (NYSE:AIG)
A48: Advent Convertible and Income Fund (NYSE:AVK) | B48: AdvanSix Inc. (NYSE:ASIX) | C48: Agnico Eagle Mines Limited (NYSE:AEM) | D48: Advance Auto Parts, Inc. (NYSE:AAP) | E48: Alcoa Corporation (NYSE:AA) | F48: Allegion plc (NYSE:ALLE) | G48: Affirm Holdings, Inc. (NASDAQGS:AFRM) | H48: Alamo Group Inc. (NYSE:ALG) | I48: American Outdoor Brands, Inc. (NASDAQGS:AOUT)
A49: AECOM (NYSE:ACM) | B49: Advent Technologies Holdings, Inc. (NASDAQCM:ADN) | C49: Agriculture & Natural Solutions Acquisition Corporation (NASDAQGM:ANSC) | D49: Advanced Drainage Systems, Inc. (NYSE:WMS) | E49: Alibaba Group Holding Limited (NYSE:BABA) | F49: Alliant Energy Corporation (NASDAQGS:LNT) | G49: Afya Limited (NASDAQGS:AFYA) | H49: Albany International Corp. (NYSE:AIN) | I49: American Vanguard Corporation (NYSE:AVD)
A50: Aehr Test Systems, Inc. (NASDAQCM:AEHR) | B50: AECOM (NYSE:ACM) | C50: AI Transportation Acquisition Corp (NASDAQCM:AITR) | D50: Advanced Energy Industries, Inc. (NASDAQGS:AEIS) | E50: Allegion plc (NYSE:ALLE) | F50: Allient Inc. (NASDAQGM:ALNT) | G50: Agilent Technologies, Inc. (NYSE:A) | H50: Alcoa Corporation (NYSE:AA) | I50: American Woodmark Corporation (NASDAQGS:AMWD)
...

Sheet 9-dim-Scores
A1: =_xll.SNL.Clients.Office.Excel.Functions.SPGTable($B$6:$B$4461,$C$3:$AD$3,,"Options:Curr=USD,Mag=Standard,ConvMethod=R,FilingVer=Current/Restated") -> SPGTable | AP1: Net Income > 0 | AQ1: Cash flow from Op > 0 | AR1: Delta RoA > 0 | AS1: CFO > Net Income | AT1: Delta LT Debt / Asset < 0 | AU1: Delta C Asset / Liability > 0 | AV1: Delta EBIT Margin > 0 | AW1: Delta Rev / Asset > 0 | AX1: Delta O/S shares < 0 | AY1: sum
A2: =_xll.SNL.Clients.Office.Excel.Functions.SPGLabel(266637,"SP_ENTITY_NAME","","","Options:Curr=USD,Mag=Standard,ConvMethod=R,FilingVer=Current/Restated") -> Entity Name | B2: =_xll.SNL.Clients.Office.Excel.Functions.SPGLabel(266637,"SP_ENTITY_ID","","","Options:Curr=USD,Mag=Standard,ConvMethod=R,FilingVer=Current/Restated") -> Entity ID | C2: =_xll.SNL.Clients.Office.Excel.Functions.SPGLabel(266637,"SP_EXCHANGE","","","Options:Curr=USD,Mag=Standard,ConvMethod=R,FilingVer=Current/Restated") -> Exchange | D2: =_xll.SNL.Clients.Office.Excel.Functions.SPGLabel(266637,"SP_PRICE_CLOSE","Current","","Options:Curr=USD,Mag=Standard,ConvMethod=R,FilingVer=Current/Restated") -> Day Close Price ($) | E2: =_xll.SNL.Clients.Office.Excel.Functions.SPGLabel(266637,"SP_MARKETCAP","","","Options:Curr=USD,Mag=Standard,ConvMethod=R,FilingVer=Current/Restated") -> Market Capitalization ($M) | F2: =_xll.SNL.Clients.Office.Excel.Functions.SPGLabel(266637,"IQ_SECTOR","","","Options:Curr=USD,Mag=Standard,ConvMethod=R,FilingVer=Current/Restated") -> Sector | G2: =_xll.SNL.Clients.Office.Excel.Functions.SPGLabel(266637,"IQ_INDUSTRY_GROUP","","","Options:Curr=USD,Mag=Standard,ConvMethod=R,FilingVer=Current/Restated") -> Industry Group | H2: =_xll.SNL.Clients.Office.Excel.Functions.SPGLabel(266637,"IQ_INDUSTRY","","","Options:Curr=USD,Mag=Standard,ConvMethod=R,FilingVer=Current/Restated") -> Industry | I2: =_xll.SNL.Clients.Office.Excel.Functions.SPGLabel(266637,"IQ_PRIMARY_INDUSTRY","","","Options:Curr=USD,Mag=Standard,ConvMethod=R,FilingVer=Current/Restated") -> Primary Industry | J2: =_xll.SNL.Clients.Office.Excel.Functions.SPGLabel(266637,"NAICS_CODE","Primary","","Options:Curr=USD,Mag=Standard,ConvMethod=R,FilingVer=Current/Restated") -> NAICS Code | K2: =_xll.SNL.Clients.Office.Excel.Functions.SPGLabel(266637,"SP_TOTAL_REV","LTM","","Options:Curr=USD,Mag=Standard,ConvMethod=R,FilingVer=Current/Restated") -> Total Revenue ($000) | L2: =_xll.SNL.Clients.Office.Excel.Functions.SPGLabel(266637,"SP_TOTAL_REV","LTM-1","","Options:Curr=USD,Mag=Standard,ConvMethod=R,FilingVer=Current/Restated") -> Total Revenue ($000) | M2: =_xll.SNL.Clients.Office.Excel.Functions.SPGLabel(266637,"SP_EBITDA","LTM","","Options:Curr=USD,Mag=Standard,ConvMethod=R,FilingVer=Current/Restated") -> EBITDA ($000) | N2: =_xll.SNL.Clients.Office.Excel.Functions.SPGLabel(266637,"SP_EBITDA","LTM-1","","Options:Curr=USD,Mag=Standard,ConvMethod=R,FilingVer=Current/Restated") -> EBITDA ($000) | O2: =_xll.SNL.Clients.Office.Excel.Functions.SPGLabel(266637,"SP_EBIT","LTM","","Options:Curr=USD,Mag=Standard,ConvMethod=R,FilingVer=Current/Restated") -> EBIT ($000) | P2: =_xll.SNL.Clients.Office.Excel.Functions.SPGLabel(266637,"SP_EBIT","LTM-1","","Options:Curr=USD,Mag=Standard,ConvMethod=R,FilingVer=Current/Restated") -> EBIT ($000) | Q2: =_xll.SNL.Clients.Office.Excel.Functions.SPGLabel(266637,"SP_NET_INC","LTM","","Options:Curr=USD,Mag=Standard,ConvMethod=R,FilingVer=Current/Restated") -> Net Income ($000) | R2: =_xll.SNL.Clients.Office.Excel.Functions.SPGLabel(266637,"SP_NET_INC","LTM-1","","Options:Curr=USD,Mag=Standard,ConvMethod=R,FilingVer=Current/Restated") -> Net Income ($000) | S2: =_xll.SNL.Clients.Office.Excel.Functions.SPGLabel(266637,"IQ_CASH_OPER","LTM","","Options:Curr=USD,Mag=Standard,ConvMethod=R,FilingVer=Current/Restated") -> Cash from Ops. ($000) | T2: =_xll.SNL.Clients.Office.Excel.Functions.SPGLabel(266637,"IQ_CASH_OPER","LTM-1","","Options:Curr=USD,Mag=Standard,ConvMethod=R,FilingVer=Current/Restated") -> Cash from Ops. ($000) | U2: =_xll.SNL.Clients.Office.Excel.Functions.SPGLabel(266637,"IQ_LT_DEBT_BNK","LTM","","Options:Curr=USD,Mag=Standard,ConvMethod=R,FilingVer=Current/Restated") -> Long-Term Debt ($000) | V2: =_xll.SNL.Clients.Office.Excel.Functions.SPGLabel(266637,"IQ_LT_DEBT_BNK","LTM-1","","Options:Curr=USD,Mag=Standard,ConvMethod=R,FilingVer=Current/Restated") -> Long-Term Debt ($000) | W2: =_xll.SNL.Clients.Office.Excel.Functions.SPGLabel(266637,"SP_TOTAL_ASSETS","LTM","","Options:Curr=USD,Mag=Standard,ConvMethod=R,FilingVer=Current/Restated") -> Total Assets ($000) | X2: =_xll.SNL.Clients.Office.Excel.Functions.SPGLabel(266637,"SP_TOTAL_ASSETS","LTM-1","","Options:Curr=USD,Mag=Standard,ConvMethod=R,FilingVer=Current/Restated") -> Total Assets ($000) | Y2: =_xll.SNL.Clients.Office.Excel.Functions.SPGLabel(266637,"SP_CURRENT_ASSETS","LTM","","Options:Curr=USD,Mag=Standard,ConvMethod=R,FilingVer=Current/Restated") -> Total Current Assets ($000) | Z2: =_xll.SNL.Clients.Office.Excel.Functions.SPGLabel(266637,"SP_CURRENT_ASSETS","LTM-1","","Options:Curr=USD,Mag=Standard,ConvMethod=R,FilingVer=Current/Restated") -> Total Current Assets ($000) | AA2: =_xll.SNL.Clients.Office.Excel.Functions.SPGLabel(266637,"SP_CURRENT_LIAB","LTM","","Options:Curr=USD,Mag=Standard,ConvMethod=R,FilingVer=Current/Restated") -> Total Current Liabilities ($000) | AB2: =_xll.SNL.Clients.Office.Excel.Functions.SPGLabel(266637,"SP_CURRENT_LIAB","LTM-1","","Options:Curr=USD,Mag=Standard,ConvMethod=R,FilingVer=Current/Restated") -> Total Current Liabilities ($000) | AC2: =_xll.SNL.Clients.Office.Excel.Functions.SPGLabel(266637,"SP_SHARES_OUT_PERIOD_END","LTM","","Options:Curr=USD,Mag=Standard,ConvMethod=R,FilingVer=Current/Restated") -> Common Shares Outstanding (actual) | AD2: =_xll.SNL.Clients.Office.Excel.Functions.SPGLabel(266637,"SP_SHARES_OUT_PERIOD_END","LTM-1","","Options:Curr=USD,Mag=Standard,ConvMethod=R,FilingVer=Current/Restated") -> Common Shares Outstanding (actual)
A3: SP_ENTITY_NAME | B3: SP_ENTITY_ID | C3: SP_EXCHANGE | D3: SP_PRICE_CLOSE | E3: SP_MARKETCAP | F3: IQ_SECTOR | G3: IQ_INDUSTRY_GROUP | H3: IQ_INDUSTRY | I3: IQ_PRIMARY_INDUSTRY | J3: NAICS_CODE | K3: SP_TOTAL_REV | L3: SP_TOTAL_REV | M3: SP_EBITDA | N3: SP_EBITDA | O3: SP_EBIT | P3: SP_EBIT | Q3: SP_NET_INC | R3: SP_NET_INC | S3: IQ_CASH_OPER | T3: IQ_CASH_OPER | U3: IQ_LT_DEBT_BNK | V3: IQ_LT_DEBT_BNK | W3: SP_TOTAL_ASSETS | X3: SP_TOTAL_ASSETS | Y3: SP_CURRENT_ASSETS | Z3: SP_CURRENT_ASSETS | AA3: SP_CURRENT_LIAB | AB3: SP_CURRENT_LIAB | AC3: SP_SHARES_OUT_PERIOD_END | AD3: SP_SHARES_OUT_PERIOD_END | AF3: RoA | AG3: RoA | AH3: Debt / Asset | AI3: Debt / Asset | AJ3: Current Asset / Liability | AK3: Current Asset / Liability | AL3: EBIT Margin | AM3: EBIT Margin | AN3: Rev / Asset | AO3: Rev / Asset
D4: =_xll.SNL.Clients.Office.Excel.Functions.SPGLabel(266637,"SP_PRICE_CLOSE","<>Current") -> Current | J4: =_xll.SNL.Clients.Office.Excel.Functions.SPGLabel(266637,"NAICS_CODE","<>Primary") -> Primary | K4: LTM | L4: LTM-1 | M4: LTM | N4: LTM-1 | O4: LTM | P4: LTM-1 | Q4: LTM | R4: LTM-1 | S4: LTM | T4: LTM-1 | U4: LTM | V4: LTM-1 | W4: LTM | X4: LTM-1 | Y4: LTM | Z4: LTM-1 | AA4: LTM | AB4: LTM-1 | AC4: LTM | AD4: LTM-1 | AF4: LTM | AG4: LTM-1 | AH4: LTM | AI4: LTM-1 | AJ4: LTM | AK4: LTM-1 | AL4: LTM | AM4: LTM-1 | AN4: LTM | AO4: LTM-1
A6: 10x Genomics, Inc. (NASDAQGS:TXG) | B6: 5248867 | C6: NASDAQGS | D6: 15.71 | E6: 1901.7654 | F6: Health Care | G6: Pharmaceuticals, Biotechnology and Life Sciences | H6: Life Sciences Tools and Services | I6: Life Sciences Tools and Services | J6: 33911 - Medical Equipment and Supplies Manufacturing | K6: 629743 | L6: 631733 | M6: -134769 | N6: -146284 | O6: -171615 | P6: -183538 | Q6: -182551 | R6: -239784 | S6: 39170 | T6: -7775 | U6: NA | V6: NA | W6: 937794 | X6: 929668 | Y6: 593893 | Z6: 579155 | AA6: 121235 | AB6: 111019 | AC6: 121039868 | AD6: 120474167 | AF6: =Q6/W6 -> -0.19466002 | AG6: =R6/X6 -> -0.25792433 | AH6: =U6/W6 -> #VALUE! | AI6: =V6/X6 -> #VALUE! | AJ6: =Y6/AA6 -> 4.8986926 | AK6: =Z6/AB6 -> 5.2167197 | AL6: =O6/K6 -> -0.27251593 | AM6: =P6/L6 -> -0.29053097 | AN6: =K6/W6 -> 0.67151528 | AO6: =L6/X6 -> 0.67952538 | AP6: =IF(OR(Q6<0, Q6="NA"), 0, 1) -> 0 | AQ6: =IF(OR(S6<0, S6="NA"), 0, 1) -> 1 | AR6: =IFERROR(IF((AF6-AG6)>0,1,0),0) -> 1 | AS6: =IFERROR(IF((S6-Q6)>0,1,0),0) -> 1 | AT6: =IFERROR(IF((AH6-AI6)<0,1,0),0) -> 0 | AU6: =IFERROR(IF((AJ6-AK6)>0,1,0),0) -> 0 | AV6: =IFERROR(IF((AL6-AM6)>0,1,0),0) -> 1 | AW6: =IFERROR(IF((AN6-AO6)>0,1,0),0) -> 0 | AX6: =IFERROR(IF((AC6-AD6)<0,1,0),0) -> 0 | AY6: =SUM(AP6:AX6) -> 4
A7: 1-800-FLOWERS.COM, Inc. (NASDAQGS:FLWS) | B7: 4122591 | C7: NASDAQGS | D7: 7.39 | E7: 471.85851 | F7: Consumer Discretionary | G7: Consumer Discretionary Distribution and Retail | H7: Specialty Retail | I7: Other Specialty Retail | J7: 459999 - All Other Miscellaneous Retailers | K7: 1804461 | L7: 1831421 | M7: 58693 | N7: 66011 | O7: 5097 | P7: 12259 | Q7: -9053 | R7: -6105 | S7: 61642 | T7: 94999 | U7: 172293 | V7: 177113 | W7: 1034624 | X7: 1032648 | Y7: 385714 | Z7: 385732 | AA7: 266994 | AB7: 227819 | AC7: 64060948 | AD7: 64215626 | AF7: =Q7/W7 -> -0.0087500387 | AG7: =R7/X7 -> -0.0059119855 | AH7: =U7/W7 -> 0.16652716 | AI7: =V7/X7 -> 0.17151343 | AJ7: =Y7/AA7 -> 1.4446542 | AK7: =Z7/AB7 -> 1.6931511 | AL7: =O7/K7 -> 0.0028246662 | AM7: =P7/L7 -> 0.0066937094 | AN7: =K7/W7 -> 1.7440742 | AO7: =L7/X7 -> 1.7735191 | AP7: =IF(OR(Q7<0, Q7="NA"), 0, 1) -> 0 | AQ7: =IF(OR(S7<0, S7="NA"), 0, 1) -> 1 | AR7: =IFERROR(IF((AF7-AG7)>0,1,0),0) -> 0 | AS7: =IFERROR(IF((S7-Q7)>0,1,0),0) -> 1 | AT7: =IFERROR(IF((AH7-AI7)<0,1,0),0) -> 1 | AU7: =IFERROR(IF((AJ7-AK7)>0,1,0),0) -> 0 | AV7: =IFERROR(IF((AL7-AM7)>0,1,0),0) -> 0 | AW7: =IFERROR(IF((AN7-AO7)>0,1,0),0) -> 0 | AX7: =IFERROR(IF((AC7-AD7)<0,1,0),0) -> 1 | AY7: =SUM(AP7:AX7) -> 4
A8: 1895 Bancorp of Wisconsin, Inc. (NASDAQCM:BCOW) | B8: 11123920 | C8: NASDAQCM | D8: 9.94 | E8: 55.057362 | F8: Financials | G8: Banks | H8: Banks | I8: Regional Banks | J8: 522180 - Savings Institutions and Other Depository Credit Intermediation | K8: 12126 | L8: 10086 | M8: NA | N8: NA | O8: 7291 | P8: 4937 | Q8: -3263 | R8: -6745 | S8: -43 | T8: -1067 | U8: NA | V8: NA | W8: 564540 | X8: 561454 | Y8: NA | Z8: NA | AA8: NA | AB8: NA | AC8: 5965459 | AD8: 5969174 | AF8: =Q8/W8 -> -0.005779927 | AG8: =R8/X8 -> -0.012013451 | AH8: =U8/W8 -> #VALUE! | AI8: =V8/X8 -> #VALUE! | AJ8: =Y8/AA8 -> #VALUE! | AK8: =Z8/AB8 -> #VALUE! | AL8: =O8/K8 -> 0.60127 | AM8: =P8/L8 -> 0.48949038 | AN8: =K8/W8 -> 0.021479435 | AO8: =L8/X8 -> 0.017964072 | AP8: =IF(OR(Q8<0, Q8="NA"), 0, 1) -> 0 | AQ8: =IF(OR(S8<0, S8="NA"), 0, 1) -> 0 | AR8: =IFERROR(IF((AF8-AG8)>0,1,0),0) -> 1 | AS8: =IFERROR(IF((S8-Q8)>0,1,0),0) -> 1 | AT8: =IFERROR(IF((AH8-AI8)<0,1,0),0) -> 0 | AU8: =IFERROR(IF((AJ8-AK8)>0,1,0),0) -> 0 | AV8: =IFERROR(IF((AL8-AM8)>0,1,0),0) -> 1 | AW8: =IFERROR(IF((AN8-AO8)>0,1,0),0) -> 1 | AX8: =IFERROR(IF((AC8-AD8)<0,1,0),0) -> 1 | AY8: =SUM(AP8:AX8) -> 5
A9: 1st Source Corporation (NASDAQGS:SRCE) | B9: 100444 | C9: NASDAQGS | D9: 55.84 | E9: 1368.9898 | F9: Financials | G9: Banks | H9: Banks | I9: Regional Banks | J9: 522110 - Commercial Banking | K9: 380682 | L9: 376439 | M9: NA | N9: NA | O9: 350177 | P9: 337806 | Q9: 129598 | R9: 127623 | S9: 204458 | T9: 188255 | U9: 39220 | V9: 39136 | W9: 8763946 | X9: 8878003 | Y9: NA | Z9: NA | AA9: NA | AB9: NA | AC9: 24514383 | AD9: 24507023 | AF9: =Q9/W9 -> 0.014787631 | AG9: =R9/X9 -> 0.014375192 | AH9: =U9/W9 -> 0.0044751531 | AI9: =V9/X9 -> 0.0044081986 | AJ9: =Y9/AA9 -> #VALUE! | AK9: =Z9/AB9 -> #VALUE! | AL9: =O9/K9 -> 0.9198675 | AM9: =P9/L9 -> 0.89737248 | AN9: =K9/W9 -> 0.043437283 | AO9: =L9/X9 -> 0.042401315 | AP9: =IF(OR(Q9<0, Q9="NA"), 0, 1) -> 1 | AQ9: =IF(OR(S9<0, S9="NA"), 0, 1) -> 1 | AR9: =IFERROR(IF((AF9-AG9)>0,1,0),0) -> 1 | AS9: =IFERROR(IF((S9-Q9)>0,1,0),0) -> 1 | AT9: =IFERROR(IF((AH9-AI9)<0,1,0),0) -> 0 | AU9: =IFERROR(IF((AJ9-AK9)>0,1,0),0) -> 0 | AV9: =IFERROR(IF((AL9-AM9)>0,1,0),0) -> 1 | AW9: =IFERROR(IF((AN9-AO9)>0,1,0),0) -> 1 | AX9: =IFERROR(IF((AC9-AD9)<0,1,0),0) -> 0 | AY9: =SUM(AP9:AX9) -> 6
A10: 3M Company (NYSE:MMM) | B10: 105135 | C10: NYSE | D10: 134.6 | E10: 73297.589 | F10: Industrials | G10: Capital Goods | H10: Industrial Conglomerates | I10: Industrial Conglomerates | J10: 3251 - Basic Chemical Manufacturing | K10: 32638000 | L10: 32614000 | M10: 8117000 | N10: 7350000 | O10: 6539000 | P10: 5547000 | Q10: 4407000 | R10: 960000 | S10: 1987000 | T10: 5684000 | U10: 11387000 | V10: 11877000 | W10: 40875000 | X10: 43377000 | Y10: 16299000 | Z10: 19515000 | AA10: 11391000 | AB10: 14345000 | AC10: 544558607 | AD10: 549353621 | AF10: =Q10/W10 -> 0.10781651 | AG10: =R10/X10 -> 0.022131544 | AH10: =U10/W10 -> 0.27858104 | AI10: =V10/X10 -> 0.2738087 | AJ10: =Y10/AA10 -> 1.4308665 | AK10: =Z10/AB10 -> 1.3604043 | AL10: =O10/K10 -> 0.20034929 | AM10: =P10/L10 -> 0.17008033 | AN10: =K10/W10 -> 0.79848318 | AO10: =L10/X10 -> 0.75187311 | AP10: =IF(OR(Q10<0, Q10="NA"), 0, 1) -> 1 | AQ10: =IF(OR(S10<0, S10="NA"), 0, 1) -> 1 | AR10: =IFERROR(IF((AF10-AG10)>0,1,0),0) -> 1 | AS10: =IFERROR(IF((S10-Q10)>0,1,0),0) -> 0 | AT10: =IFERROR(IF((AH10-AI10)<0,1,0),0) -> 0 | AU10: =IFERROR(IF((AJ10-AK10)>0,1,0),0) -> 1 | AV10: =IFERROR(IF((AL10-AM10)>0,1,0),0) -> 1 | AW10: =IFERROR(IF((AN10-AO10)>0,1,0),0) -> 1 | AX10: =IFERROR(IF((AC10-AD10)<0,1,0),0) -> 1 | AY10: =SUM(AP10:AX10) -> 7
A11: 4D Molecular Therapeutics, Inc. (NASDAQGS:FDMT) | B11: 5284798 | C11: NASDAQGS | D11: 4.76 | E11: 220.04389 | F11: Health Care | G11: Pharmaceuticals, Biotechnology and Life Sciences | H11: Biotechnology | I11: Biotechnology | J11: 541714 - Research and Development in Biotechnology (except Nanobiotechnology) | K11: 17 | L11: 20218 | M11: -163717 | N11: -126755 | O11: -168376 | P11: -131218 | Q11: -143480 | R11: -109893 | S11: -113372 | T11: -85152 | U11: NA | V11: NA | W11: 604028 | X11: 620117 | Y11: 510757 | Z11: 552633 | AA11: 29465 | AB11: 19403 | AC11: 51996639 | AD11: 51914275 | AF11: =Q11/W11 -> -0.23753866 | AG11: =R11/X11 -> -0.17721333 | AH11: =U11/W11 -> #VALUE! | AI11: =V11/X11 -> #VALUE! | AJ11: =Y11/AA11 -> 17.334363 | AK11: =Z11/AB11 -> 28.481833 | AL11: =O11/K11 -> -9904.4706 | AM11: =P11/L11 -> -6.4901573 | AN11: =K11/W11 -> 2.8144391e-05 | AO11: =L11/X11 -> 0.032603525 | AP11: =IF(OR(Q11<0, Q11="NA"), 0, 1) -> 0 | AQ11: =IF(OR(S11<0, S11="NA"), 0, 1) -> 0 | AR11: =IFERROR(IF((AF11-AG11)>0,1,0),0) -> 0 | AS11: =IFERROR(IF((S11-Q11)>0,1,0),0) -> 1 | AT11: =IFERROR(IF((AH11-AI11)<0,1,0),0) -> 0 | AU11: =IFERROR(IF((AJ11-AK11)>0,1,0),0) -> 0 | AV11: =IFERROR(IF((AL11-AM11)>0,1,0),0) -> 0 | AW11: =IFERROR(IF((AN11-AO11)>0,1,0),0) -> 0 | AX11: =IFERROR(IF((AC11-AD11)<0,1,0),0) -> 0 | AY11: =SUM(AP11:AX11) -> 1
A12: 5:01 Acquisition Corp. (NASDAQCM:FVAM) | B12: 25688942 | C12: NASDAQCM | D12: 10 | E12: 106.56717 | F12: Financials | G12: Financial Services | H12: Capital Markets | I12: Asset Management and Custody Banks | J12: 525990 - Other Financial Vehicles | K12: NA | L12: NA | M12: NA | N12: NA | O12: -1317.983 | P12: -1200.069 | Q12: -1187.185 | R12: -1186.415 | S12: -1111.117 | T12: -986.685 | U12: 1000 | V12: 1000 | W12: 83430.064 | X12: 83681.82 | Y12: 739.002 | Z12: 1100.207 | AA12: 275 | AB12: 315 | AC12: 10656717 | AD12: 10685467 | AF12: =Q12/W12 -> -0.014229703 | AG12: =R12/X12 -> -0.014177691 | AH12: =U12/W12 -> 0.011986087 | AI12: =V12/X12 -> 0.011950027 | AJ12: =Y12/AA12 -> 2.68728 | AK12: =Z12/AB12 -> 3.4927206 | AL12: =O12/K12 -> #VALUE! | AM12: =P12/L12 -> #VALUE! | AN12: =K12/W12 -> #VALUE! | AO12: =L12/X12 -> #VALUE! | AP12: =IF(OR(Q12<0, Q12="NA"), 0, 1) -> 0 | AQ12: =IF(OR(S12<0, S12="NA"), 0, 1) -> 0 | AR12: =IFERROR(IF((AF12-AG12)>0,1,0),0) -> 0 | AS12: =IFERROR(IF((S12-Q12)>0,1,0),0) -> 1 | AT12: =IFERROR(IF((AH12-AI12)<0,1,0),0) -> 0 | AU12: =IFERROR(IF((AJ12-AK12)>0,1,0),0) -> 0 | AV12: =IFERROR(IF((AL12-AM12)>0,1,0),0) -> 0 | AW12: =IFERROR(IF((AN12-AO12)>0,1,0),0) -> 0 | AX12: =IFERROR(IF((AC12-AD12)<0,1,0),0) -> 1 | AY12: =SUM(AP12:AX12) -> 2
A13: 89bio, Inc. (NASDAQGM:ETNB) | B13: 19357914 | C13: NASDAQGM | D13: 6.31 | E13: 741.94381 | F13: Health Care | G13: Pharmaceuticals, Biotechnology and Life Sciences | H13: Biotechnology | I13: Biotechnology | J13: 325414 - Biological Product (except Diagnostic) Manufacturing | K13: NA | L13: NA | M13: -303812 | N13: -191217 | O13: -303857 | P13: -191264 | Q13: -288960 | R13: -174612 | S13: -280536 | T13: -165538 | U13: 35544 | V13: 20355 | W13: 458297 | X13: 582138 | Y13: 456206 | Z13: 579854 | AA13: 39131 | AB13: 41653 | AC13: 106126338 | AD13: 104915176 | AF13: =Q13/W13 -> -0.63050816 | AG13: =R13/X13 -> -0.2999495 | AH13: =U13/W13 -> 0.077556694 | AI13: =V13/X13 -> 0.034965936 | AJ13: =Y13/AA13 -> 11.658429 | AK13: =Z13/AB13 -> 13.921062 | AL13: =O13/K13 -> #VALUE! | AM13: =P13/L13 -> #VALUE! | AN13: =K13/W13 -> #VALUE! | AO13: =L13/X13 -> #VALUE! | AP13: =IF(OR(Q13<0, Q13="NA"), 0, 1) -> 0 | AQ13: =IF(OR(S13<0, S13="NA"), 0, 1) -> 0 | AR13: =IFERROR(IF((AF13-AG13)>0,1,0),0) -> 0 | AS13: =IFERROR(IF((S13-Q13)>0,1,0),0) -> 1 | AT13: =IFERROR(IF((AH13-AI13)<0,1,0),0) -> 0 | AU13: =IFERROR(IF((AJ13-AK13)>0,1,0),0) -> 0 | AV13: =IFERROR(IF((AL13-AM13)>0,1,0),0) -> 0 | AW13: =IFERROR(IF((AN13-AO13)>0,1,0),0) -> 0 | AX13: =IFERROR(IF((AC13-AD13)<0,1,0),0) -> 0 | AY13: =SUM(AP13:AX13) -> 1
A14: A SPAC III Acquisition Corp. (NASDAQCM:ASPC.U) | B14: 100630552 | C14: NASDAQCM | D14: 9.98 | E14: 80.3889 | F14: Financials | G14: Financial Services | H14: Capital Markets | I14: Asset Management and Custody Banks | J14: 525990 - Other Financial Vehicles | K14: NA | L14: NA | M14: NA | N14: NA | O14: -49.428 | P14: -2.65 | Q14: -49.428 | R14: -2.65 | S14: NA | T14: 0 | U14: NA | V14: NA | W14: 82.25 | X14: NA | Y14: NA | Z14: NA | AA14: 270 | AB14: 141 | AC14: 1581250 | AD14: 1581250 | AF14: =Q14/W14 -> -0.60094833 | AG14: =R14/X14 -> #VALUE! | AH14: =U14/W14 -> #VALUE! | AI14: =V14/X14 -> #VALUE! | AJ14: =Y14/AA14 -> #VALUE! | AK14: =Z14/AB14 -> #VALUE! | AL14: =O14/K14 -> #VALUE! | AM14: =P14/L14 -> #VALUE! | AN14: =K14/W14 -> #VALUE! | AO14: =L14/X14 -> #VALUE! | AP14: =IF(OR(Q14<0, Q14="NA"), 0, 1) -> 0 | AQ14: =IF(OR(S14<0, S14="NA"), 0, 1) -> 0 | AR14: =IFERROR(IF((AF14-AG14)>0,1,0),0) -> 0 | AS14: =IFERROR(IF((S14-Q14)>0,1,0),0) -> 0 | AT14: =IFERROR(IF((AH14-AI14)<0,1,0),0) -> 0 | AU14: =IFERROR(IF((AJ14-AK14)>0,1,0),0) -> 0 | AV14: =IFERROR(IF((AL14-AM14)>0,1,0),0) -> 0 | AW14: =IFERROR(IF((AN14-AO14)>0,1,0),0) -> 0 | AX14: =IFERROR(IF((AC14-AD14)<0,1,0),0) -> 0 | AY14: =SUM(AP14:AX14) -> 0
A15: A. O. Smith Corporation (NYSE:AOS) | B15: 4020605 | C15: NYSE | D15: 68.63 | E15: 9951.0386 | F15: Industrials | G15: Capital Goods | H15: Building Products | I15: Building Products | J15: 3352 - Household Appliance Manufacturing | K15: 3893800 | L15: 3928700 | M15: 809100 | N15: 828900 | O15: 728800 | P15: 749500 | Q15: 561200 | R15: 576500 | S15: 591200 | T15: 574100 | U15: 109700 | V15: 130400 | W15: 3154200 | X15: 3197600 | Y15: 1412500 | Z15: 1481300 | AA15: 844200 | AB15: 872400 | AC15: 144995463 | AD15: 145845344 | AF15: =Q15/W15 -> 0.1779215 | AG15: =R15/X15 -> 0.18029147 | AH15: =U15/W15 -> 0.034779025 | AI15: =V15/X15 -> 0.040780585 | AJ15: =Y15/AA15 -> 1.6731817 | AK15: =Z15/AB15 -> 1.6979597 | AL15: =O15/K15 -> 0.18716935 | AM15: =P15/L15 -> 0.19077557 | AN15: =K15/W15 -> 1.234481 | AO15: =L15/X15 -> 1.2286402 | AP15: =IF(OR(Q15<0, Q15="NA"), 0, 1) -> 1 | AQ15: =IF(OR(S15<0, S15="NA"), 0, 1) -> 1 | AR15: =IFERROR(IF((AF15-AG15)>0,1,0),0) -> 0 | AS15: =IFERROR(IF((S15-Q15)>0,1,0),0) -> 1 | AT15: =IFERROR(IF((AH15-AI15)<0,1,0),0) -> 1 | AU15: =IFERROR(IF((AJ15-AK15)>0,1,0),0) -> 0 | AV15: =IFERROR(IF((AL15-AM15)>0,1,0),0) -> 0 | AW15: =IFERROR(IF((AN15-AO15)>0,1,0),0) -> 1 | AX15: =IFERROR(IF((AC15-AD15)<0,1,0),0) -> 1 | AY15: =SUM(AP15:AX15) -> 6
A16: a.k.a. Brands Holding Corp. (NYSE:AKA) | B16: 29663785 | C16: NYSE | D16: 19.57 | E16: 208.23249 | F16: Consumer Discretionary | G16: Consumer Discretionary Distribution and Retail | H16: Specialty Retail | I16: Apparel Retail | J16: 459 - Sporting Goods, Hobby, Musical Instrument, Book, and Miscellaneous Retailers | K16: 564586 | L16: 555516 | M16: 6553 | N16: 4878 | O16: -10917 | P16: -12670 | Q16: -30516 | R16: -95487 | S16: 9046 | T16: 21938 | U16: 105610 | V16: 100607 | W16: 404101 | X16: 388804 | Y16: 156277 | Z16: 155067 | AA16: 98830 | AB16: 99843 | AC16: 10631326 | AD16: 10529419 | AF16: =Q16/W16 -> -0.075515775 | AG16: =R16/X16 -> -0.24559161 | AH16: =U16/W16 -> 0.26134555 | AI16: =V16/X16 -> 0.2587602 | AJ16: =Y16/AA16 -> 1.5812709 | AK16: =Z16/AB16 -> 1.5531084 | AL16: =O16/K16 -> -0.019336292 | AM16: =P16/L16 -> -0.022807624 | AN16: =K16/W16 -> 1.3971408 | AO16: =L16/X16 -> 1.4287816 | AP16: =IF(OR(Q16<0, Q16="NA"), 0, 1) -> 0 | AQ16: =IF(OR(S16<0, S16="NA"), 0, 1) -> 1 | AR16: =IFERROR(IF((AF16-AG16)>0,1,0),0) -> 1 | AS16: =IFERROR(IF((S16-Q16)>0,1,0),0) -> 1 | AT16: =IFERROR(IF((AH16-AI16)<0,1,0),0) -> 0 | AU16: =IFERROR(IF((AJ16-AK16)>0,1,0),0) -> 1 | AV16: =IFERROR(IF((AL16-AM16)>0,1,0),0) -> 1 | AW16: =IFERROR(IF((AN16-AO16)>0,1,0),0) -> 0 | AX16: =IFERROR(IF((AC16-AD16)<0,1,0),0) -> 0 | AY16: =SUM(AP16:AX16) -> 5
A17: A10 Networks, Inc. (NYSE:ATEN) | B17: 4433033 | C17: NYSE | D17: 17.99 | E17: 1327.6422 | F17: Information Technology | G17: Software and Services | H17: Software | I17: Systems Software | J17: 513210 - Software Publishers | K17: 257909 | L17: 248963 | M17: 53927 | N17: 45490 | O17: 43578 | P17: 35344 | Q17: 49756 | R17: 43588 | S17: 67513 | T17: 70442 | U17: NA | V17: NA | W17: 407747 | X17: 397170 | Y17: 283837 | Z17: 275047 | AA17: 127038 | AB17: 115033 | AC17: 73783000 | AD17: 73860000 | AF17: =Q17/W17 -> 0.12202665 | AG17: =R17/X17 -> 0.10974646 | AH17: =U17/W17 -> #VALUE! | AI17: =V17/X17 -> #VALUE! | AJ17: =Y17/AA17 -> 2.2342685 | AK17: =Z17/AB17 -> 2.3910269 | AL17: =O17/K17 -> 0.16896657 | AM17: =P17/L17 -> 0.14196487 | AN17: =K17/W17 -> 0.63252213 | AO17: =L17/X17 -> 0.62684241 | AP17: =IF(OR(Q17<0, Q17="NA"), 0, 1) -> 1 | AQ17: =IF(OR(S17<0, S17="NA"), 0, 1) -> 1 | AR17: =IFERROR(IF((AF17-AG17)>0,1,0),0) -> 1 | AS17: =IFERROR(IF((S17-Q17)>0,1,0),0) -> 1 | AT17: =IFERROR(IF((AH17-AI17)<0,1,0),0) -> 0 | AU17: =IFERROR(IF((AJ17-AK17)>0,1,0),0) -> 0 | AV17: =IFERROR(IF((AL17-AM17)>0,1,0),0) -> 1 | AW17: =IFERROR(IF((AN17-AO17)>0,1,0),0) -> 1 | AX17: =IFERROR(IF((AC17-AD17)<0,1,0),0) -> 1 | AY17: =SUM(AP17:AX17) -> 7
A18: A2Z Cust2Mate Solutions Corp. (NASDAQCM:AZ) | B18: 19068495 | C18: NASDAQCM | D18: 6.66 | E18: 173.59994 | F18: Industrials | G18: Capital Goods | H18: Aerospace and Defense | I18: Aerospace and Defense | J18: 336992 - Military Armored Vehicle, Tank, and Tank Component Manufacturing | K18: 6628 | L18: 7142 | M18: -13874 | N18: -15876 | O18: -14501 | P18: -16541 | Q18: -11307 | R18: -10362 | S18: -10472 | T18: -13179 | U18: 136 | V18: 133 | W18: 10152 | X18: 7219 | Y18: 6627 | Z18: 3561 | AA18: 9356 | AB18: 6768 | AC18: 22732495 | AD18: 20892941 | AF18: =Q18/W18 -> -1.1137707 | AG18: =R18/X18 -> -1.4353789 | AH18: =U18/W18 -> 0.013396375 | AI18: =V18/X18 -> 0.018423604 | AJ18: =Y18/AA18 -> 0.70831552 | AK18: =Z18/AB18 -> 0.52615248 | AL18: =O18/K18 -> -2.1878395 | AM18: =P18/L18 -> -2.3160179 | AN18: =K18/W18 -> 0.65287628 | AO18: =L18/X18 -> 0.9893337 | AP18: =IF(OR(Q18<0, Q18="NA"), 0, 1) -> 0 | AQ18: =IF(OR(S18<0, S18="NA"), 0, 1) -> 0 | AR18: =IFERROR(IF((AF18-AG18)>0,1,0),0) -> 1 | AS18: =IFERROR(IF((S18-Q18)>0,1,0),0) -> 1 | AT18: =IFERROR(IF((AH18-AI18)<0,1,0),0) -> 1 | AU18: =IFERROR(IF((AJ18-AK18)>0,1,0),0) -> 1 | AV18: =IFERROR(IF((AL18-AM18)>0,1,0),0) -> 1 | AW18: =IFERROR(IF((AN18-AO18)>0,1,0),0) -> 0 | AX18: =IFERROR(IF((AC18-AD18)<0,1,0),0) -> 0 | AY18: =SUM(AP18:AX18) -> 5
A19: AA Mission Acquisition Corp. (NYSE:AAM) | B19: 118460002 | C19: NYSE | D19: 10.12 | E19: 445.01688 | F19: Financials | G19: Financial Services | H19: Capital Markets | I19: Asset Management and Custody Banks | J19: 525990 - Other Financial Vehicles | K19: NA | L19: NA | M19: NA | N19: NA | O19: NA | P19: NA | Q19: NA | R19: NA | S19: NA | T19: NA | U19: NA | V19: NA | W19: NA | X19: NA | Y19: NA | Z19: NA | AA19: NA | AB19: NA | AC19: NA | AD19: NA | AF19: =Q19/W19 -> #VALUE! | AG19: =R19/X19 -> #VALUE! | AH19: =U19/W19 -> #VALUE! | AI19: =V19/X19 -> #VALUE! | AJ19: =Y19/AA19 -> #VALUE! | AK19: =Z19/AB19 -> #VALUE! | AL19: =O19/K19 -> #VALUE! | AM19: =P19/L19 -> #VALUE! | AN19: =K19/W19 -> #VALUE! | AO19: =L19/X19 -> #VALUE! | AP19: =IF(OR(Q19<0, Q19="NA"), 0, 1) -> 0 | AQ19: =IF(OR(S19<0, S19="NA"), 0, 1) -> 0 | AR19: =IFERROR(IF((AF19-AG19)>0,1,0),0) -> 0 | AS19: =IFERROR(IF((S19-Q19)>0,1,0),0) -> 0 | AT19: =IFERROR(IF((AH19-AI19)<0,1,0),0) -> 0 | AU19: =IFERROR(IF((AJ19-AK19)>0,1,0),0) -> 0 | AV19: =IFERROR(IF((AL19-AM19)>0,1,0),0) -> 0 | AW19: =IFERROR(IF((AN19-AO19)>0,1,0),0) -> 0 | AX19: =IFERROR(IF((AC19-AD19)<0,1,0),0) -> 0 | AY19: =SUM(AP19:AX19) -> 0
A20: AAON, Inc. (NASDAQGS:AAON) | B20: 4987250 | C20: NASDAQGS | D20: 123.4 | E20: 10029.906 | F20: Industrials | G20: Capital Goods | H20: Building Products | I20: Building Products | J20: 333415 - Air-Conditioning and Warm Air Heating Equipment and Commercial and Industrial Refrigeration Equipment Manufacturing | K20: 1209555 | L20: 1194273 | M20: 310718 | N20: 304944 | O20: 252504 | P20: 251789 | Q20: 190918 | R20: 186371 | S20: 243437 | T20: 226867 | U20: 55677 | V20: 85884 | W20: 1030625 | X20: 1010716 | Y20: 427836 | Z20: 423095 | AA20: 139833 | AB20: 141319 | AC20: 81246902 | AD20: 80950856 | AF20: =Q20/W20 -> 0.18524488 | AG20: =R20/X20 -> 0.18439502 | AH20: =U20/W20 -> 0.054022559 | AI20: =V20/X20 -> 0.084973425 | AJ20: =Y20/AA20 -> 3.0596211 | AK20: =Z20/AB20 -> 2.9939003 | AL20: =O20/K20 -> 0.20875777 | AM20: =P20/L20 -> 0.21083035 | AN20: =K20/W20 -> 1.1736131 | AO20: =L20/X20 -> 1.1816109 | AP20: =IF(OR(Q20<0, Q20="NA"), 0, 1) -> 1 | AQ20: =IF(OR(S20<0, S20="NA"), 0, 1) -> 1 | AR20: =IFERROR(IF((AF20-AG20)>0,1,0),0) -> 1 | AS20: =IFERROR(IF((S20-Q20)>0,1,0),0) -> 1 | AT20: =IFERROR(IF((AH20-AI20)<0,1,0),0) -> 1 | AU20: =IFERROR(IF((AJ20-AK20)>0,1,0),0) -> 1 | AV20: =IFERROR(IF((AL20-AM20)>0,1,0),0) -> 0 | AW20: =IFERROR(IF((AN20-AO20)>0,1,0),0) -> 0 | AX20: =IFERROR(IF((AC20-AD20)<0,1,0),0) -> 0 | AY20: =SUM(AP20:AX20) -> 6
A21: AAR Corp. (NYSE:AIR) | B21: 4157610 | C21: NYSE | D21: 69.45 | E21: 2450.1022 | F21: Industrials | G21: Capital Goods | H21: Aerospace and Defense | I21: Aerospace and Defense | J21: 488190 - Other Support Activities for Air Transportation | K21: 2571600 | L21: 2430900 | M21: 197800 | N21: 212800 | O21: 144900 | P21: 165800 | Q21: 10500 | R21: 64900 | S21: 48300 | T21: 43700 | U21: 986700 | V21: 981000 | W21: 2849300 | X21: 2783300 | Y21: 1498000 | Z21: 1426900 | AA21: 558300 | AB21: 466900 | AC21: 35278649 | AD21: 35271686 | AF21: =Q21/W21 -> 0.0036851156 | AG21: =R21/X21 -> 0.023317645 | AH21: =U21/W21 -> 0.34629558 | AI21: =V21/X21 -> 0.35245931 | AJ21: =Y21/AA21 -> 2.6831453 | AK21: =Z21/AB21 -> 3.0561148 | AL21: =O21/K21 -> 0.056346244 | AM21: =P21/L21 -> 0.068205191 | AN21: =K21/W21 -> 0.90253747 | AO21: =L21/X21 -> 0.87338771 | AP21: =IF(OR(Q21<0, Q21="NA"), 0, 1) -> 1 | AQ21: =IF(OR(S21<0, S21="NA"), 0, 1) -> 1 | AR21: =IFERROR(IF((AF21-AG21)>0,1,0),0) -> 0 | AS21: =IFERROR(IF((S21-Q21)>0,1,0),0) -> 1 | AT21: =IFERROR(IF((AH21-AI21)<0,1,0),0) -> 1 | AU21: =IFERROR(IF((AJ21-AK21)>0,1,0),0) -> 0 | AV21: =IFERROR(IF((AL21-AM21)>0,1,0),0) -> 0 | AW21: =IFERROR(IF((AN21-AO21)>0,1,0),0) -> 1 | AX21: =IFERROR(IF((AC21-AD21)<0,1,0),0) -> 0 | AY21: =SUM(AP21:AX21) -> 5
